Workbook
Name EntitiesCol: Entities!$SRI$2
Name EntitiesRow: Entities!$A$999490
Name RelationshipsCol: [1]Relationships!$SSS$2
Name RelationshipsRow: [1]Relationships!$A$1000000
Name RSC__refxartikeltypsap: 'Reference Data'!$T$2:$T$5
Name RSC__refxbooleanalkoholhaltig: 'Reference Data'!$U$2:$U$5
Name RSC__refxboolen: 'Reference Data'!$V$2:$V$5
Name RSC__refxgtintyperegioartikel: 'Reference Data'!$AP$2:$AP$5
Name RSC__refxshopinshop: 'Reference Data'!$AO$2:$AO$5
Name RSC__refxsystemsap: 'Reference Data'!$AQ$2:$AQ$5
Name RSC_atxalkoholhaltig__de_DE: 'Reference Data'!$M$2:$M$2
Name RSC_atxalkoholhaltig__fr_FR: 'Reference Data'!$L$2:$L$2
Name RSC_atxalkoholhaltig__it_IT: 'Reference Data'!$G$2:$G$2
Name RSC_atxwarengruppesap__de_DE: 'Reference Data'!$B$2:$B$2
Name RSC_atxwarengruppesap__fr_FR: 'Reference Data'!$E$2:$E$2
Name RSC_atxwarengruppesap__it_IT: 'Reference Data'!$O$2:$O$2
Name RSC_axartikelslpmstruktur__de_DE: 'Reference Data'!$C$2:$C$2
Name RSC_axartikelslpmstruktur__fr_FR: 'Reference Data'!$H$2:$H$2
Name RSC_axartikelslpmstruktur__it_IT: 'Reference Data'!$A$2:$A$2
Name RSC_axartikeltypsap__de_DE: 'Reference Data'!$J$2:$J$2
Name RSC_axartikeltypsap__fr_FR: 'Reference Data'!$I$2:$I$2
Name RSC_axartikeltypsap__it_IT: 'Reference Data'!$P$2:$P$2
Name RSC_axmhdvorhanden__de_DE: 'Reference Data'!$N$2:$N$2
Name RSC_axmhdvorhanden__fr_FR: 'Reference Data'!$Q$2:$Q$2
Name RSC_axmhdvorhanden__it_IT: 'Reference Data'!$D$2:$D$2
Name RSC_axtaxdummyfilter__de_DE: 'Reference Data'!$K$2:$K$2
Name RSC_axtaxdummyfilter__fr_FR: 'Reference Data'!$R$2:$R$2
Name RSC_axtaxdummyfilter__it_IT: 'Reference Data'!$F$2:$F$2
Name RSC_de_DE_refxaltersbegrtyp: 'Reference Data'!$AL$2:$AL$9
Name RSC_de_DE_refxartikelartsap: 'Reference Data'!$W$2:$W$14
Name RSC_de_DE_refxmengeneinheit: 'Reference Data'!$AC$2:$AC$14
Name RSC_de_DE_refxsaisontypsap: 'Reference Data'!$Z$2:$Z$7
Name RSC_de_DE_refxtaxclass: 'Reference Data'!$AI$2:$AI$6
Name RSC_de_DE_refxvergleichspreiseinheit: 'Reference Data'!$AF$2:$AF$6
Name RSC_ENTITY_NAME: 'Reference Data'!$S$2:$S$2
Name RSC_fr_FR_refxaltersbegrtyp: 'Reference Data'!$AM$2:$AM$9
Name RSC_fr_FR_refxartikelartsap: 'Reference Data'!$X$2:$X$6
Name RSC_fr_FR_refxmengeneinheit: 'Reference Data'!$AD$2:$AD$14
Name RSC_fr_FR_refxsaisontypsap: 'Reference Data'!$AA$2:$AA$7
Name RSC_fr_FR_refxtaxclass: 'Reference Data'!$AJ$2:$AJ$6
Name RSC_fr_FR_refxvergleichspreiseinheit: 'Reference Data'!$AG$2:$AG$3
Name RSC_it_IT_refxaltersbegrtyp: 'Reference Data'!$AN$2:$AN$9
Name RSC_it_IT_refxartikelartsap: 'Reference Data'!$Y$2:$Y$6
Name RSC_it_IT_refxmengeneinheit: 'Reference Data'!$AE$2:$AE$14
Name RSC_it_IT_refxsaisontypsap: 'Reference Data'!$AB$2:$AB$7
Name RSC_it_IT_refxtaxclass: 'Reference Data'!$AK$2:$AK$6
Name RSC_it_IT_refxvergleichspreiseinheit: 'Reference Data'!$AH$2:$AH$3

Sheet Help
B3: These are all read only
A4: TEMPLATE NAME | B4: RS EXCEL
A5: TEMPLATE VERSION | B5: V1.0
A6: MULTI VALUES DELIMITER | B6: ||
A7: CONTEXT PATH DELIMITER | B7: >>
A8: LEGENDS | B8: INHERITED VALUE(S)
B9: GOVERNANCE ERROR(S)
A12: Type
A13: SYSTEM/RELATIONSHIPS | B13: COLLECTION | C13: MANDATORY | D13: MANDATORY COLLECTION
A14: GLOBAL | B14: COLLECTION | C14: MANDATORY | D14: MANDATORY COLLECTION
A15: GLOBAL ENHANCER | B15: COLLECTION | C15: MANDATORY | D15: MANDATORY COLLECTION
A16: CONTEXT | B16: COLLECTION | C16: MANDATORY | D16: MANDATORY COLLECTION
A17: CONTEXT ENHANCER | B17: COLLECTION | C17: MANDATORY | D17: MANDATORY COLLECTION

Sheet Entities
A1: System Attributes | E1: Enhancer Attribute(s) | G1: Matching Attribute(s) | H1: 01 - Rumpfinformationen | J1: 99 - intern | L1: 01 - Rumpfinformationen | O1: 03 - Texte | U1: 99 - intern | AA1: 01 - Rumpfinformationen | AH1: 05 - Kasse | AM1: 99 - intern
A2: Action | B2: Type | C2: ID | D2: Name | E2: Artikeltyp | F2: Warengruppe//de-DE | G2: MDM ID | H2: Artikelart//de-DE | I2: Saison Typ//de-DE | J2: GTIN Suche | K2: Ergänzte Regio-Artikel-GTIN | L2: Artikeltext//de-DE | M2: Artikeltext//fr-FR | N2: Artikeltext//it-IT | O2: Gestellbeschriftung 1//de-DE | P2: Gestellbeschriftung 1//fr-FR | Q2: Gestellbeschriftung 1//it-IT | R2: Gestellbeschriftung 2//de-DE | S2: Gestellbeschriftung 2//fr-FR | T2: Gestellbeschriftung 2//it-IT | U2: Gestellbeschriftung 3 Regio//de-DE | V2: Gestellbeschriftung 3 Regio//fr-FR | W2: Gestellbeschriftung 3 Regio//it-IT | X2: Cash receipt text Regio//de-DE | Y2: Cash receipt text Regio//fr-FR | Z2: Cash receipt text Regio//it-IT | AA2: Nettoinhalt | AB2: Inhaltsmengeneinheit Grundpreis//de-DE | AC2: Grundpreiseinheit//de-DE | AD2: Basismengeneinheit//de-DE | AE2: Steuerklassifikation//de-DE | AF2: Leergut | AG2: Altersbegrenzungs-Typ//de-DE | AH2: Rabatt zugelassen | AI2: Rückgabe zugelassen | AJ2: Preisänderung Kasse erlaubt | AK2: Automatischer Bondruck | AL2: Shop-In-Shop | AM2: Ist Fremdartikel | AN2: GTIN-Typ Regioapp | AO2: Ist Regioartikel | AP2: Source | AQ2: SAP System Integration | AR2: Ist Vordefiniert
B3: exartikel | E3: 00 - Einzelartikel | F3: ="Warengruppe>>"&_xlfn.TEXTJOIN(">>",TRUE,Migrationsartikel!V2:X2) -> Warengruppe>>Backwaren & Convenience>>Brot und Backwaren>>Backwaren andere | H3: ZHAW - Handelsware ohne Charge | J3: =Migrationsartikel!B2 -> 0 | L3: =_xlfn.TEXTJOIN(" ",TRUE,Migrationsartikel!F2:H2) -> Baguette aus der Region 250g | M3: =_xlfn.TEXTJOIN(" ",TRUE,Migrationsartikel!J2:L2) -> Baguette de la région 250g | N3: =_xlfn.TEXTJOIN(" ",TRUE,Migrationsartikel!N2:P2) -> Baguette della regione 250g | O3: =Migrationsartikel!F2 -> Baguette | P3: =Migrationsartikel!J2 -> Baguette | Q3: =Migrationsartikel!N2 -> Baguette | R3: =_xlfn.TEXTJOIN(" ",TRUE,Migrationsartikel!G2) -> aus der Region | S3: =_xlfn.TEXTJOIN(" ",TRUE,Migrationsartikel!K2) -> de la région | T3: =_xlfn.TEXTJOIN(" ",TRUE,Migrationsartikel!O2) -> della regione | U3: =_xlfn.TEXTJOIN(" ",TRUE,Migrationsartikel!H2) -> 250g | V3: =_xlfn.TEXTJOIN(" ",TRUE,Migrationsartikel!L2) -> 250g | W3: =_xlfn.TEXTJOIN(" ",TRUE,Migrationsartikel!P2) -> 250g | X3: =Migrationsartikel!I2 -> Baguette 250g | Y3: =Migrationsartikel!M2 -> Baguette 250g | Z3: =Migrationsartikel!Q2 -> Baguette 250g | AA3: =Migrationsartikel!R2 -> 0.25 | AB3: =Migrationsartikel!T2 -> Gramm | AC3: =Migrationsartikel!S2 -> 100 | AD3: =Migrationsartikel!U2 -> (PCE) Stück | AE3: 1 - Normalsatz | AF3: =Migrationsartikel!AA2 -> 0 | AG3: Keine | AH3: =IF(Migrationsartikel!AB2="ja","true",FALSE) -> true | AI3: =IF(Migrationsartikel!AC2="ja","true",FALSE) -> true | AJ3: =IF(Migrationsartikel!AD2="ja","true",FALSE) -> true | AK3: =IF(Migrationsartikel!AE2="ja","true",FALSE) -> true | AL3: =IF(Migrationsartikel!AF2="ja","Denner Partner","") | AM3: =IF(Migrationsartikel!AG2="ja","true","false") -> false | AN3: =IF(AND(ISNUMBER(J3),J3>=100,J3<=999),"PLU",IF(AND(ISNUMBER(J3),J3>999),"GTIN","Kassentastenbelegung (ohne GTIN/PLU)")) -> Kassentastenbelegung (ohne GTIN/PLU) | AO3: true | AP3: Imp. Regio Lf-Nr 1 – 1003 | AQ3: S4H | AR3: true
B4: exartikel | E4: 00 - Einzelartikel | F4: ="Warengruppe>>"&_xlfn.TEXTJOIN(">>",TRUE,Migrationsartikel!V3:X3) -> Warengruppe>>Backwaren & Convenience>>Brot und Backwaren>>Backwaren andere | H4: ZHAW - Handelsware ohne Charge | J4: =Migrationsartikel!B3 -> 0 | L4: =_xlfn.TEXTJOIN(" ",TRUE,Migrationsartikel!F3:H3) -> Baslerbrot aus der Region 250g | M4: =_xlfn.TEXTJOIN(" ",TRUE,Migrationsartikel!J3:L3) -> Pain bâlois de la région 250g | N4: =_xlfn.TEXTJOIN(" ",TRUE,Migrationsartikel!N3:P3) -> Pane di Basilea della regione 250g | O4: =Migrationsartikel!F3 -> Baslerbrot | P4: =Migrationsartikel!J3 -> Pain bâlois | Q4: =Migrationsartikel!N3 -> Pane di Basilea | R4: =_xlfn.TEXTJOIN(" ",TRUE,Migrationsartikel!G3) -> aus der Region | S4: =_xlfn.TEXTJOIN(" ",TRUE,Migrationsartikel!K3) -> de la région | T4: =_xlfn.TEXTJOIN(" ",TRUE,Migrationsartikel!O3) -> della regione | U4: =_xlfn.TEXTJOIN(" ",TRUE,Migrationsartikel!H3) -> 250g | V4: =_xlfn.TEXTJOIN(" ",TRUE,Migrationsartikel!L3) -> 250g | W4: =_xlfn.TEXTJOIN(" ",TRUE,Migrationsartikel!P3) -> 250g | X4: =Migrationsartikel!I3 -> Baslerbrot 250g | Y4: =Migrationsartikel!M3 -> Pain bâlois 250g | Z4: =Migrationsartikel!Q3 -> Pane di Basilea 250g | AA4: =Migrationsartikel!R3 -> 0.25 | AB4: =Migrationsartikel!T3 -> Gramm | AC4: =Migrationsartikel!S3 -> 100 | AD4: =Migrationsartikel!U3 -> (PCE) Stück | AE4: 1 - Normalsatz | AF4: =Migrationsartikel!AA3 -> 0 | AG4: Keine | AH4: =IF(Migrationsartikel!AB3="ja","true",FALSE) -> true | AI4: =IF(Migrationsartikel!AC3="ja","true",FALSE) -> true | AJ4: =IF(Migrationsartikel!AD3="ja","true",FALSE) -> true | AK4: =IF(Migrationsartikel!AE3="ja","true",FALSE) -> true | AL4: =IF(Migrationsartikel!AF3="ja","Denner Partner","") | AM4: =IF(Migrationsartikel!AG3="ja","true","false") -> false | AN4: =IF(AND(ISNUMBER(J4),J4>=100,J4<=999),"PLU",IF(AND(ISNUMBER(J4),J4>999),"GTIN","Kassentastenbelegung (ohne GTIN/PLU)")) -> Kassentastenbelegung (ohne GTIN/PLU) | AO4: true | AP4: Imp. Regio Lf-Nr 2 – 1004 | AQ4: S4H | AR4: true
B5: exartikel | E5: 00 - Einzelartikel | F5: ="Warengruppe>>"&_xlfn.TEXTJOIN(">>",TRUE,Migrationsartikel!V4:X4) -> Warengruppe>>Backwaren & Convenience>>Brot und Backwaren>>Backwaren andere | H5: ZHAW - Handelsware ohne Charge | J5: =Migrationsartikel!B4 -> 0 | L5: =_xlfn.TEXTJOIN(" ",TRUE,Migrationsartikel!F4:H4) -> Baslerbrot aus der Region 500g | M5: =_xlfn.TEXTJOIN(" ",TRUE,Migrationsartikel!J4:L4) -> Pain bâlois de la région 500g | N5: =_xlfn.TEXTJOIN(" ",TRUE,Migrationsartikel!N4:P4) -> Pane di Basilea della regione 500g | O5: =Migrationsartikel!F4 -> Baslerbrot | P5: =Migrationsartikel!J4 -> Pain bâlois | Q5: =Migrationsartikel!N4 -> Pane di Basilea | R5: =_xlfn.TEXTJOIN(" ",TRUE,Migrationsartikel!G4) -> aus der Region | S5: =_xlfn.TEXTJOIN(" ",TRUE,Migrationsartikel!K4) -> de la région | T5: =_xlfn.TEXTJOIN(" ",TRUE,Migrationsartikel!O4) -> della regione | U5: =_xlfn.TEXTJOIN(" ",TRUE,Migrationsartikel!H4) -> 500g | V5: =_xlfn.TEXTJOIN(" ",TRUE,Migrationsartikel!L4) -> 500g | W5: =_xlfn.TEXTJOIN(" ",TRUE,Migrationsartikel!P4) -> 500g | X5: =Migrationsartikel!I4 -> Baslerbrot 500g | Y5: =Migrationsartikel!M4 -> Pain bâlois 500g | Z5: =Migrationsartikel!Q4 -> Pane di Basilea 500g | AA5: =Migrationsartikel!R4 -> 0.5 | AB5: =Migrationsartikel!T4 -> Gramm | AC5: =Migrationsartikel!S4 -> 100 | AD5: =Migrationsartikel!U4 -> (PCE) Stück | AE5: 1 - Normalsatz | AF5: =Migrationsartikel!AA4 -> 0 | AG5: Keine | AH5: =IF(Migrationsartikel!AB4="ja","true",FALSE) -> true | AI5: =IF(Migrationsartikel!AC4="ja","true",FALSE) -> true | AJ5: =IF(Migrationsartikel!AD4="ja","true",FALSE) -> true | AK5: =IF(Migrationsartikel!AE4="ja","true",FALSE) -> true | AL5: =IF(Migrationsartikel!AF4="ja","Denner Partner","") | AM5: =IF(Migrationsartikel!AG4="ja","true","false") -> false | AN5: =IF(AND(ISNUMBER(J5),J5>=100,J5<=999),"PLU",IF(AND(ISNUMBER(J5),J5>999),"GTIN","Kassentastenbelegung (ohne GTIN/PLU)")) -> Kassentastenbelegung (ohne GTIN/PLU) | AO5: true | AP5: Imp. Regio Lf-Nr 3 – 1005 | AQ5: S4H | AR5: true
B6: exartikel | E6: 00 - Einzelartikel | F6: ="Warengruppe>>"&_xlfn.TEXTJOIN(">>",TRUE,Migrationsartikel!V5:X5) -> Warengruppe>>Backwaren & Convenience>>Brot und Backwaren>>Backwaren andere | H6: ZHAW - Handelsware ohne Charge | J6: =Migrationsartikel!B5 -> 0 | L6: =_xlfn.TEXTJOIN(" ",TRUE,Migrationsartikel!F5:H5) -> Berliner aus der Region 1Stk | M6: =_xlfn.TEXTJOIN(" ",TRUE,Migrationsartikel!J5:L5) -> Boule de Berlin de la région 1pce | N6: =_xlfn.TEXTJOIN(" ",TRUE,Migrationsartikel!N5:P5) -> Berliner della regione 1pz | O6: =Migrationsartikel!F5 -> Berliner | P6: =Migrationsartikel!J5 -> Boule de Berlin | Q6: =Migrationsartikel!N5 -> Berliner | R6: =_xlfn.TEXTJOIN(" ",TRUE,Migrationsartikel!G5) -> aus der Region | S6: =_xlfn.TEXTJOIN(" ",TRUE,Migrationsartikel!K5) -> de la région | T6: =_xlfn.TEXTJOIN(" ",TRUE,Migrationsartikel!O5) -> della regione | U6: =_xlfn.TEXTJOIN(" ",TRUE,Migrationsartikel!H5) -> 1Stk | V6: =_xlfn.TEXTJOIN(" ",TRUE,Migrationsartikel!L5) -> 1pce | W6: =_xlfn.TEXTJOIN(" ",TRUE,Migrationsartikel!P5) -> 1pz | X6: =Migrationsartikel!I5 -> Berliner | Y6: =Migrationsartikel!M5 -> Boule de Berlin | Z6: =Migrationsartikel!Q5 -> Berliner | AA6: =Migrationsartikel!R5 -> 1 | AB6: =Migrationsartikel!T5 -> Stück | AC6: =Migrationsartikel!S5 -> 1 | AD6: =Migrationsartikel!U5 -> (PCE) Stück | AE6: 1 - Normalsatz | AF6: =Migrationsartikel!AA5 -> 0 | AG6: Keine | AH6: =IF(Migrationsartikel!AB5="ja","true",FALSE) -> true | AI6: =IF(Migrationsartikel!AC5="ja","true",FALSE) -> true | AJ6: =IF(Migrationsartikel!AD5="ja","true",FALSE) -> true | AK6: =IF(Migrationsartikel!AE5="ja","true",FALSE) -> true | AL6: =IF(Migrationsartikel!AF5="ja","Denner Partner","") | AM6: =IF(Migrationsartikel!AG5="ja","true","false") -> false | AN6: =IF(AND(ISNUMBER(J6),J6>=100,J6<=999),"PLU",IF(AND(ISNUMBER(J6),J6>999),"GTIN","Kassentastenbelegung (ohne GTIN/PLU)")) -> Kassentastenbelegung (ohne GTIN/PLU) | AO6: true | AP6: Imp. Regio Lf-Nr 4 – 1006 | AQ6: S4H | AR6: true
B7: exartikel | E7: 00 - Einzelartikel | F7: ="Warengruppe>>"&_xlfn.TEXTJOIN(">>",TRUE,Migrationsartikel!V6:X6) -> Warengruppe>>Backwaren & Convenience>>Brot und Backwaren>>Backwaren andere | H7: ZHAW - Handelsware ohne Charge | J7: =Migrationsartikel!B6 -> 0 | L7: =_xlfn.TEXTJOIN(" ",TRUE,Migrationsartikel!F6:H6) -> Birewegge aus der Region 1Stk | M7: =_xlfn.TEXTJOIN(" ",TRUE,Migrationsartikel!J6:L6) -> Birewegge de la région 1pce | N7: =_xlfn.TEXTJOIN(" ",TRUE,Migrationsartikel!N6:P6) -> Birewegge della regione 1pz | O7: =Migrationsartikel!F6 -> Birewegge | P7: =Migrationsartikel!J6 -> Birewegge | Q7: =Migrationsartikel!N6 -> Birewegge | R7: =_xlfn.TEXTJOIN(" ",TRUE,Migrationsartikel!G6) -> aus der Region | S7: =_xlfn.TEXTJOIN(" ",TRUE,Migrationsartikel!K6) -> de la région | T7: =_xlfn.TEXTJOIN(" ",TRUE,Migrationsartikel!O6) -> della regione | U7: =_xlfn.TEXTJOIN(" ",TRUE,Migrationsartikel!H6) -> 1Stk | V7: =_xlfn.TEXTJOIN(" ",TRUE,Migrationsartikel!L6) -> 1pce | W7: =_xlfn.TEXTJOIN(" ",TRUE,Migrationsartikel!P6) -> 1pz | X7: =Migrationsartikel!I6 -> Birewegge | Y7: =Migrationsartikel!M6 -> Birewegge | Z7: =Migrationsartikel!Q6 -> Birewegge | AA7: =Migrationsartikel!R6 -> 1 | AB7: =Migrationsartikel!T6 -> Stück | AC7: =Migrationsartikel!S6 -> 1 | AD7: =Migrationsartikel!U6 -> (PCE) Stück | AE7: 1 - Normalsatz | AF7: =Migrationsartikel!AA6 -> 0 | AG7: Keine | AH7: =IF(Migrationsartikel!AB6="ja","true",FALSE) -> true | AI7: =IF(Migrationsartikel!AC6="ja","true",FALSE) -> true | AJ7: =IF(Migrationsartikel!AD6="ja","true",FALSE) -> true | AK7: =IF(Migrationsartikel!AE6="ja","true",FALSE) -> true | AL7: =IF(Migrationsartikel!AF6="ja","Denner Partner","") | AM7: =IF(Migrationsartikel!AG6="ja","true","false") -> false | AN7: =IF(AND(ISNUMBER(J7),J7>=100,J7<=999),"PLU",IF(AND(ISNUMBER(J7),J7>999),"GTIN","Kassentastenbelegung (ohne GTIN/PLU)")) -> Kassentastenbelegung (ohne GTIN/PLU) | AO7: true | AP7: Imp. Regio Lf-Nr 5 – 1007 | AQ7: S4H | AR7: true
B8: exartikel | E8: 00 - Einzelartikel | F8: ="Warengruppe>>"&_xlfn.TEXTJOIN(">>",TRUE,Migrationsartikel!V7:X7) -> Warengruppe>>Backwaren & Convenience>>Brot und Backwaren>>Backwaren andere | H8: ZHAW - Handelsware ohne Charge | J8: =Migrationsartikel!B7 -> 0 | L8: =_xlfn.TEXTJOIN(" ",TRUE,Migrationsartikel!F7:H7) -> Bricelets aus der Region 1Stk | M8: =_xlfn.TEXTJOIN(" ",TRUE,Migrationsartikel!J7:L7) -> Bricelets de la région 1pce | N8: =_xlfn.TEXTJOIN(" ",TRUE,Migrationsartikel!N7:P7) -> Bricelets della regione 1pz | O8: =Migrationsartikel!F7 -> Bricelets | P8: =Migrationsartikel!J7 -> Bricelets | Q8: =Migrationsartikel!N7 -> Bricelets | R8: =_xlfn.TEXTJOIN(" ",TRUE,Migrationsartikel!G7) -> aus der Region | S8: =_xlfn.TEXTJOIN(" ",TRUE,Migrationsartikel!K7) -> de la région | T8: =_xlfn.TEXTJOIN(" ",TRUE,Migrationsartikel!O7) -> della regione | U8: =_xlfn.TEXTJOIN(" ",TRUE,Migrationsartikel!H7) -> 1Stk | V8: =_xlfn.TEXTJOIN(" ",TRUE,Migrationsartikel!L7) -> 1pce | W8: =_xlfn.TEXTJOIN(" ",TRUE,Migrationsartikel!P7) -> 1pz | X8: =Migrationsartikel!I7 -> Bricelets | Y8: =Migrationsartikel!M7 -> Bricelets | Z8: =Migrationsartikel!Q7 -> Bricelets | AA8: =Migrationsartikel!R7 -> 1 | AB8: =Migrationsartikel!T7 -> Stück | AC8: =Migrationsartikel!S7 -> 1 | AD8: =Migrationsartikel!U7 -> (PCE) Stück | AE8: 1 - Normalsatz | AF8: =Migrationsartikel!AA7 -> 0 | AG8: Keine | AH8: =IF(Migrationsartikel!AB7="ja","true",FALSE) -> true | AI8: =IF(Migrationsartikel!AC7="ja","true",FALSE) -> true | AJ8: =IF(Migrationsartikel!AD7="ja","true",FALSE) -> true | AK8: =IF(Migrationsartikel!AE7="ja","true",FALSE) -> true | AL8: =IF(Migrationsartikel!AF7="ja","Denner Partner","") | AM8: =IF(Migrationsartikel!AG7="ja","true","false") -> false | AN8: =IF(AND(ISNUMBER(J8),J8>=100,J8<=999),"PLU",IF(AND(ISNUMBER(J8),J8>999),"GTIN","Kassentastenbelegung (ohne GTIN/PLU)")) -> Kassentastenbelegung (ohne GTIN/PLU) | AO8: true | AP8: Imp. Regio Lf-Nr 6 – 1008 | AQ8: S4H | AR8: true
B9: exartikel | E9: 00 - Einzelartikel | F9: ="Warengruppe>>"&_xlfn.TEXTJOIN(">>",TRUE,Migrationsartikel!V8:X8) -> Warengruppe>>Backwaren & Convenience>>Brot und Backwaren>>Backwaren andere | H9: ZHAW - Handelsware ohne Charge | J9: =Migrationsartikel!B8 -> 0 | L9: =_xlfn.TEXTJOIN(" ",TRUE,Migrationsartikel!F8:H8) -> Brioche mit Füllung aus der Region 1Stk | M9: =_xlfn.TEXTJOIN(" ",TRUE,Migrationsartikel!J8:L8) -> Brioche fourée de la région 1pce | N9: =_xlfn.TEXTJOIN(" ",TRUE,Migrationsartikel!N8:P8) -> Brioche ripiena della regione 1pz | O9: =Migrationsartikel!F8 -> Brioche mit Füllung | P9: =Migrationsartikel!J8 -> Brioche fourée | Q9: =Migrationsartikel!N8 -> Brioche ripiena | R9: =_xlfn.TEXTJOIN(" ",TRUE,Migrationsartikel!G8) -> aus der Region | S9: =_xlfn.TEXTJOIN(" ",TRUE,Migrationsartikel!K8) -> de la région | T9: =_xlfn.TEXTJOIN(" ",TRUE,Migrationsartikel!O8) -> della regione | U9: =_xlfn.TEXTJOIN(" ",TRUE,Migrationsartikel!H8) -> 1Stk | V9: =_xlfn.TEXTJOIN(" ",TRUE,Migrationsartikel!L8) -> 1pce | W9: =_xlfn.TEXTJOIN(" ",TRUE,Migrationsartikel!P8) -> 1pz | X9: =Migrationsartikel!I8 -> Brioche mit Füllung | Y9: =Migrationsartikel!M8 -> Brioche fourée | Z9: =Migrationsartikel!Q8 -> Brioche ripiena | AA9: =Migrationsartikel!R8 -> 1 | AB9: =Migrationsartikel!T8 -> Stück | AC9: =Migrationsartikel!S8 -> 1 | AD9: =Migrationsartikel!U8 -> (PCE) Stück | AE9: 1 - Normalsatz | AF9: =Migrationsartikel!AA8 -> 0 | AG9: Keine | AH9: =IF(Migrationsartikel!AB8="ja","true",FALSE) -> true | AI9: =IF(Migrationsartikel!AC8="ja","true",FALSE) -> true | AJ9: =IF(Migrationsartikel!AD8="ja","true",FALSE) -> true | AK9: =IF(Migrationsartikel!AE8="ja","true",FALSE) -> true | AL9: =IF(Migrationsartikel!AF8="ja","Denner Partner","") | AM9: =IF(Migrationsartikel!AG8="ja","true","false") -> false | AN9: =IF(AND(ISNUMBER(J9),J9>=100,J9<=999),"PLU",IF(AND(ISNUMBER(J9),J9>999),"GTIN","Kassentastenbelegung (ohne GTIN/PLU)")) -> Kassentastenbelegung (ohne GTIN/PLU) | AO9: true | AP9: Imp. Regio Lf-Nr 7 – 1009 | AQ9: S4H | AR9: true
B10: exartikel | E10: 00 - Einzelartikel | F10: ="Warengruppe>>"&_xlfn.TEXTJOIN(">>",TRUE,Migrationsartikel!V9:X9) -> Warengruppe>>Backwaren & Convenience>>Brot und Backwaren>>Backwaren andere | H10: ZHAW - Handelsware ohne Charge | J10: =Migrationsartikel!B9 -> 0 | L10: =_xlfn.TEXTJOIN(" ",TRUE,Migrationsartikel!F9:H9) -> Brot vom Beck aus der Region 1Stk | M10: =_xlfn.TEXTJOIN(" ",TRUE,Migrationsartikel!J9:L9) -> Pain du boulanger de la région 1pce | N10: =_xlfn.TEXTJOIN(" ",TRUE,Migrationsartikel!N9:P9) -> Pane del panettiere della regione 1pz | O10: =Migrationsartikel!F9 -> Brot vom Beck | P10: =Migrationsartikel!J9 -> Pain du boulanger | Q10: =Migrationsartikel!N9 -> Pane del panettiere | R10: =_xlfn.TEXTJOIN(" ",TRUE,Migrationsartikel!G9) -> aus der Region | S10: =_xlfn.TEXTJOIN(" ",TRUE,Migrationsartikel!K9) -> de la région | T10: =_xlfn.TEXTJOIN(" ",TRUE,Migrationsartikel!O9) -> della regione | U10: =_xlfn.TEXTJOIN(" ",TRUE,Migrationsartikel!H9) -> 1Stk | V10: =_xlfn.TEXTJOIN(" ",TRUE,Migrationsartikel!L9) -> 1pce | W10: =_xlfn.TEXTJOIN(" ",TRUE,Migrationsartikel!P9) -> 1pz | X10: =Migrationsartikel!I9 -> Brot vom Beck | Y10: =Migrationsartikel!M9 -> Pain du boulanger | Z10: =Migrationsartikel!Q9 -> Pane del panettiere | AA10: =Migrationsartikel!R9 -> 1 | AB10: =Migrationsartikel!T9 -> Stück | AC10: =Migrationsartikel!S9 -> 1 | AD10: =Migrationsartikel!U9 -> (PCE) Stück | AE10: 1 - Normalsatz | AF10: =Migrationsartikel!AA9 -> 0 | AG10: Keine | AH10: =IF(Migrationsartikel!AB9="ja","true",FALSE) -> true | AI10: =IF(Migrationsartikel!AC9="ja","true",FALSE) -> true | AJ10: =IF(Migrationsartikel!AD9="ja","true",FALSE) -> true | AK10: =IF(Migrationsartikel!AE9="ja","true",FALSE) -> true | AL10: =IF(Migrationsartikel!AF9="ja","Denner Partner","") | AM10: =IF(Migrationsartikel!AG9="ja","true","false") -> false | AN10: =IF(AND(ISNUMBER(J10),J10>=100,J10<=999),"PLU",IF(AND(ISNUMBER(J10),J10>999),"GTIN","Kassentastenbelegung (ohne GTIN/PLU)")) -> Kassentastenbelegung (ohne GTIN/PLU) | AO10: true | AP10: Imp. Regio Lf-Nr 8 – 1010 | AQ10: S4H | AR10: true
B11: exartikel | E11: 00 - Einzelartikel | F11: ="Warengruppe>>"&_xlfn.TEXTJOIN(">>",TRUE,Migrationsartikel!V10:X10) -> Warengruppe>>Backwaren & Convenience>>Brot und Backwaren>>Backwaren andere | H11: ZHAW - Handelsware ohne Charge | J11: =Migrationsartikel!B10 -> 0 | L11: =_xlfn.TEXTJOIN(" ",TRUE,Migrationsartikel!F10:H10) -> Brottheke aus der Region 1Stk | M11: =_xlfn.TEXTJOIN(" ",TRUE,Migrationsartikel!J10:L10) -> Comptoir à pain de la région 1pce | N11: =_xlfn.TEXTJOIN(" ",TRUE,Migrationsartikel!N10:P10) -> Banco pane della regione 1pz | O11: =Migrationsartikel!F10 -> Brottheke | P11: =Migrationsartikel!J10 -> Comptoir à pain | Q11: =Migrationsartikel!N10 -> Banco pane | R11: =_xlfn.TEXTJOIN(" ",TRUE,Migrationsartikel!G10) -> aus der Region | S11: =_xlfn.TEXTJOIN(" ",TRUE,Migrationsartikel!K10) -> de la région | T11: =_xlfn.TEXTJOIN(" ",TRUE,Migrationsartikel!O10) -> della regione | U11: =_xlfn.TEXTJOIN(" ",TRUE,Migrationsartikel!H10) -> 1Stk | V11: =_xlfn.TEXTJOIN(" ",TRUE,Migrationsartikel!L10) -> 1pce | W11: =_xlfn.TEXTJOIN(" ",TRUE,Migrationsartikel!P10) -> 1pz | X11: =Migrationsartikel!I10 -> Brottheke | Y11: =Migrationsartikel!M10 -> Comptoir à pain | Z11: =Migrationsartikel!Q10 -> Banco pane | AA11: =Migrationsartikel!R10 -> 1 | AB11: =Migrationsartikel!T10 -> Stück | AC11: =Migrationsartikel!S10 -> 1 | AD11: =Migrationsartikel!U10 -> (PCE) Stück | AE11: 1 - Normalsatz | AF11: =Migrationsartikel!AA10 -> 0 | AG11: Keine | AH11: =IF(Migrationsartikel!AB10="ja","true",FALSE) -> true | AI11: =IF(Migrationsartikel!AC10="ja","true",FALSE) -> true | AJ11: =IF(Migrationsartikel!AD10="ja","true",FALSE) -> true | AK11: =IF(Migrationsartikel!AE10="ja","true",FALSE) -> true | AL11: =IF(Migrationsartikel!AF10="ja","Denner Partner","") | AM11: =IF(Migrationsartikel!AG10="ja","true","false") -> false | AN11: =IF(AND(ISNUMBER(J11),J11>=100,J11<=999),"PLU",IF(AND(ISNUMBER(J11),J11>999),"GTIN","Kassentastenbelegung (ohne GTIN/PLU)")) -> Kassentastenbelegung (ohne GTIN/PLU) | AO11: true | AP11: Imp. Regio Lf-Nr 9 – 1011 | AQ11: S4H | AR11: true
B12: exartikel | E12: 00 - Einzelartikel | F12: ="Warengruppe>>"&_xlfn.TEXTJOIN(">>",TRUE,Migrationsartikel!V11:X11) -> Warengruppe>>Backwaren & Convenience>>Brot und Backwaren>>Backwaren andere | H12: ZHAW - Handelsware ohne Charge | J12: =Migrationsartikel!B11 -> 0 | L12: =_xlfn.TEXTJOIN(" ",TRUE,Migrationsartikel!F11:H11) -> Bürli aus der Region 1Stk | M12: =_xlfn.TEXTJOIN(" ",TRUE,Migrationsartikel!J11:L11) -> Bürli de la région 1pce | N12: =_xlfn.TEXTJOIN(" ",TRUE,Migrationsartikel!N11:P11) -> Bürli della regione 1pz | O12: =Migrationsartikel!F11 -> Bürli | P12: =Migrationsartikel!J11 -> Bürli | Q12: =Migrationsartikel!N11 -> Bürli | R12: =_xlfn.TEXTJOIN(" ",TRUE,Migrationsartikel!G11) -> aus der Region | S12: =_xlfn.TEXTJOIN(" ",TRUE,Migrationsartikel!K11) -> de la région | T12: =_xlfn.TEXTJOIN(" ",TRUE,Migrationsartikel!O11) -> della regione | U12: =_xlfn.TEXTJOIN(" ",TRUE,Migrationsartikel!H11) -> 1Stk | V12: =_xlfn.TEXTJOIN(" ",TRUE,Migrationsartikel!L11) -> 1pce | W12: =_xlfn.TEXTJOIN(" ",TRUE,Migrationsartikel!P11) -> 1pz | X12: =Migrationsartikel!I11 -> Bürli | Y12: =Migrationsartikel!M11 -> Bürli | Z12: =Migrationsartikel!Q11 -> Bürli | AA12: =Migrationsartikel!R11 -> 1 | AB12: =Migrationsartikel!T11 -> Stück | AC12: =Migrationsartikel!S11 -> 1 | AD12: =Migrationsartikel!U11 -> (PCE) Stück | AE12: 1 - Normalsatz | AF12: =Migrationsartikel!AA11 -> 0 | AG12: Keine | AH12: =IF(Migrationsartikel!AB11="ja","true",FALSE) -> true | AI12: =IF(Migrationsartikel!AC11="ja","true",FALSE) -> true | AJ12: =IF(Migrationsartikel!AD11="ja","true",FALSE) -> true | AK12: =IF(Migrationsartikel!AE11="ja","true",FALSE) -> true | AL12: =IF(Migrationsartikel!AF11="ja","Denner Partner","") | AM12: =IF(Migrationsartikel!AG11="ja","true","false") -> false | AN12: =IF(AND(ISNUMBER(J12),J12>=100,J12<=999),"PLU",IF(AND(ISNUMBER(J12),J12>999),"GTIN","Kassentastenbelegung (ohne GTIN/PLU)")) -> Kassentastenbelegung (ohne GTIN/PLU) | AO12: true | AP12: Imp. Regio Lf-Nr 10 – 1012 | AQ12: S4H | AR12: true
B13: exartikel | E13: 00 - Einzelartikel | F13: ="Warengruppe>>"&_xlfn.TEXTJOIN(">>",TRUE,Migrationsartikel!V12:X12) -> Warengruppe>>Backwaren & Convenience>>Brot und Backwaren>>Backwaren andere | H13: ZHAW - Handelsware ohne Charge | J13: =Migrationsartikel!B12 -> 0 | L13: =_xlfn.TEXTJOIN(" ",TRUE,Migrationsartikel!F12:H12) -> Buttergipfel aus der Region 1Stk | M13: =_xlfn.TEXTJOIN(" ",TRUE,Migrationsartikel!J12:L12) -> Croissant au beurre de la région 1pce | N13: =_xlfn.TEXTJOIN(" ",TRUE,Migrationsartikel!N12:P12) -> Cornetto al burro della regione 1pz | O13: =Migrationsartikel!F12 -> Buttergipfel | P13: =Migrationsartikel!J12 -> Croissant au beurre | Q13: =Migrationsartikel!N12 -> Cornetto al burro | R13: =_xlfn.TEXTJOIN(" ",TRUE,Migrationsartikel!G12) -> aus der Region | S13: =_xlfn.TEXTJOIN(" ",TRUE,Migrationsartikel!K12) -> de la région | T13: =_xlfn.TEXTJOIN(" ",TRUE,Migrationsartikel!O12) -> della regione | U13: =_xlfn.TEXTJOIN(" ",TRUE,Migrationsartikel!H12) -> 1Stk | V13: =_xlfn.TEXTJOIN(" ",TRUE,Migrationsartikel!L12) -> 1pce | W13: =_xlfn.TEXTJOIN(" ",TRUE,Migrationsartikel!P12) -> 1pz | X13: =Migrationsartikel!I12 -> Buttergipfel | Y13: =Migrationsartikel!M12 -> Croissant au beurre | Z13: =Migrationsartikel!Q12 -> Cornetto al burro | AA13: =Migrationsartikel!R12 -> 1 | AB13: =Migrationsartikel!T12 -> Stück | AC13: =Migrationsartikel!S12 -> 1 | AD13: =Migrationsartikel!U12 -> (PCE) Stück | AE13: 1 - Normalsatz | AF13: =Migrationsartikel!AA12 -> 0 | AG13: Keine | AH13: =IF(Migrationsartikel!AB12="ja","true",FALSE) -> true | AI13: =IF(Migrationsartikel!AC12="ja","true",FALSE) -> true | AJ13: =IF(Migrationsartikel!AD12="ja","true",FALSE) -> true | AK13: =IF(Migrationsartikel!AE12="ja","true",FALSE) -> true | AL13: =IF(Migrationsartikel!AF12="ja","Denner Partner","") | AM13: =IF(Migrationsartikel!AG12="ja","true","false") -> false | AN13: =IF(AND(ISNUMBER(J13),J13>=100,J13<=999),"PLU",IF(AND(ISNUMBER(J13),J13>999),"GTIN","Kassentastenbelegung (ohne GTIN/PLU)")) -> Kassentastenbelegung (ohne GTIN/PLU) | AO13: true | AP13: Imp. Regio Lf-Nr 11 – 1013 | AQ13: S4H | AR13: true
B14: exartikel | E14: 00 - Einzelartikel | F14: ="Warengruppe>>"&_xlfn.TEXTJOIN(">>",TRUE,Migrationsartikel!V13:X13) -> Warengruppe>>Backwaren & Convenience>>Brot und Backwaren>>Backwaren andere | H14: ZHAW - Handelsware ohne Charge | J14: =Migrationsartikel!B13 -> 0 | L14: =_xlfn.TEXTJOIN(" ",TRUE,Migrationsartikel!F13:H13) -> Butterzopf aus der Region 300g | M14: =_xlfn.TEXTJOIN(" ",TRUE,Migrationsartikel!J13:L13) -> Tresse de la région 300g | N14: =_xlfn.TEXTJOIN(" ",TRUE,Migrationsartikel!N13:P13) -> Treccia della regione 300g | O14: =Migrationsartikel!F13 -> Butterzopf | P14: =Migrationsartikel!J13 -> Tresse | Q14: =Migrationsartikel!N13 -> Treccia | R14: =_xlfn.TEXTJOIN(" ",TRUE,Migrationsartikel!G13) -> aus der Region | S14: =_xlfn.TEXTJOIN(" ",TRUE,Migrationsartikel!K13) -> de la région | T14: =_xlfn.TEXTJOIN(" ",TRUE,Migrationsartikel!O13) -> della regione | U14: =_xlfn.TEXTJOIN(" ",TRUE,Migrationsartikel!H13) -> 300g | V14: =_xlfn.TEXTJOIN(" ",TRUE,Migrationsartikel!L13) -> 300g | W14: =_xlfn.TEXTJOIN(" ",TRUE,Migrationsartikel!P13) -> 300g | X14: =Migrationsartikel!I13 -> Butterzopf 300g | Y14: =Migrationsartikel!M13 -> Tresse 300g | Z14: =Migrationsartikel!Q13 -> Treccia 300g | AA14: =Migrationsartikel!R13 -> 0.3 | AB14: =Migrationsartikel!T13 -> Gramm | AC14: =Migrationsartikel!S13 -> 100 | AD14: =Migrationsartikel!U13 -> (PCE) Stück | AE14: 1 - Normalsatz | AF14: =Migrationsartikel!AA13 -> 0 | AG14: Keine | AH14: =IF(Migrationsartikel!AB13="ja","true",FALSE) -> true | AI14: =IF(Migrationsartikel!AC13="ja","true",FALSE) -> true | AJ14: =IF(Migrationsartikel!AD13="ja","true",FALSE) -> true | AK14: =IF(Migrationsartikel!AE13="ja","true",FALSE) -> true | AL14: =IF(Migrationsartikel!AF13="ja","Denner Partner","") | AM14: =IF(Migrationsartikel!AG13="ja","true","false") -> false | AN14: =IF(AND(ISNUMBER(J14),J14>=100,J14<=999),"PLU",IF(AND(ISNUMBER(J14),J14>999),"GTIN","Kassentastenbelegung (ohne GTIN/PLU)")) -> Kassentastenbelegung (ohne GTIN/PLU) | AO14: true | AP14: Imp. Regio Lf-Nr 12 – 1014 | AQ14: S4H | AR14: true
... B249: exartikel | E249: 00 - Einzelartikel | F249: ="Warengruppe>>"&_xlfn.TEXTJOIN(">>",TRUE,Migrationsartikel!V248:X248) -> Warengruppe>>Früchte und Gemüse>>Früchte und Gemüse>>Früchte | H249: ZHAW - Handelsware ohne Charge | J249: =Migrationsartikel!B248 -> 2202381000008 | L249: =_xlfn.TEXTJOIN(" ",TRUE,Migrationsartikel!F248:H248) -> Äpfel Gala Kl. 1 gepackt | M249: =_xlfn.TEXTJOIN(" ",TRUE,Migrationsartikel!J248:L248) -> Pommes Gala Cl. 1 emballé | N249: =_xlfn.TEXTJOIN(" ",TRUE,Migrationsartikel!N248:P248) -> Mele Gala Cl. 1 confezionato | O249: =Migrationsartikel!F248 -> Äpfel Gala | P249: =Migrationsartikel!J248 -> Pommes Gala | Q249: =Migrationsartikel!N248 -> Mele Gala | R249: =_xlfn.TEXTJOIN(" ",TRUE,Migrationsartikel!G248) -> Kl. 1 gepackt | S249: =_xlfn.TEXTJOIN(" ",TRUE,Migrationsartikel!K248) -> Cl. 1 emballé | T249: =_xlfn.TEXTJOIN(" ",TRUE,Migrationsartikel!O248) -> Cl. 1 confezionato | U249: =_xlfn.TEXTJOIN(" ",TRUE,Migrationsartikel!H248) | V249: =_xlfn.TEXTJOIN(" ",TRUE,Migrationsartikel!L248) | W249: =_xlfn.TEXTJOIN(" ",TRUE,Migrationsartikel!P248) | X249: =Migrationsartikel!I248 -> Äpfel Gala Kl. 1 gepackt | Y249: =Migrationsartikel!M248 -> Pommes Gala cl. 1 emballé | Z249: =Migrationsartikel!Q248 -> Mele Gala cl. 1 confezionato | AA249: =Migrationsartikel!R248 -> 1 | AB249: =Migrationsartikel!T248 -> Kilogramm | AC249: =Migrationsartikel!S248 -> 1 | AD249: =Migrationsartikel!U248 -> (PCE) Stück | AE249: 1 - Normalsatz | AF249: =Migrationsartikel!AA248 -> 0 | AG249: Keine | AH249: =IF(Migrationsartikel!AB248="ja","true",FALSE) -> true | AI249: =IF(Migrationsartikel!AC248="ja","true",FALSE) -> true | AJ249: =IF(Migrationsartikel!AD248="ja","true",FALSE) -> true | AK249: =IF(Migrationsartikel!AE248="ja","true",FALSE) -> true | AL249: =IF(Migrationsartikel!AF248="ja","Denner Partner","") | AM249: =IF(Migrationsartikel!AG248="ja","true","false") -> false | AN249: =IF(AND(ISNUMBER(J249),J249>=100,J249<=999),"PLU",IF(AND(ISNUMBER(J249),J249>999),"GTIN","Kassentastenbelegung (ohne GTIN/PLU)")) -> GTIN | AO249: true | AP249: Imp. Regio Lf-Nr 265 – 1249 | AQ249: S4H | AR249: true

Sheet Migrationsartikel
A1: Lf Nr. | B1: PLU-Nr. neu | C1: Stk / kg | D1: PAZ | E1: EAN | F1: Gestellbeschriftung 1 Max. 22 Zeichen (d) | G1: Gestellbeschriftung 2 Max. 22 Zeichen (d) | H1: Gestellbeschriftung 3 Max. 4-8 Zeichen (d) | I1: Kassenbontext Max. 28 Zeichen (d) | J1: Gestellbeschriftung 1 Max. 22 Zeichen (f) | K1: Gestellbeschriftung 2 Max. 22 Zeichen (f) | L1: Gestellbeschriftung 3 Max. 4-8 Zeichen (f) | M1: Kassenbontext Max. 28 Zeichen (f) | N1: Gestellbeschriftung 1 Max. 22 Zeichen (i) | O1: Gestellbeschriftung 2 Max. 22 Zeichen (i) | P1: Gestellbeschriftung 3 Max. 4-8 Zeichen (i) | Q1: Kassenbontext Max. 28 Zeichen (i) | R1: Nettoinhalt | S1: Grundpreismenge Feld 1 | T1: Grundpreismenge Feld 2 | U1: Basismengeneinheit Waage = Kg Verkauf = Stk = Stk Relevant für Berechnungen im MDM/SAP | V1: Warengruppe 1. Feld | W1: Warengruppe 2. Feld | X1: Warengruppe 3. Feld | Y1: Steuerklassifikation | Z1: Altersbegrenzung | AA1: Depot | AB1: Rabatt zugelassen | AC1: Rückgabe zugelassen | AD1: Preisänderung zugelassen | AE1: Etiketten-druck | AF1: Shop-in-Shop | AG1: Fremdartikel | AH1: Qualitätsanforderung geprüft | AI1: Verkaufskonditionen | AJ1: Lieferant
A2: 1 | C2: Stk | D2: Nein | F2: Baguette | G2: aus der Region | H2: 250g | I2: Baguette 250g | J2: Baguette | K2: de la région | L2: 250g | M2: Baguette 250g | N2: Baguette | O2: della regione | P2: 250g | Q2: Baguette 250g | R2: 0.25 | S2: 100 | T2: Gramm | U2: (PCE) Stück | V2: Backwaren & Convenience | W2: Brot und Backwaren | X2: Backwaren andere | AB2: ja | AC2: ja | AD2: ja | AE2: ja | AF2: - | AG2: - | AH2: ja | AI2: 0.05 | AJ2: -
A3: 2 | C3: Stk | D3: Nein | F3: Baslerbrot | G3: aus der Region | H3: 250g | I3: Baslerbrot 250g | J3: Pain bâlois | K3: de la région | L3: 250g | M3: Pain bâlois 250g | N3: Pane di Basilea | O3: della regione | P3: 250g | Q3: Pane di Basilea 250g | R3: 0.25 | S3: 100 | T3: Gramm | U3: (PCE) Stück | V3: Backwaren & Convenience | W3: Brot und Backwaren | X3: Backwaren andere | AB3: ja | AC3: ja | AD3: ja | AE3: ja | AF3: - | AG3: - | AH3: ja | AI3: 0.05 | AJ3: -
A4: 3 | C4: Stk | D4: Nein | F4: Baslerbrot | G4: aus der Region | H4: 500g | I4: Baslerbrot 500g | J4: Pain bâlois | K4: de la région | L4: 500g | M4: Pain bâlois 500g | N4: Pane di Basilea | O4: della regione | P4: 500g | Q4: Pane di Basilea 500g | R4: 0.5 | S4: 100 | T4: Gramm | U4: (PCE) Stück | V4: Backwaren & Convenience | W4: Brot und Backwaren | X4: Backwaren andere | AB4: ja | AC4: ja | AD4: ja | AE4: ja | AF4: - | AG4: - | AH4: ja | AI4: 0.05 | AJ4: -
A5: 4 | C5: Stk | D5: Nein | F5: Berliner | G5: aus der Region | H5: 1Stk | I5: Berliner | J5: Boule de Berlin | K5: de la région | L5: 1pce | M5: Boule de Berlin | N5: Berliner | O5: della regione | P5: 1pz | Q5: Berliner | R5: 1 | S5: 1 | T5: Stück | U5: (PCE) Stück | V5: Backwaren & Convenience | W5: Brot und Backwaren | X5: Backwaren andere | AB5: ja | AC5: ja | AD5: ja | AE5: ja | AF5: - | AG5: - | AH5: ja | AI5: 0.05 | AJ5: -
A6: 5 | C6: Stk | D6: Nein | F6: Birewegge | G6: aus der Region | H6: 1Stk | I6: Birewegge | J6: Birewegge | K6: de la région | L6: 1pce | M6: Birewegge | N6: Birewegge | O6: della regione | P6: 1pz | Q6: Birewegge | R6: 1 | S6: 1 | T6: Stück | U6: (PCE) Stück | V6: Backwaren & Convenience | W6: Brot und Backwaren | X6: Backwaren andere | AB6: ja | AC6: ja | AD6: ja | AE6: ja | AF6: - | AG6: - | AH6: ja | AI6: 0.05 | AJ6: -
A7: 6 | C7: Stk | D7: Nein | F7: Bricelets | G7: aus der Region | H7: 1Stk | I7: Bricelets | J7: Bricelets | K7: de la région | L7: 1pce | M7: Bricelets | N7: Bricelets | O7: della regione | P7: 1pz | Q7: Bricelets | R7: 1 | S7: 1 | T7: Stück | U7: (PCE) Stück | V7: Backwaren & Convenience | W7: Brot und Backwaren | X7: Backwaren andere | AB7: ja | AC7: ja | AD7: ja | AE7: ja | AF7: - | AG7: - | AH7: ja | AI7: 0.05 | AJ7: -
A8: 7 | C8: Stk | D8: Nein | F8: Brioche mit Füllung | G8: aus der Region | H8: 1Stk | I8: Brioche mit Füllung | J8: Brioche fourée | K8: de la région | L8: 1pce | M8: Brioche fourée | N8: Brioche ripiena | O8: della regione | P8: 1pz | Q8: Brioche ripiena | R8: 1 | S8: 1 | T8: Stück | U8: (PCE) Stück | V8: Backwaren & Convenience | W8: Brot und Backwaren | X8: Backwaren andere | AB8: ja | AC8: ja | AD8: ja | AE8: ja | AF8: - | AG8: - | AH8: ja | AI8: 0 | AJ8: -
A9: 8 | C9: Stk | D9: Nein | F9: Brot vom Beck | G9: aus der Region | H9: 1Stk | I9: Brot vom Beck | J9: Pain du boulanger | K9: de la région | L9: 1pce | M9: Pain du boulanger | N9: Pane del panettiere | O9: della regione | P9: 1pz | Q9: Pane del panettiere | R9: 1 | S9: 1 | T9: Stück | U9: (PCE) Stück | V9: Backwaren & Convenience | W9: Brot und Backwaren | X9: Backwaren andere | AB9: ja | AC9: ja | AD9: ja | AE9: ja | AF9: - | AG9: - | AH9: ja | AI9: 0 | AJ9: -
A10: 9 | C10: Stk | D10: Nein | F10: Brottheke | G10: aus der Region | H10: 1Stk | I10: Brottheke | J10: Comptoir à pain | K10: de la région | L10: 1pce | M10: Comptoir à pain | N10: Banco pane | O10: della regione | P10: 1pz | Q10: Banco pane | R10: 1 | S10: 1 | T10: Stück | U10: (PCE) Stück | V10: Backwaren & Convenience | W10: Brot und Backwaren | X10: Backwaren andere | AB10: ja | AC10: ja | AD10: ja | AE10: ja | AF10: - | AG10: - | AH10: ja | AI10: 0 | AJ10: -
A11: 10 | C11: Stk | D11: Nein | F11: Bürli | G11: aus der Region | H11: 1Stk | I11: Bürli | J11: Bürli | K11: de la région | L11: 1pce | M11: Bürli | N11: Bürli | O11: della regione | P11: 1pz | Q11: Bürli | R11: 1 | S11: 1 | T11: Stück | U11: (PCE) Stück | V11: Backwaren & Convenience | W11: Brot und Backwaren | X11: Backwaren andere | AB11: ja | AC11: ja | AD11: ja | AE11: ja | AF11: - | AG11: - | AH11: ja | AI11: 0.05 | AJ11: -
A12: 11 | C12: Stk | D12: Nein | F12: Buttergipfel | G12: aus der Region | H12: 1Stk | I12: Buttergipfel | J12: Croissant au beurre | K12: de la région | L12: 1pce | M12: Croissant au beurre | N12: Cornetto al burro | O12: della regione | P12: 1pz | Q12: Cornetto al burro | R12: 1 | S12: 1 | T12: Stück | U12: (PCE) Stück | V12: Backwaren & Convenience | W12: Brot und Backwaren | X12: Backwaren andere | AB12: ja | AC12: ja | AD12: ja | AE12: ja | AF12: - | AG12: - | AH12: ja | AI12: 0.05 | AJ12: -
A13: 12 | C13: Stk | D13: Nein | F13: Butterzopf | G13: aus der Region | H13: 300g | I13: Butterzopf 300g | J13: Tresse | K13: de la région | L13: 300g | M13: Tresse 300g | N13: Treccia | O13: della regione | P13: 300g | Q13: Treccia 300g | R13: 0.3 | S13: 100 | T13: Gramm | U13: (PCE) Stück | V13: Backwaren & Convenience | W13: Brot und Backwaren | X13: Backwaren andere | AB13: ja | AC13: ja | AD13: ja | AE13: ja | AF13: - | AG13: - | AH13: ja | AI13: 0.05 | AJ13: -
... A69: 64 | C69: Stk | D69: Nein | F69: Salatsauce | G69: aus der Region | H69: 1l | I69: Salatsauce 1l | J69: Sauce à salade | K69: de la région | L69: 1l | M69: Sauce à salade 1l | N69: Salsa per insalata | O69: della regione | P69: 1l | Q69: Salsa per insalata 1l | R69: 1 | S69: 1 | T69: Liter | U69: (PCE) Stück | V69: Food | W69: Öl/Essig/Salatsaucen | X69: Öl/Essig/Salatsaucen | AB69: ja | AC69: ja | AD69: ja | AE69: ja | AF69: - | AG69: - | AH69: ja | AI69: 0 | AJ69: -
A70: 65 | B70: 861 | C70: kg | D70: Nein | F70: Bauernschüblig | G70: aus der Region | H70: 2Stk | I70: Bauernschüblig 2Stk | J70: Schüblig | K70: de la région | L70: 2pces | M70: Schüblig 2pces | N70: Schüblig contadino | O70: della regione | P70: 2pz | Q70: Schüblig contadino 2pz | R70: 2 | S70: 100 | T70: Gramm | U70: (PCE) Stück | V70: Frische | W70: Fleisch- und Wurstwaren | X70: Wurstwaren | AB70: ja | AC70: ja | AD70: ja | AE70: ja | AF70: - | AG70: - | AH70: ja | AI70: 0.05 | AJ70: -
A71: 66 | C71: Stk | D71: Nein | F71: Büscion | G71: aus der Region | H71: 2Stk | I71: Büscion 2Stk | J71: Büscion 2pces | K71: de la région | L71: 2pces | M71: Büscion | N71: Büscion | O71: della regione | P71: 2pz | Q71: Büscion 2pz | R71: 2 | S71: 1 | T71: Stück | U71: (PCE) Stück | V71: Frische | W71: Käse | X71: Käse | AB71: ja | AC71: ja | AD71: ja | AE71: ja | AF71: - | AG71: - | AH71: ja | AI71: 0.05 | AJ71: -
A72: 67 | C72: Stk | D72: Nein | F72: Butter | G72: aus der Region | H72: 100g | I72: Butter 100g | J72: Beurre | K72: de la région | L72: 100g | M72: Beurre 100g | N72: Burro | O72: della regione | P72: 100g | Q72: Burro 100g | R72: 0.1 | S72: 100 | T72: Gramm | U72: (PCE) Stück | V72: Frische | W72: Molkereiprodukte & Eier | X72: Milchprodukte | AB72: ja | AC72: ja | AD72: ja | AE72: ja | AF72: - | AG72: - | AH72: ja | AI72: 0.05 | AJ72: -
A73: 68 | C73: Stk | D73: Nein | F73: Butter | G73: aus der Region | H73: 200g | I73: Butter 200g | J73: Beurre | K73: de la région | L73: 200g | M73: Beurre 200g | N73: Burro | O73: della regione | P73: 200g | Q73: Burro 200g | R73: 0.2 | S73: 100 | T73: Gramm | U73: (PCE) Stück | V73: Frische | W73: Molkereiprodukte & Eier | X73: Milchprodukte | AB73: ja | AC73: ja | AD73: ja | AE73: ja | AF73: - | AG73: - | AH73: ja | AI73: 0.05 | AJ73: -
A74: 69 | C74: Stk | D74: Nein | F74: Butter | G74: aus der Region | H74: 250g | I74: Butter 250g | J74: Beurre | K74: de la région | L74: 250g | M74: Beurre 250g | N74: Burro | O74: della regione | P74: 250g | Q74: Burro 250g | R74: 0.25 | S74: 100 | T74: Gramm | U74: (PCE) Stück | V74: Frische | W74: Molkereiprodukte & Eier | X74: Milchprodukte | AB74: ja | AC74: ja | AD74: ja | AE74: ja | AF74: - | AG74: - | AH74: ja | AI74: 0.05 | AJ74: -
A75: 70 | B75: 862 | C75: kg | D75: Nein | F75: Cervelat | G75: aus der Region | H75: 2Stk | I75: Cervelat 2Stk | J75: Cervelas | K75: de la région | L75: 2pces | M75: Cervelas 2pces | N75: Cervelat | O75: della regione | P75: 2pz | Q75: Cervelat 2pz | R75: 2 | S75: 100 | T75: Gramm | U75: (PCE) Stück | V75: Frische | W75: Fleisch- und Wurstwaren | X75: Wurstwaren | AB75: ja | AC75: ja | AD75: ja | AE75: ja | AF75: - | AG75: - | AH75: ja | AI75: 0.05 | AJ75: -
A76: 71 | C76: Stk | D76: Nein | F76: Doppel-Rahm | G76: aus der Region | H76: 200ml | I76: Doppel-Rahm 200ml | J76: Double crème | K76: de la région | L76: 200ml | M76: Double crème 200ml | N76: Panna doppia | O76: della regione | P76: 200ml | Q76: Panna 200ml | R76: 0.2 | S76: 100 | T76: Milliliter | U76: (PCE) Stück | V76: Frische | W76: Molkereiprodukte & Eier | X76: Milchprodukte | AB76: ja | AC76: ja | AD76: ja | AE76: ja | AF76: - | AG76: - | AH76: ja | AI76: 0.05 | AJ76: -
A77: 72 | C77: Stk | D77: Nein | F77: Doppel-Rahm | G77: aus der Region | H77: 250ml | I77: Doppel-Rahm 250ml | J77: Double crème | K77: de la région | L77: 250ml | M77: Double crème 250ml | N77: Panna doppia | O77: della regione | P77: 250ml | Q77: Panna 250ml | R77: 0.25 | S77: 100 | T77: Milliliter | U77: (PCE) Stück | V77: Frische | W77: Molkereiprodukte & Eier | X77: Milchprodukte | AB77: ja | AC77: ja | AD77: ja | AE77: ja | AF77: - | AG77: - | AH77: ja | AI77: 0.05 | AJ77: -
A78: 73 | B78: 829 | C78: kg | D78: Nein | F78: Eglifilet | G78: aus der Region | H78: 1Stk | I78: Eglifilet | J78: Filet de perche | K78: de la région | L78: 1pce | M78: Filet de perche | N78: Filetto di persico | O78: della regione | P78: 1pz | Q78: Filetto di persico | R78: 1 | S78: 100 | T78: Gramm | U78: (PCE) Stück | V78: Frische | W78: SB - Fleisch | X78: Fisch | AB78: ja | AC78: ja | AD78: ja | AE78: ja | AF78: - | AG78: - | AH78: ja | AI78: 0.05 | AJ78: -
A79: 74 | C79: Stk | D79: Nein | F79: Eier | G79: aus der Region | H79: 4Stk | I79: Eier 4Stk | J79: Oeufs | K79: de la région | L79: 4pces | M79: Oeufs 4pces | N79: Uova | O79: della regione | P79: 4pz | Q79: Uova 4pz | R79: 4 | S79: 1 | T79: Stück | U79: (PCE) Stück | V79: Frische | W79: Molkereiprodukte & Eier | X79: Eier | AB79: ja | AC79: ja | AD79: ja | AE79: ja | AF79: - | AG79: - | AH79: ja | AI79: 0.05 | AJ79: -
A80: 75 | C80: Stk | D80: Nein | F80: Eier | G80: aus der Region | H80: 10Stk | I80: Eier 10Stk | J80: Oeufs | K80: de la région | L80: 10pces | M80: Oeufs 10pces | N80: Uova | O80: della regione | P80: 10pz | Q80: Uova 10pz | R80: 10 | S80: 1 | T80: Stück | U80: (PCE) Stück | V80: Frische | W80: Molkereiprodukte & Eier | X80: Eier | AB80: ja | AC80: ja | AD80: ja | AE80: ja | AF80: - | AG80: - | AH80: ja | AI80: 0.05 | AJ80: -
A81: 76 | C81: Stk | D81: Nein | F81: Eier | G81: aus der Region | H81: 1Stk | I81: Eier 1Stk | J81: Oeuf | K81: de la région | L81: 1pce | M81: Oeuf 1pce | N81: Uovo | O81: della regione | P81: 1pz | Q81: Uovo 1pz | R81: 1 | S81: 1 | T81: Stück | U81: (PCE) Stück | V81: Frische | W81: Molkereiprodukte & Eier | X81: Eier | AB81: ja | AC81: ja | AD81: ja | AE81: ja | AF81: - | AG81: - | AH81: ja | AI81: 0.05 | AJ81: -
A82: 77 | C82: Stk | D82: Nein | F82: Eier | G82: aus der Region | H82: 6Stk | I82: Eier 6Stk | J82: Oeufs | K82: de la région | L82: 6pces | M82: Oeufs 6pces | N82: Uova | O82: della regione | P82: 6pz | Q82: Uova 6pz | R82: 6 | S82: 1 | T82: Stück | U82: (PCE) Stück | V82: Frische | W82: Molkereiprodukte & Eier | X82: Eier | AB82: ja | AC82: ja | AD82: ja | AE82: ja | AF82: - | AG82: - | AH82: ja | AI82: 0.05 | AJ82: -
A83: 78 | C83: Stk | D83: Nein | F83: Fleischtheke | G83: aus der Region | H83: 1Stk | I83: Fleischtheke | J83: Boucherie | K83: de la région | L83: 1pce | M83: Boucherie | N83: Banco carni | O83: della regione | P83: 1pz | Q83: Banco carni | R83: 1 | S83: 1 | T83: Stück | U83: (PCE) Stück | V83: Frische | W83: SB - Fleisch | X83: SB - Fleisch andere | AB83: ja | AC83: ja | AD83: ja | AE83: ja | AF83: - | AG83: - | AH83: ja | AI83: 0 | AJ83: -
A84: 79 | C84: Stk | D84: Nein | F84: Fondue | G84: aus der Region | H84: 400g | I84: Fondue 400g | J84: Fondue | K84: de la région | L84: 400g | M84: Fondue 400g | N84: Fondue | O84: della regione | P84: 400g | Q84: Fondue 400g | R84: 0.4 | S84: 100 | T84: Gramm | U84: (PCE) Stück | V84: Frische | W84: Käse | X84: Käse | AB84: ja | AC84: ja | AD84: ja | AE84: ja | AF84: - | AG84: - | AH84: ja | AI84: 0.05 | AJ84: -
A85: 80 | C85: Stk | D85: Nein | F85: Fondue | G85: aus der Region | H85: 600g | I85: Fondue 600g | J85: Fondue | K85: de la région | L85: 600g | M85: Fondue 600g | N85: Fondue | O85: della regione | P85: 600g | Q85: Fondue 600g | R85: 0.6 | S85: 100 | T85: Gramm | U85: (PCE) Stück | V85: Frische | W85: Käse | X85: Käse | AB85: ja | AC85: ja | AD85: ja | AE85: ja | AF85: - | AG85: - | AH85: ja | AI85: 0.05 | AJ85: -
A86: 81 | C86: Stk | D86: Nein | F86: Fondue | G86: aus der Region | H86: 800g | I86: Fondue 800g | J86: Fondue | K86: de la région | L86: 800g | M86: Fondue 800g | N86: Fondue | O86: della regione | P86: 800g | Q86: Fondue 800g | R86: 0.8 | S86: 100 | T86: Gramm | U86: (PCE) Stück | V86: Frische | W86: Käse | X86: Käse | AB86: ja | AC86: ja | AD86: ja | AE86: ja | AF86: - | AG86: - | AH86: ja | AI86: 0.05 | AJ86: -
A87: 82 | B87: 837 | C87: kg | D87: Nein | F87: Frischkäse | G87: aus der Region | H87: 2Stk | I87: Frischkäse 2Stk | J87: Fromage frais | K87: de la région | L87: 2pces | M87: Fromage frais 2pces | N87: Formaggini freschi | O87: della regione | P87: 2pz | Q87: Formaggini freschi 2pz | R87: 2 | S87: 100 | T87: Gramm | U87: (PCE) Stück | V87: Frische | W87: Käse | X87: Käse | AB87: ja | AC87: ja | AD87: ja | AE87: ja | AF87: - | AG87: - | AH87: ja | AI87: 0.05 | AJ87: -
A88: 83 | B88: 838 | C88: kg | D88: Nein | F88: Gruyère | G88: aus der Region | H88: 1Stk | I88: Gruyère | J88: Gruyère | K88: de la région | L88: 1pce | M88: Gruyère | N88: Gruyère | O88: della regione | P88: 1pz | Q88: Gruyère | R88: 1 | S88: 100 | T88: Gramm | U88: (PCE) Stück | V88: Frische | W88: Käse | X88: Käse | AB88: ja | AC88: ja | AD88: ja | AE88: ja | AF88: - | AG88: - | AH88: ja | AI88: 0.05 | AJ88: -
A89: 84 | B89: 863 | C89: kg | D89: Nein | F89: Hauswurst | G89: aus der Region | H89: 2Stk | I89: Hauswurst 2Stk | J89: Saucisse | K89: de la région | L89: 2pces | M89: Saucisse 2pces | N89: Salsiccia | O89: della regione | P89: 2pz | Q89: Salsiccia 2pz | R89: 2 | S89: 100 | T89: Gramm | U89: (PCE) Stück | V89: Frische | W89: Fleisch- und Wurstwaren | X89: Wurstwaren | AB89: ja | AC89: ja | AD89: ja | AE89: ja | AF89: - | AG89: - | AH89: ja | AI89: 0 | AJ89: -
A90: 85 | C90: Stk | D90: Nein | F90: Jogurt | G90: aus der Region | H90: 130g | I90: Jogurt 130g | J90: Yogourt | K90: de la région | L90: 130g | M90: Yogourt 130g | N90: Yogourt | O90: della regione | P90: 130g | Q90: Yogourt 130g | R90: 0.13 | S90: 100 | T90: Gramm | U90: (PCE) Stück | V90: Frische | W90: Molkereiprodukte & Eier | X90: Milchprodukte | AB90: ja | AC90: ja | AD90: ja | AE90: ja | AF90: - | AG90: - | AH90: ja | AI90: 0 | AJ90: -
A91: 85 | C91: Stk | D91: Nein | F91: Jogurt | G91: aus der Region | H91: 150g | I91: Jogurt 150g | J91: Yogourt | K91: de la région | L91: 150g | M91: Yogourt 150g | N91: Yogourt | O91: della regione | P91: 150g | Q91: Yogourt 150g | R91: 0.15 | S91: 100 | T91: Gramm | U91: (PCE) Stück | V91: Frische | W91: Molkereiprodukte & Eier | X91: Milchprodukte | AB91: ja | AC91: ja | AD91: ja | AE91: ja | AF91: - | AG91: - | AH91: ja | AI91: 0 | AJ91: -
A92: 85 | C92: Stk | D92: Nein | F92: Jogurt | G92: aus der Region | H92: 180g | I92: Jogurt 180g | J92: Yogourt | K92: de la région | L92: 180g | M92: Yogourt 180g | N92: Yogourt | O92: della regione | P92: 180g | Q92: Yogourt 180g | R92: 0.18 | S92: 100 | T92: Gramm | U92: (PCE) Stück | V92: Frische | W92: Molkereiprodukte & Eier | X92: Milchprodukte | AB92: ja | AC92: ja | AD92: ja | AE92: ja | AF92: - | AG92: - | AH92: ja | AI92: 0 | AJ92: -
A93: 85 | C93: Stk | D93: Nein | F93: Jogurt | G93: aus der Region | H93: 200g | I93: Jogurt 200g | J93: Yogourt | K93: de la région | L93: 200g | M93: Yogourt 200g | N93: Yogourt | O93: della regione | P93: 200g | Q93: Yogourt 200g | R93: 0.2 | S93: 100 | T93: Gramm | U93: (PCE) Stück | V93: Frische | W93: Molkereiprodukte & Eier | X93: Milchprodukte | AB93: ja | AC93: ja | AD93: ja | AE93: ja | AF93: - | AG93: - | AH93: ja | AI93: 0 | AJ93: -
A94: 85 | C94: Stk | D94: Nein | F94: Jogurt | G94: aus der Region | H94: 250g | I94: Jogurt 250g | J94: Yogourt | K94: de la région | L94: 250g | M94: Yogourt 250g | N94: Yogourt | O94: della regione | P94: 250g | Q94: Yogourt 250g | R94: 0.25 | S94: 100 | T94: Gramm | U94: (PCE) Stück | V94: Frische | W94: Molkereiprodukte & Eier | X94: Milchprodukte | AB94: ja | AC94: ja | AD94: ja | AE94: ja | AF94: - | AG94: - | AH94: ja | AI94: 0 | AJ94: -
A95: 86 | C95: Stk | D95: Nein | F95: Jogurt | G95: aus der Region | H95: 400g | I95: Jogurt 400g | J95: Yogourt | K95: de la région | L95: 400g | M95: Yogourt 400g | N95: Yogourt | O95: della regione | P95: 400g | Q95: Yogourt 400g | R95: 0.4 | S95: 100 | T95: Gramm | U95: (PCE) Stück | V95: Frische | W95: Molkereiprodukte & Eier | X95: Milchprodukte | AB95: ja | AC95: ja | AD95: ja | AE95: ja | AF95: - | AG95: - | AH95: ja | AI95: 0 | AJ95: -
...

Sheet Leergutliste
A1: System Attributes | E1: Matching Attribute(s) | F1: Reference Data Attributes
A2: Action | B2: Type | C2: ID | D2: Name | E2: Artikelnummer | F2: Artikeltext//de-DE | G2: Artikeltext//fr-FR | H2: Artikeltext//it-IT | I2: Konditionsbetrag | J2: GTIN
B3: refxdepotartikel | C3: 24a46c0f-a771-41e2-93ed-cb0c3fab73bd | D3: 1031091 - Flasche Depot Fr. 0.30 1Stk | E3: 1031091 | F3: 1031091 - Flasche Depot Fr. 0.30 1Stk | G3: 1031091 - Bouteille Dépôt Fr. 0.30 1pce | H3: 1031091 - Bottiglia deposito CHF 0.30 1pz | I3: 0.3 | J3: 2009990300013 | L3: PROD
B4: refxdepotartikel | C4: cb0f8f2a-b148-4463-8ea6-f724fe195806 | D4: 1031091 - Flasche Depot Fr. 0.30 1Stk | E4: 1031091 | F4: 1031091 - Flasche Depot Fr. 0.30 1Stk | G4: 1031091 - Bouteille Dépôt Fr. 0.30 1pc | H4: 1031091 - Bottiglia 0.30 Deposito Fr. 1pz | I4: 0.3 | J4: 2009990300013 | L4: FS
B5: refxdepotartikel | C5: ab6d040c-8203-4e0b-b175-1994c4972eae | D5: 1031092 - Zylinder Soda Pfand Lieferung 1Stk CHF 10.00 | E5: 1031092 | F5: 1031092 - Zylinder Soda Pfand Lieferung 1Stk CHF 10.00 | G5: 1031092 - Cylindre Soda consigne 1pc CHF 10.00 | H5: 1031092 - Zylinder Soda cilindro consegna 1pz CHF 10.00 | I5: 10 | J5: 2009990400010 | L5: PROD
B6: refxdepotartikel | C6: fbc0f523-d3b6-47ba-81d4-f929ccdf1d54 | D6: 1031092 - Zylinder Soda Pfand Lieferung 1Stk | E6: 1031092 | F6: 1031092 - Zylinder Soda Pfand Lieferung 1Stk | G6: 1031092 - Cylindre Soda consigne 1pc | H6: 1031092 - Zylinder Soda cilindro consegna 1pz | I6: 10 | J6: 2009990400010 | L6: FS
B7: refxdepotartikel | C7: eff3978d-7324-4585-9715-cc4ffba09c37 | D7: 1031093 - Soda Lieferkarton 1Stk CHF 0.01 | E7: 1031093 | F7: 1031093 - Soda Lieferkarton 1Stk CHF 0.01 | G7: 1031093 - Carton de livraison Soda 1pc CHF 0.01 | H7: 1031093 - Soda Cartone consegna 1pz CHF 0.01 | I7: 0.01 | J7: 2009990410019 | L7: PROD
B8: refxdepotartikel | C8: bbd5d45f-1d71-4630-8c19-a80359c65efc | D8: 1031095 - Bierharass Depot 20er Fr. 5.00 1Stk | E8: 1031095 | F8: 1031095 - Bierharass Depot 20er Fr. 5.00 1Stk | G8: 1031095 - Caisse de bière dépôt 20 bt Fr. 5.00 1pc | H8: 1031095 - Cassa di birra da 20 deposi Fr. 5.00 1pz | I8: 5 | J8: 2009995530019 | L8: PROD
B9: refxdepotartikel | C9: efc07f6e-9d05-4740-8c39-a909a84956a5 | D9: 1031095 - Bierharass Depot 20er Fr. 5.00 1Stk | E9: 1031095 | F9: 1031095 - Bierharass Depot 20er Fr. 5.00 1Stk | G9: 1031095 - Caisse de bière Depot 20 Fr. 5.00 1pc | H9: 1031095 - Cassa di birra da 20 Depot Fr. 5.00 1pz | I9: 5 | J9: 2009995530019 | L9: FS
B10: refxdepotartikel | C10: 4ef93831-6d2b-4ecf-b453-90d4c225e3c6 | D10: 1035856 - Depot Harasse mit 20 Fl. CHF 11.00 | E10: 1035856 | F10: 1035856 - Depot Harasse mit 20 Fl. CHF 11.00 | G10: 1035856 - Depot Caisse avec 20 btlles CHF 11.00 | H10: 1035856 - Depot Cassa 20 bottiglie CHF 11.00 | I10: 11 | J10: 2009992010019 | L10: PROD
B11: refxdepotartikel | C11: aefcdd96-edf3-4763-8537-23b468197a31 | D11: 1035857 - Soda Zylinder Gebinde Rückgabe 1Stk CHF 10.00 | E11: 1035857 | F11: 1035857 - Soda Zylinder Gebinde Rückgabe 1Stk CHF 10.00 | G11: 1035857 - Soda Cylindre vide reprise 1 pce CHF 10.00 | H11: 1035857 - Soda Cilindri Contenitore resi 1pz CHF 10.00 | I11: 10 | J11: 2009995950015 | L11: PROD
B12: refxdepotartikel | C12: 39869ad3-bb9d-4f50-b44d-875afa9af2d4 | D12: 1035857 - Soda Zylinder Gebinde Rückgabe 1Stk | E12: 1035857 | F12: 1035857 - Soda Zylinder Gebinde Rückgabe 1Stk | G12: 1035857 - Soda Cylindre vide reprise 1 pce | H12: 1035857 - Soda Cilindri Contenitore resi 1pz | I12: 10 | J12: 2009995950015 | L12: FS
B13: refxdepotartikel | C13: 3cacbdbc-b134-402c-adba-636c19439a49 | D13: 1035858 - Gebinderücknahme DSD | E13: 1035858 | F13: 1035858 - Gebinderücknahme DSD | G13: 1035858 - restitution consigne DSD | H13: 1035858 - Restituzione contenitori, DSD | I13: 0.01 | J13: 2009995990011 | L13: FS
B14: refxdepotartikel | C14: f43d1af9-c103-4073-8a92-0c7379dd1446 | D14: 1102242 - Depot CHF 0.10 | E14: 1102242 | F14: 1102242 - Depot CHF 0.10 | G14: 1102242 - Depot CHF 0.10 | H14: 1102242 - Depot CHF 0.10 | I14: 0.1 | J14: 2011022420019 | L14: PROD
... B32: refxdepotartikel | C32: ers2vCq6ZaKBFib | D32: 1601772 - Depot Gasflasche Composite CHF 65.00 | E32: 1601772 | F32: 1601772 - Depot Gasflasche Composite CHF 65.00 | G32: 1102318 - Dépot Bouteille gaz Composite Vito 65.00 | H32: 1102318 - Bombole di gas deposito Vito CHF 65.00 | I32: 65 | J32: 2016017720013 | L32: FS

Sheet Model
A1: Sheet Name | B1: Data | D1: Attribute Name | E1: isCollection
A2: Entities | B2: Data | D2: GTIN-Typ Regioapp | E2: true

Sheet Reference Data
A1: axartikelslpmstruktur__it_IT | B1: atxwarengruppesap__de_DE | C1: axartikelslpmstruktur__de_DE | D1: axmhdvorhanden__it_IT | E1: atxwarengruppesap__fr_FR | F1: axtaxdummyfilter__it_IT | G1: atxalkoholhaltig__it_IT | H1: axartikelslpmstruktur__fr_FR | I1: axartikeltypsap__fr_FR | J1: axartikeltypsap__de_DE | K1: axtaxdummyfilter__de_DE | L1: atxalkoholhaltig__fr_FR | M1: atxalkoholhaltig__de_DE | N1: axmhdvorhanden__de_DE | O1: atxwarengruppesap__it_IT | P1: axartikeltypsap__it_IT | Q1: axmhdvorhanden__fr_FR | R1: axtaxdummyfilter__fr_FR | S1: ENTITY_NAME | T1: refxartikeltypsap | U1: refxbooleanalkoholhaltig | V1: refxboolen | W1: refxartikelartsap de-DE | X1: refxartikelartsap fr-FR | Y1: refxartikelartsap it-IT | Z1: refxsaisontypsap de-DE | AA1: refxsaisontypsap fr-FR | AB1: refxsaisontypsap it-IT | AC1: refxmengeneinheit de-DE | AD1: refxmengeneinheit fr-FR | AE1: refxmengeneinheit it-IT | AF1: refxvergleichspreiseinheit de-DE | AG1: refxvergleichspreiseinheit fr-FR | AH1: refxvergleichspreiseinheit it-IT | AI1: refxtaxclass de-DE | AJ1: refxtaxclass fr-FR | AK1: refxtaxclass it-IT | AL1: refxaltersbegrtyp de-DE | AM1: refxaltersbegrtyp fr-FR | AN1: refxaltersbegrtyp it-IT | AO1: refxshopinshop | AP1: refxgtintyperegioartikel | AQ1: refxsystemsap
A2: SLPM Struktur>>3 Getränke>>30 Getränke>>3025 Tafelgetränke>>30251010 Säfte gekühlt | B2: Warengruppe>>Getränke>>Tafelgetränke>>Säfte gekühlt | C2: SLPM Struktur>>3 Getränke>>30 Getränke>>3025 Tafelgetränke>>30251010 Säfte gekühlt | D2: Ja | E2: Groupe de produits>>Boissons>>Boissons de table>>Jus de fruits réfrigérés | F2: Dummy for Attribute Filtering | G2: Nein | H2: SLPM Struktur>>3 Getränke>>30 Getränke>>3025 Tafelgetränke>>30251010 Säfte gekühlt | I2: 00 - Einzelartikel | J2: 00 - Einzelartikel | K2: Dummy for Attribute Filtering | L2: Nein | M2: Nein | N2: Ja | O2: Gruppo di prodotti>>Bevande>>Bevande da tavola>>Succhi refrigerati | P2: 00 - Einzelartikel | Q2: Ja | R2: Dummy for Attribute Filtering | S2: exartikel | T2: 00 - Einzelartikel | U2: Ja | V2: Ja | W2: ZAUS - Display In/Out Artikel | X2: ZAUS - Display In/Out Artikel | Y2: ZAUS - Display In/Out Artikel | Z2: In/Out | AA2: In/Out | AB2: In/Out | AC2: Centiliter | AD2: Caisse | AE2: Borsa | AF2: 1 | AG2: [DELETE] | AH2: [DELETE] | AI2: 0 - Ohne MWST | AJ2: 0 - Sans TVA | AK2: 0 - Senza IVA | AL2: Alcopops | AM2: Alcopop | AN2: Alcolpop | AO2: Denner Partner | AP2: GTIN | AQ2: S4H
T3: 12 - Display | U3: Nein | V3: Nein | W3: ZEGS - Externe Gutscheine | X3: ZHAW - Handelsware ohne Charge | Y3: ZHAW - Handelsware ohne Charge | Z3: Permanent | AA3: Permanent | AB3: Permanent | AC3: Each | AD3: Centilitre | AE3: Cassa | AF3: 10 | AG3: [NULL] | AH3: [NULL] | AI3: 1 - Normalsatz | AJ3: 1 - Taux normal | AK3: 1 - Tariffa standard | AL3: Bier | AM3: Aucune | AN3: Birra | AO3: Postartikel | AP3: _EMPTY | AQ3: S4HP
T4: [DELETE] | U4: [DELETE] | V4: [DELETE] | W4: ZHAW - Handelsware ohne Charge | X4: ZWEI - Wein mit Charge | Y4: ZWEI - Wein mit Charge | Z4: Saison | AA4: Saison | AB4: Saison | AC4: Gramm | AD4: Chaque | AE4: Centilitro | AF4: 100 | AI4: 3 - Reduzierter Satz | AJ4: 3 - Taux réduit | AK4: 3 - Tariffa ridotta | AL4: Keine | AM4: Bière | AN4: Nessuna | AO4: [DELETE] | AP4: [DELETE] | AQ4: [DELETE]
T5: [NULL] | U5: [NULL] | V5: [NULL] | W5: ZHIB - Hilfs-/Betriebsstoffe aus VZ | X5: [DELETE] | Y5: [DELETE] | Z5: Saison/Promo | AA5: Saison/Promo | AB5: Saison/Promo | AC5: Kilogramm | AD5: Gramme | AE5: Chilogrammo | AF5: [DELETE] | AI5: [DELETE] | AJ5: [DELETE] | AK5: [DELETE] | AL5: Rauchwaren | AM5: Spiriteux | AN5: Superalcolici | AO5: [NULL] | AP5: [NULL] | AQ5: [NULL]
W6: ZIGS - Denner Gutschein | X6: [NULL] | Y6: [NULL] | Z6: [DELETE] | AA6: [DELETE] | AB6: [DELETE] | AC6: Kiste | AD6: Kilogramme | AE6: Confezione | AF6: [NULL] | AI6: [NULL] | AJ6: [NULL] | AK6: [NULL] | AL6: Spirituosen | AM6: Tabac | AN6: Tabacchi
W7: ZLEE - Leergut | Z7: [NULL] | AA7: [NULL] | AB7: [NULL] | AC7: Liter | AD7: Litre | AE7: Each | AL7: Wein | AM7: Vin | AN7: Vino
W8: ZLOS - Lose | AC8: Milliliter | AD8: Millilitre | AE8: Grammo | AL8: [DELETE] | AM8: [DELETE] | AN8: [DELETE]
W9: ZRWE - Wein in Tanks | AC9: Pack | AD9: Paquet | AE9: Litro | AL9: [NULL] | AM9: [NULL] | AN9: [NULL]
W10: ZVBR - Verbrauchsmat. aus Antalis | AC10: Rolle | AD10: Pièce | AE10: Millilitro
W11: ZVOL - Vollgut | AC11: Stück | AD11: Rouleau | AE11: Pezzo
W12: ZWEI - Wein mit Charge | AC12: Tüte | AD12: Sachet | AE12: Rotolo
W13: [DELETE] | AC13: [DELETE] | AD13: [DELETE] | AE13: [DELETE]
W14: [NULL] | AC14: [NULL] | AD14: [NULL] | AE14: [NULL]

Sheet dedea_axba2387
A1: ZIGS - Denner Gutschein | B1: ZWEI - Wein mit Charge | C1: [EMPTY] | D1: ZVOL - Vollgut | E1: ZAUS - Display In/Out Artikel | F1: ZLEE - Leergut | G1: ZEGS - Externe Gutscheine | H1: ZHAW - Handelsware ohne Charge | I1: ZRWE - Wein in Tanks | J1: ZHIB - Hilfs-/Betriebsstoffe aus VZ | K1: ZLOS - Lose
A2: (KGM) KG | B2: (PCE) Stück | C2: (KGM) KG | D2: (KGM) KG | E2: (KGM) KG | F2: (KGM) KG | G2: (KGM) KG | H2: (KGM) KG | I2: (LTR) Liter | J2: (KGM) KG | K2: (KGM) KG
