Workbook

Sheet Abkürzungen_WG
A1: Abkürzungen nach Artikelarten

Sheet Migrationsartikel
A1: Lf Nr. | B1: PLU-Nr. neu | C1: Stk / kg | D1: PAZ | E1: EAN | F1: Gestellbeschriftung 1 Max. 22 Zeichen (d) | G1: Gestellbeschriftung 2 Max. 22 Zeichen (d) | H1: Gestellbeschriftung 3 Max. 4-8 Zeichen (d) | I1: Kassenbontext Max. 28 Zeichen (d) | J1: Gestellbeschriftung 1 Max. 22 Zeichen (f) | K1: Gestellbeschriftung 2 Max. 22 Zeichen (f) | L1: Gestellbeschriftung 3 Max. 4-8 Zeichen (f) | M1: Kassenbontext Max. 28 Zeichen (f) | N1: Gestellbeschriftung 1 Max. 22 Zeichen (i) | O1: Gestellbeschriftung 2 Max. 22 Zeichen (i) | P1: Gestellbeschriftung 3 Max. 4-8 Zeichen (i) | Q1: Kassenbontext Max. 28 Zeichen (i) | R1: Nettoinhalt | S1: Grundpreismenge Feld 1 | T1: Grundpreismenge Feld 2 | U1: Basismengeneinheit Waage = Kg Verkauf = Stk = Stk Relevant für Berechnungen im MDM/SAP | V1: Warengruppe 1. Feld | W1: Warengruppe 2. Feld | X1: Warengruppe 3. Feld | Y1: Steuerklassifikation | Z1: Altersbegrenzung | AA1: Depot | AB1: Rabatt zugelassen | AC1: Rückgabe zugelassen | AD1: Preisänderung zugelassen | AE1: Etiketten-druck | AF1: Shop-in-Shop | AG1: Fremdartikel | AH1: Qualitätsanforderung geprüft | AI1: Verkaufskonditionen | AJ1: Lieferant
A2: 1 | C2: Stk | D2: Nein | F2: Baguette | G2: aus der Region | H2: 250g | I2: Baguette 250g | J2: Baguette | K2: de la région | L2: 250g | M2: Baguette 250g | N2: Baguette | O2: della regione | P2: 250g | Q2: Baguette 250g | R2: 0.25 | S2: 100 | T2: Gramm | U2: (PCE) Stück | V2: Backwaren & Convenience | W2: Brot und Backwaren | X2: Backwaren andere | AB2: ja | AC2: ja | AD2: ja | AE2: ja | AF2: - | AG2: - | AH2: ja | AI2: 0.05 | AJ2: -
A3: 2 | C3: Stk | D3: Nein | F3: Baslerbrot | G3: aus der Region | H3: 250g | I3: Baslerbrot 250g | J3: Pain bâlois | K3: de la région | L3: 250g | M3: Pain bâlois 250g | N3: Pane di Basilea | O3: della regione | P3: 250g | Q3: Pane di Basilea 250g | R3: 0.25 | S3: 100 | T3: Gramm | U3: (PCE) Stück | V3: Backwaren & Convenience | W3: Brot und Backwaren | X3: Backwaren andere | AB3: ja | AC3: ja | AD3: ja | AE3: ja | AF3: - | AG3: - | AH3: ja | AI3: 0.05 | AJ3: -
A4: 3 | C4: Stk | D4: Nein | F4: Baslerbrot | G4: aus der Region | H4: 500g | I4: Baslerbrot 500g | J4: Pain bâlois | K4: de la région | L4: 500g | M4: Pain bâlois 500g | N4: Pane di Basilea | O4: della regione | P4: 500g | Q4: Pane di Basilea 500g | R4: 0.5 | S4: 100 | T4: Gramm | U4: (PCE) Stück | V4: Backwaren & Convenience | W4: Brot und Backwaren | X4: Backwaren andere | AB4: ja | AC4: ja | AD4: ja | AE4: ja | AF4: - | AG4: - | AH4: ja | AI4: 0.05 | AJ4: -
A5: 4 | C5: Stk | D5: Nein | F5: Berliner | G5: aus der Region | H5: 1Stk | I5: Berliner | J5: Boule de Berlin | K5: de la région | L5: 1pce | M5: Boule de Berlin | N5: Berliner | O5: della regione | P5: 1pz | Q5: Berliner | R5: 1 | S5: 1 | T5: Stück | U5: (PCE) Stück | V5: Backwaren & Convenience | W5: Brot und Backwaren | X5: Backwaren andere | AB5: ja | AC5: ja | AD5: ja | AE5: ja | AF5: - | AG5: - | AH5: ja | AI5: 0.05 | AJ5: -
A6: 5 | C6: Stk | D6: Nein | F6: Birewegge | G6: aus der Region | H6: 1Stk | I6: Birewegge | J6: Birewegge | K6: de la région | L6: 1pce | M6: Birewegge | N6: Birewegge | O6: della regione | P6: 1pz | Q6: Birewegge | R6: 1 | S6: 1 | T6: Stück | U6: (PCE) Stück | V6: Backwaren & Convenience | W6: Brot und Backwaren | X6: Backwaren andere | AB6: ja | AC6: ja | AD6: ja | AE6: ja | AF6: - | AG6: - | AH6: ja | AI6: 0.05 | AJ6: -
A7: 6 | C7: Stk | D7: Nein | F7: Bricelets | G7: aus der Region | H7: 1Stk | I7: Bricelets | J7: Bricelets | K7: de la région | L7: 1pce | M7: Bricelets | N7: Bricelets | O7: della regione | P7: 1pz | Q7: Bricelets | R7: 1 | S7: 1 | T7: Stück | U7: (PCE) Stück | V7: Backwaren & Convenience | W7: Brot und Backwaren | X7: Backwaren andere | AB7: ja | AC7: ja | AD7: ja | AE7: ja | AF7: - | AG7: - | AH7: ja | AI7: 0.05 | AJ7: -
A8: 7 | C8: Stk | D8: Nein | F8: Brioche mit Füllung | G8: aus der Region | H8: 1Stk | I8: Brioche mit Füllung | J8: Brioche fourée | K8: de la région | L8: 1pce | M8: Brioche fourée | N8: Brioche ripiena | O8: della regione | P8: 1pz | Q8: Brioche ripiena | R8: 1 | S8: 1 | T8: Stück | U8: (PCE) Stück | V8: Backwaren & Convenience | W8: Brot und Backwaren | X8: Backwaren andere | AB8: ja | AC8: ja | AD8: ja | AE8: ja | AF8: - | AG8: - | AH8: ja | AI8: 0 | AJ8: -
A9: 8 | C9: Stk | D9: Nein | F9: Brot vom Beck | G9: aus der Region | H9: 1Stk | I9: Brot vom Beck | J9: Pain du boulanger | K9: de la région | L9: 1pce | M9: Pain du boulanger | N9: Pane del panettiere | O9: della regione | P9: 1pz | Q9: Pane del panettiere | R9: 1 | S9: 1 | T9: Stück | U9: (PCE) Stück | V9: Backwaren & Convenience | W9: Brot und Backwaren | X9: Backwaren andere | AB9: ja | AC9: ja | AD9: ja | AE9: ja | AF9: - | AG9: - | AH9: ja | AI9: 0 | AJ9: -
A10: 9 | C10: Stk | D10: Nein | F10: Brottheke | G10: aus der Region | H10: 1Stk | I10: Brottheke | J10: Comptoir à pain | K10: de la région | L10: 1pce | M10: Comptoir à pain | N10: Banco pane | O10: della regione | P10: 1pz | Q10: Banco pane | R10: 1 | S10: 1 | T10: Stück | U10: (PCE) Stück | V10: Backwaren & Convenience | W10: Brot und Backwaren | X10: Backwaren andere | AB10: ja | AC10: ja | AD10: ja | AE10: ja | AF10: - | AG10: - | AH10: ja | AI10: 0 | AJ10: -
A11: 10 | C11: Stk | D11: Nein | F11: Bürli | G11: aus der Region | H11: 1Stk | I11: Bürli | J11: Bürli | K11: de la région | L11: 1pce | M11: Bürli | N11: Bürli | O11: della regione | P11: 1pz | Q11: Bürli | R11: 1 | S11: 1 | T11: Stück | U11: (PCE) Stück | V11: Backwaren & Convenience | W11: Brot und Backwaren | X11: Backwaren andere | AB11: ja | AC11: ja | AD11: ja | AE11: ja | AF11: - | AG11: - | AH11: ja | AI11: 0.05 | AJ11: -
A12: 11 | C12: Stk | D12: Nein | F12: Buttergipfel | G12: aus der Region | H12: 1Stk | I12: Buttergipfel | J12: Croissant au beurre | K12: de la région | L12: 1pce | M12: Croissant au beurre | N12: Cornetto al burro | O12: della regione | P12: 1pz | Q12: Cornetto al burro | R12: 1 | S12: 1 | T12: Stück | U12: (PCE) Stück | V12: Backwaren & Convenience | W12: Brot und Backwaren | X12: Backwaren andere | AB12: ja | AC12: ja | AD12: ja | AE12: ja | AF12: - | AG12: - | AH12: ja | AI12: 0.05 | AJ12: -
A13: 12 | C13: Stk | D13: Nein | F13: Butterzopf | G13: aus der Region | H13: 300g | I13: Butterzopf 300g | J13: Tresse | K13: de la région | L13: 300g | M13: Tresse 300g | N13: Treccia | O13: della regione | P13: 300g | Q13: Treccia 300g | R13: 0.3 | S13: 100 | T13: Gramm | U13: (PCE) Stück | V13: Backwaren & Convenience | W13: Brot und Backwaren | X13: Backwaren andere | AB13: ja | AC13: ja | AD13: ja | AE13: ja | AF13: - | AG13: - | AH13: ja | AI13: 0.05 | AJ13: -
... A78: 100 | C78: Stk | D78: Nein | F78: Wachteleier | G78: aus der Region | H78: 1Stk | I78: Wachteleier 1Stk | J78: Oeufs de caille | K78: de la région | L78: 1pce | M78: Oeufs de caille | N78: Uova di quaglia | O78: della regione | P78: 1pz | Q78: Uova di quaglia | R78: 1 | S78: 1 | T78: Stück | U78: (PCE) Stück | V78: Frische | W78: Molkereiprodukte & Eier | X78: Eier | AB78: ja | AC78: ja | AD78: ja | AE78: ja | AF78: - | AG78: - | AH78: ja | AI78: 0.05 | AJ78: -
A79: 73 | B79: 829 | C79: kg | D79: Nein | F79: Eglifilet | G79: aus der Region | H79: 1Stk | I79: Eglifilet | J79: Filet de perche | K79: de la région | L79: 1pce | M79: Filet de perche | N79: Filetto di persico | O79: della regione | P79: 1pz | Q79: Filetto di persico | R79: 1 | S79: 100 | T79: Gramm | U79: (PCE) Stück | V79: Frische | W79: SB - Fleisch | X79: Fisch | AB79: ja | AC79: ja | AD79: ja | AE79: ja | AF79: - | AG79: - | AH79: ja | AI79: 0.05 | AJ79: -
A80: 98 | B80: 830 | C80: kg | D80: Nein | F80: Rindstartar | G80: aus der Region | H80: 1Stk | I80: Rindstartar | J80: Tartare de boeuf | K80: de la région | L80: 1pce | M80: Tartare de boeuf | N80: Tartare di manzo | O80: della regione | P80: 1pz | Q80: Tartare di manzo | R80: 1 | S80: 100 | T80: Gramm | U80: (PCE) Stück | V80: Frische | W80: SB - Fleisch | X80: Fleisch | AB80: ja | AC80: ja | AD80: ja | AE80: ja | AF80: - | AG80: - | AH80: ja | AI80: 0.05 | AJ80: -
A81: 99 | C81: Stk | D81: Nein | F81: Theke Wurstwaren | G81: aus der Region | H81: 1Stk | I81: Theke Wurstwaren | J81: Comptoir charcuterie | K81: de la région | L81: 1pce | M81: Comptoir charcuterie | N81: Banco salumeria | O81: della regione | P81: 1pz | Q81: Banco salumeria | R81: 1 | S81: 1 | T81: Stück | U81: (PCE) Stück | V81: Frische | W81: Fleisch- und Wurstwaren | X81: Fleisch- und Wurstwaren andere | AB81: ja | AC81: ja | AD81: ja | AE81: ja | AF81: - | AG81: - | AH81: ja | AI81: 0 | AJ81: -
A82: 101 | C82: Stk | D82: Nein | F82: Wurstwaren | G82: aus der Region | H82: 1Stk | I82: Wurstwaren | J82: Charcuterie | K82: de la région | L82: 1pce | M82: Charcuterie | N82: Salumi | O82: della regione | P82: 1pz | Q82: Salumi | R82: 1 | S82: 1 | T82: Stück | U82: (PCE) Stück | V82: Frische | W82: Fleisch- und Wurstwaren | X82: Fleisch- und Wurstwaren andere | AB82: ja | AC82: ja | AD82: ja | AE82: ja | AF82: - | AG82: - | AH82: ja | AI82: 0 | AJ82: -
A83: 66 | C83: Stk | D83: Nein | F83: Büscion | G83: aus der Region | H83: 2Stk | I83: Büscion 2Stk | J83: Büscion 2pces | K83: de la région | L83: 2pces | M83: Büscion | N83: Büscion | O83: della regione | P83: 2pz | Q83: Büscion 2pz | R83: 2 | S83: 1 | T83: Stück | U83: (PCE) Stück | V83: Frische | W83: Käse | X83: Käse | AB83: ja | AC83: ja | AD83: ja | AE83: ja | AF83: - | AG83: - | AH83: ja | AI83: 0.05 | AJ83: -
A84: 79 | C84: Stk | D84: Nein | F84: Fondue | G84: aus der Region | H84: 400g | I84: Fondue 400g | J84: Fondue | K84: de la région | L84: 400g | M84: Fondue 400g | N84: Fondue | O84: della regione | P84: 400g | Q84: Fondue 400g | R84: 0.4 | S84: 100 | T84: Gramm | U84: (PCE) Stück | V84: Frische | W84: Käse | X84: Käse | AB84: ja | AC84: ja | AD84: ja | AE84: ja | AF84: - | AG84: - | AH84: ja | AI84: 0.05 | AJ84: -
A85: 80 | C85: Stk | D85: Nein | F85: Fondue | G85: aus der Region | H85: 600g | I85: Fondue 600g | J85: Fondue | K85: de la région | L85: 600g | M85: Fondue 600g | N85: Fondue | O85: della regione | P85: 600g | Q85: Fondue 600g | R85: 0.6 | S85: 100 | T85: Gramm | U85: (PCE) Stück | V85: Frische | W85: Käse | X85: Käse | AB85: ja | AC85: ja | AD85: ja | AE85: ja | AF85: - | AG85: - | AH85: ja | AI85: 0.05 | AJ85: -
A86: 81 | C86: Stk | D86: Nein | F86: Fondue | G86: aus der Region | H86: 800g | I86: Fondue 800g | J86: Fondue | K86: de la région | L86: 800g | M86: Fondue 800g | N86: Fondue | O86: della regione | P86: 800g | Q86: Fondue 800g | R86: 0.8 | S86: 100 | T86: Gramm | U86: (PCE) Stück | V86: Frische | W86: Käse | X86: Käse | AB86: ja | AC86: ja | AD86: ja | AE86: ja | AF86: - | AG86: - | AH86: ja | AI86: 0.05 | AJ86: -
A87: 82 | B87: 837 | C87: kg | D87: Nein | F87: Frischkäse | G87: aus der Region | H87: 2Stk | I87: Frischkäse 2Stk | J87: Fromage frais | K87: de la région | L87: 2pces | M87: Fromage frais 2pces | N87: Formaggini freschi | O87: della regione | P87: 2pz | Q87: Formaggini freschi 2pz | R87: 2 | S87: 100 | T87: Gramm | U87: (PCE) Stück | V87: Frische | W87: Käse | X87: Käse | AB87: ja | AC87: ja | AD87: ja | AE87: ja | AF87: - | AG87: - | AH87: ja | AI87: 0.05 | AJ87: -
A88: 83 | B88: 838 | C88: kg | D88: Nein | F88: Gruyère | G88: aus der Region | H88: 1Stk | I88: Gruyère | J88: Gruyère | K88: de la région | L88: 1pce | M88: Gruyère | N88: Gruyère | O88: della regione | P88: 1pz | Q88: Gruyère | R88: 1 | S88: 100 | T88: Gramm | U88: (PCE) Stück | V88: Frische | W88: Käse | X88: Käse | AB88: ja | AC88: ja | AD88: ja | AE88: ja | AF88: - | AG88: - | AH88: ja | AI88: 0.05 | AJ88: -
A89: 87 | C89: Stk | D89: Nein | F89: Käse Spezialitäten | G89: aus der Region | H89: 1Stk | I89: Käse Spezialitäten | J89: Spécialités de fromage | K89: de la région | L89: 1pce | M89: Spécialités de fromage | N89: Formaggi | O89: della regione | P89: 1pz | Q89: Formaggi | R89: 1 | S89: 1 | T89: Stück | U89: (PCE) Stück | V89: Frische | W89: Käse | X89: Käse | AB89: ja | AC89: ja | AD89: ja | AE89: ja | AF89: - | AG89: - | AH89: ja | AI89: 0 | AJ89: -
A90: 88 | C90: Stk | D90: Nein | F90: Käsetheke | G90: aus der Region | H90: 1Stk | I90: Käsetheke | J90: Fromagerie | K90: de la région | L90: 1pce | M90: Fromagerie | N90: Banco formaggi | O90: della regione | P90: 1pz | Q90: Banco formaggi | R90: 1 | S90: 1 | T90: Stück | U90: (PCE) Stück | V90: Frische | W90: Käse | X90: Käse | AB90: ja | AC90: ja | AD90: ja | AE90: ja | AF90: - | AG90: - | AH90: ja | AI90: 0 | AJ90: -
A91: 93 | B91: 841 | C91: kg | D91: Nein | F91: Mutschli | G91: aus der Region | H91: 1Stk | I91: Mutschli | J91: Tomme | K91: de la région | L91: 1pce | M91: Tomme | N91: Tomino | O91: della regione | P91: 1pz | Q91: Tomino | R91: 1 | S91: 100 | T91: Gramm | U91: (PCE) Stück | V91: Frische | W91: Käse | X91: Käse | AB91: ja | AC91: ja | AD91: ja | AE91: ja | AF91: - | AG91: - | AH91: ja | AI91: 0.05 | AJ91: -
A92: 96 | B92: 842 | C92: kg | D92: Nein | F92: Raclette | G92: aus der Region | H92: 1Stk | I92: Raclette | J92: Raclette | K92: de la région | L92: 1pce | M92: Raclette | N92: Raclette | O92: della regione | P92: 1pz | Q92: Raclette | R92: 1 | S92: 100 | T92: Gramm | U92: (PCE) Stück | V92: Frische | W92: Käse | X92: Käse | AB92: ja | AC92: ja | AD92: ja | AE92: ja | AF92: - | AG92: - | AH92: ja | AI92: 0.05 | AJ92: -
A93: 102 | C93: Stk | D93: Nein | F93: Zincarlin | G93: aus der Region | H93: 1Stk | I93: Zincarlin | J93: Zincarlin | K93: de la région | L93: 1pce | M93: Zincarlin | N93: Zincarlin | O93: della regione | P93: 1pz | Q93: Zincarlin | R93: 1 | S93: 1 | T93: Stück | U93: (PCE) Stück | V93: Frische | W93: Käse | X93: Käse | AB93: ja | AC93: ja | AD93: ja | AE93: ja | AF93: - | AG93: - | AH93: ja | AI93: 0.05 | AJ93: -
A94: 67 | C94: Stk | D94: Nein | F94: Butter | G94: aus der Region | H94: 100g | I94: Butter 100g | J94: Beurre | K94: de la région | L94: 100g | M94: Beurre 100g | N94: Burro | O94: della regione | P94: 100g | Q94: Burro 100g | R94: 0.1 | S94: 100 | T94: Gramm | U94: (PCE) Stück | V94: Frische | W94: Molkereiprodukte & Eier | X94: Milchprodukte | AB94: ja | AC94: ja | AD94: ja | AE94: ja | AF94: - | AG94: - | AH94: ja | AI94: 0.05 | AJ94: -
A95: 68 | C95: Stk | D95: Nein | F95: Butter | G95: aus der Region | H95: 200g | I95: Butter 200g | J95: Beurre | K95: de la région | L95: 200g | M95: Beurre 200g | N95: Burro | O95: della regione | P95: 200g | Q95: Burro 200g | R95: 0.2 | S95: 100 | T95: Gramm | U95: (PCE) Stück | V95: Frische | W95: Molkereiprodukte & Eier | X95: Milchprodukte | AB95: ja | AC95: ja | AD95: ja | AE95: ja | AF95: - | AG95: - | AH95: ja | AI95: 0.05 | AJ95: -
A96: 69 | C96: Stk | D96: Nein | F96: Butter | G96: aus der Region | H96: 250g | I96: Butter 250g | J96: Beurre | K96: de la région | L96: 250g | M96: Beurre 250g | N96: Burro | O96: della regione | P96: 250g | Q96: Burro 250g | R96: 0.25 | S96: 100 | T96: Gramm | U96: (PCE) Stück | V96: Frische | W96: Molkereiprodukte & Eier | X96: Milchprodukte | AB96: ja | AC96: ja | AD96: ja | AE96: ja | AF96: - | AG96: - | AH96: ja | AI96: 0.05 | AJ96: -
A97: 71 | C97: Stk | D97: Nein | F97: Doppel-Rahm | G97: aus der Region | H97: 200ml | I97: Doppel-Rahm 200ml | J97: Double crème | K97: de la région | L97: 200ml | M97: Double crème 200ml | N97: Panna doppia | O97: della regione | P97: 200ml | Q97: Panna 200ml | R97: 0.2 | S97: 100 | T97: Milliliter | U97: (PCE) Stück | V97: Frische | W97: Molkereiprodukte & Eier | X97: Milchprodukte | AB97: ja | AC97: ja | AD97: ja | AE97: ja | AF97: - | AG97: - | AH97: ja | AI97: 0.05 | AJ97: -
A98: 72 | C98: Stk | D98: Nein | F98: Doppel-Rahm | G98: aus der Region | H98: 250ml | I98: Doppel-Rahm 250ml | J98: Double crème | K98: de la région | L98: 250ml | M98: Double crème 250ml | N98: Panna doppia | O98: della regione | P98: 250ml | Q98: Panna 250ml | R98: 0.25 | S98: 100 | T98: Milliliter | U98: (PCE) Stück | V98: Frische | W98: Molkereiprodukte & Eier | X98: Milchprodukte | AB98: ja | AC98: ja | AD98: ja | AE98: ja | AF98: - | AG98: - | AH98: ja | AI98: 0.05 | AJ98: -
A99: 85 | C99: Stk | D99: Nein | F99: Jogurt | G99: aus der Region | H99: 130g | I99: Jogurt 130g | J99: Yogourt | K99: de la région | L99: 130g | M99: Yogourt 130g | N99: Yogourt | O99: della regione | P99: 130g | Q99: Yogourt 130g | R99: 0.13 | S99: 100 | T99: Gramm | U99: (PCE) Stück | V99: Frische | W99: Molkereiprodukte & Eier | X99: Milchprodukte | AB99: ja | AC99: ja | AD99: ja | AE99: ja | AF99: - | AG99: - | AH99: ja | AI99: 0 | AJ99: -
A100: 85 | C100: Stk | D100: Nein | F100: Jogurt | G100: aus der Region | H100: 150g | I100: Jogurt 150g | J100: Yogourt | K100: de la région | L100: 150g | M100: Yogourt 150g | N100: Yogourt | O100: della regione | P100: 150g | Q100: Yogourt 150g | R100: 0.15 | S100: 100 | T100: Gramm | U100: (PCE) Stück | V100: Frische | W100: Molkereiprodukte & Eier | X100: Milchprodukte | AB100: ja | AC100: ja | AD100: ja | AE100: ja | AF100: - | AG100: - | AH100: ja | AI100: 0 | AJ100: -
A101: 85 | C101: Stk | D101: Nein | F101: Jogurt | G101: aus der Region | H101: 180g | I101: Jogurt 180g | J101: Yogourt | K101: de la région | L101: 180g | M101: Yogourt 180g | N101: Yogourt | O101: della regione | P101: 180g | Q101: Yogourt 180g | R101: 0.18 | S101: 100 | T101: Gramm | U101: (PCE) Stück | V101: Frische | W101: Molkereiprodukte & Eier | X101: Milchprodukte | AB101: ja | AC101: ja | AD101: ja | AE101: ja | AF101: - | AG101: - | AH101: ja | AI101: 0 | AJ101: -
A102: 85 | C102: Stk | D102: Nein | F102: Jogurt | G102: aus der Region | H102: 200g | I102: Jogurt 200g | J102: Yogourt | K102: de la région | L102: 200g | M102: Yogourt 200g | N102: Yogourt | O102: della regione | P102: 200g | Q102: Yogourt 200g | R102: 0.2 | S102: 100 | T102: Gramm | U102: (PCE) Stück | V102: Frische | W102: Molkereiprodukte & Eier | X102: Milchprodukte | AB102: ja | AC102: ja | AD102: ja | AE102: ja | AF102: - | AG102: - | AH102: ja | AI102: 0 | AJ102: -
A103: 85 | C103: Stk | D103: Nein | F103: Jogurt | G103: aus der Region | H103: 250g | I103: Jogurt 250g | J103: Yogourt | K103: de la région | L103: 250g | M103: Yogourt 250g | N103: Yogourt | O103: della regione | P103: 250g | Q103: Yogourt 250g | R103: 0.25 | S103: 100 | T103: Gramm | U103: (PCE) Stück | V103: Frische | W103: Molkereiprodukte & Eier | X103: Milchprodukte | AB103: ja | AC103: ja | AD103: ja | AE103: ja | AF103: - | AG103: - | AH103: ja | AI103: 0 | AJ103: -
A104: 86 | C104: Stk | D104: Nein | F104: Jogurt | G104: aus der Region | H104: 400g | I104: Jogurt 400g | J104: Yogourt | K104: de la région | L104: 400g | M104: Yogourt 400g | N104: Yogourt | O104: della regione | P104: 400g | Q104: Yogourt 400g | R104: 0.4 | S104: 100 | T104: Gramm | U104: (PCE) Stück | V104: Frische | W104: Molkereiprodukte & Eier | X104: Milchprodukte | AB104: ja | AC104: ja | AD104: ja | AE104: ja | AF104: - | AG104: - | AH104: ja | AI104: 0 | AJ104: -
...

Sheet Stückartikel_Nat._Bearbeitung
A1: Artikelnr. | B1: PLU | C1: Typ | D1: SAP Nr | E1: Vorschlag Einkauf Text 1 | F1: Vorschlag Einkauf Text 2 | G1: Menge | H1: EAN Code kg 21er | I1: EAN Code 29er | J1: Coli EAN | K1: Vorschlag für Bezeichnung in Deutsch (Kasentext) | L1: Verkaufsmenge gemäss Angaben Lieferant | M1: Kassentext (D) | N1: Gestellbeschriftung 1 (D) | O1: Gestellbeschriftung 2 (D) | P1: Kassentext (D) | Q1: Gestellbeschriftung 1 (F) | R1: Gestellbeschriftung 2 (F) | S1: Kassentext (I) | T1: Gestellbeschriftung 1 (I) | U1: Gestellbeschriftung 2 (I) | V1: Lieferant | W1: Grund- einheit | X1: WG | Y1: MWSt | Z1: VP | AA1: Altersbegrenz. | AB1: Gewichtsartikel | AC1: Barcode ohne Prüfziffer | AD1: Rabatt zugelassen | AE1: Gratis- artikel | AF1: Rückgabe zugelassen | AG1: Preisänder. Kasse erlaub. | AH1: Shop-in-Shop Artikel | AI1: Depot | AJ1: Regio- oder Fremdartikel | AK1: Etiketten- druck | AL1: Artikel gem. LMV
A2: 801722 | B2: 1006097 | C2: F | D2: 1006097 | E2: Bio Zitronen Stück 1 Stück
A3: 801003 | C3: F | D3: 1006284 | E3: Melonen Galia 1 Stück
A4: 800084 | C4: F | D4: 1006007 | E4: Avocado 1 Stück
A5: 800896 | C5: F | D5: 1006180 | E5: Limetten Stück 1 Stück
A6: 800988 | C6: F | D6: 1006035 | E6: Melonen Cantaloupe 1 Stück
A7: 800198 | C7: F | D7: 1006173 | E7: Granatapfel 1 Stück
A8: 800143 | C8: F | D8: 1006213 | E8: Grapefruit 1 Stück
A9: 800885 | C9: F | D9: 1006045 | E9: Kiwis Offenverkauf 1 Stück
A10: 801967 | C10: F | D10: 1006119 | E10: Honigmelone gelb 1 Stück
A11: 800848 | C11: F | D11: 1006086 | E11: Ananas 1 Stück
A12: 800586 | C12: F | D12: 1006059 | E12: Melone Piel de Sapo 1 Stück
A13: 801880 | C13: F | D13: 1100346 | E13: Kiwi Gold Stk
A14: 802608 | C14: F | D14: 1100307 | E14: Avocado Bio Stk
... A23: 800167 | C23: G | D23: 1006232 | E23: Knoblauch 1 Stück

Sheet System-Informationen
A1: Navision (Ist)
A27: MDM (Neu) für nationale Daten
A29: Es stehen folgende Felder zur Verfügung
A30: Gestellbeschriftung 1 | B30: Maximal 22 Zeichen, wenn Markenartikel, so steht dieser Name zuerst
A31: Gestellbeschriftung 2 | B31: Maximal 22 Zeichen, für die restliche Bezeichnung
A32: Gestellbeschriftung 3 | B32: 4-8 Zeichen (für Menge)
A33: Text für Belege | B33: = Text für Kassenzettel, maximal 28 Zeichen. Setzt sicht aus Gestellbeschriftung 1+2+3 zusammen und wird automatisch gekürzt (Anpassungen möglich)
A62: MDM (Neu) Regio App

Sheet Einheiten Nav
A1: Artikelnr. | B1: Code | C1: Einheit aktiv (intern) | D1: Menge pro Basiseinheit | E1: Einheit aktiv (POS) | F1: Gestelletikette drucken | G1: Etiketten-Druck am | H1: Beschreibung | I1: Masterbarcode | J1: Anzahl Barcodes | K1: Einheit Typ | L1: CU Zuweisung | M1: CU BME | N1: CU/TU Verhältnis | O1: Belieferung durch MVN | P1: ProduktNummerWaage | Q1: Netto Gewicht | R1: Brutto Gewicht | S1: OP verfügbar | T1: Colis je Lage OP | U1: Lagen je OP | V1: Colis je OP | W1: Basiseinheiten je OP | X1: HP verfügbar | Y1: Colis per Lage HP | Z1: Lagen je HP | AA1: Colis je HP | AB1: Basiseinheiten je HP | AC1: Länge (mm) | AD1: Breite (mm) | AE1: Höhe (mm) | AF1: Volumen (m3) | AG1: Pfandartikel | AH1: Umgebinde Colis | AI1: Pfandartikel und Umgebinde Colis
A2: 661105 | B2: STK | C2: Ja | D2: 1 | E2: Ja | F2: Ja | H2: Papaya Offenverkauf kg | I2: 2006611050005 | J2: 3 | O2: Nein | P2: 157 | Q2: 1 | R2: 1.05 | AC2: 20 | AD2: 10 | AE2: 10
A3: 661334 | B3: STK | C3: Ja | D3: 1 | E3: Ja | F3: Ja | H3: Maniok kg | I3: 2006613340005 | J3: 3 | O3: Nein | P3: 251 | Q3: 1 | R3: 1.05 | AC3: 100 | AD3: 100 | AE3: 100 | AF3: 0.001
A4: 661455 | B4: STK | C4: Ja | D4: 1 | E4: Ja | F4: Ja | H4: Bio Mini Wassermelone kg | I4: 2006614550007 | J4: 3 | O4: Nein | P4: 158 | Q4: 2 | R4: 2.05 | AC4: 100 | AD4: 100 | AE4: 100 | AF4: 0.001
A5: 790004 | B5: STK | C5: Ja | D5: 1 | E5: Ja | F5: Nein | H5: Test Waage 31. Roger | I5: 2007900040011 | J5: 1 | O5: Nein | P5: 141 | Q5: 0 | R5: 1
A6: 790005 | B6: STK | C6: Ja | D6: 1 | E6: Nein | F6: Nein | H6: Test Waage 11.6. Roger | J6: 1 | O6: Nein | P6: 142 | Q6: 0 | R6: 1
A7: 800269 | B7: STK | C7: Ja | D7: 1 | E7: Ja | F7: Ja | H7: Wassermelonen kg | I7: 2008002690012 | J7: 4 | K7: CU | O7: Nein | P7: 152 | Q7: 1 | R7: 1 | AC7: 100 | AD7: 100 | AE7: 100 | AF7: 0.001
A8: 800471 | B8: STK | C8: Ja | D8: 1 | E8: Ja | F8: Ja | H8: Zwiebeln | I8: 2008004710008 | J8: 2 | O8: Nein | P8: 244 | Q8: 0 | R8: 1 | AC8: 600 | AD8: 400 | AE8: 160 | AF8: 0.038
A9: 800693 | B9: STK | C9: Ja | D9: 1 | E9: Ja | F9: Ja | H9: Pflaumen Offenverkauf kg | I9: 2008006930008 | J9: 3 | K9: CU | O9: Nein | P9: 120 | Q9: 1 | R9: 1 | AC9: 600 | AD9: 400 | AE9: 120 | AF9: 0.029
A10: 800705 | B10: STK | C10: Ja | D10: 1 | E10: Ja | F10: Ja | H10: Tomaten Spezial Offenverk kg | I10: 2008007050002 | J10: 3 | K10: CU | O10: Nein | P10: 207 | Q10: 1 | R10: 1 | AC10: 300 | AD10: 400 | AE10: 120 | AF10: 0.014
A11: 800708 | B11: STK | C11: Ja | D11: 1 | E11: Ja | F11: Ja | H11: Zwetschgen Offenverkauf kg | I11: 2008007080009 | J11: 3 | K11: CU | O11: Nein | P11: 111 | Q11: 1 | R11: 1 | AC11: 100 | AD11: 100 | AE11: 100 | AF11: 0.001
A12: 800709 | B12: STK | C12: Ja | D12: 1 | E12: Ja | F12: Ja | H12: Süss-Kartoffeln Offenver kg | I12: 2008007090008 | J12: 3 | K12: CU | O12: Nein | P12: 208 | Q12: 1 | R12: 1 | AC12: 100 | AD12: 100 | AE12: 100 | AF12: 0.001
A13: 800717 | B13: STK | C13: Ja | D13: 1 | E13: Ja | F13: Ja | H13: Pfirsiche Offenverkauf kg | I13: 2008007170007 | J13: 3 | K13: CU | O13: Nein | P13: 109 | Q13: 1 | R13: 1 | AC13: 600 | AD13: 400 | AE13: 120 | AF13: 0.029
A14: 800719 | B14: STK | C14: Ja | D14: 1 | E14: Ja | F14: Nein | H14: Satsumas Offenverkauf kg | I14: 2008007190005 | J14: 2 | O14: Nein | P14: 124 | Q14: 0 | R14: 0.1
A15: 800753 | B15: STK | C15: Ja | D15: 1 | E15: Ja | F15: Ja | H15: Birnen Abate Fetel | I15: 2008007530009 | J15: 2 | O15: Nein | P15: 114 | Q15: 0 | R15: 1
A16: 800754 | B16: STK | C16: Ja | D16: 1 | E16: Ja | F16: Ja | H16: Äpfel Pink Lady | I16: 2008007540008 | J16: 2 | O16: Nein | P16: 115 | Q16: 0 | R16: 1
A17: 800755 | B17: STK | C17: Ja | D17: 1 | E17: Ja | F17: Ja | H17: Äpfel rot offen Sorte sie kg | I17: 2008007550007 | J17: 3 | K17: CU | O17: Nein | P17: 122 | Q17: 1 | R17: 1 | AC17: 300 | AD17: 400 | AE17: 120 | AF17: 0.014
A18: 800785 | B18: STK | C18: Ja | D18: 1 | E18: Ja | F18: Ja | H18: Satsumas | I18: 2008007850008 | J18: 2 | O18: Nein | P18: 103 | Q18: 0 | R18: 0.1
A19: 800806 | B19: STK | C19: Ja | D19: 1 | E19: Ja | F19: Ja | H19: Zwiebeln Offenverkauf kg | I19: 2008008060000 | J19: 3 | K19: CU | O19: Nein | P19: 213 | Q19: 1 | R19: 1 | AC19: 300 | AD19: 400 | AE19: 120 | AF19: 0.014
A20: 800807 | B20: STK | C20: Ja | D20: 1 | E20: Ja | F20: Ja | H20: Birnen offen Sorte siehe kg | I20: 2008008070009 | J20: 3 | K20: CU | O20: Nein | P20: 119 | Q20: 1 | R20: 1 | AC20: 300 | AD20: 400 | AE20: 120 | AF20: 0.014
A21: 800816 | B21: STK | C21: Ja | D21: 1 | E21: Ja | F21: Nein | H21: Orangen | I21: 2008008160007 | J21: 2 | O21: Nein | P21: 117 | Q21: 0 | R21: 1
A22: 800822 | B22: STK | C22: Ja | D22: 1 | E22: Ja | F22: Ja | H22: Auberginen Offenverkauf kg | I22: 2008008220008 | J22: 3 | K22: CU | O22: Nein | P22: 212 | Q22: 1 | R22: 1 | AC22: 100 | AD22: 100 | AE22: 100 | AF22: 0.001
A23: 800826 | B23: STK | C23: Ja | D23: 1 | E23: Ja | F23: Nein | H23: Spitzpaprika rot Offenverka | I23: 2008008260004 | J23: 2 | O23: Nein | P23: 215 | Q23: 0 | R23: 1
A24: 800827 | B24: STK | C24: Ja | D24: 1 | E24: Ja | F24: Nein | H24: Lollo rot/grün | I24: 2008008270003 | J24: 2 | O24: Nein | P24: 216 | Q24: 0 | R24: 1
A25: 800828 | B25: STK | C25: Ja | D25: 1 | E25: Nein | F25: Nein | H25: Endiviensalat | J25: 2 | O25: Nein | P25: 217 | Q25: 0 | R25: 1
A26: 800834 | B26: STK | C26: Ja | D26: 1 | E26: Ja | F26: Ja | H26: Chiquita Bananen Offenver kg | I26: 2008008340003 | J26: 3 | K26: CU | O26: Nein | P26: 118 | Q26: 1 | R26: 1 | AC26: 600 | AD26: 400 | AE26: 120 | AF26: 0.029
A27: 800855 | B27: STK | C27: Ja | D27: 1 | E27: Ja | F27: Nein | H27: Flachpfirsiche | I27: 2008008550006 | J27: 2 | O27: Nein | P27: 123 | Q27: 0 | R27: 1
A28: 800882 | B28: STK | C28: Ja | D28: 1 | E28: Ja | F28: Ja | H28: Tomaten Peretti Offenver kg | I28: 2008008820000 | J28: 3 | K28: CU | O28: Nein | P28: 214 | Q28: 1 | R28: 1 | AC28: 300 | AD28: 400 | AE28: 120 | AF28: 0.014
A29: 800883 | B29: STK | C29: Ja | D29: 1 | E29: Ja | F29: Ja | H29: Nektarinen flach | I29: 2008008830009 | J29: 2 | O29: Nein | P29: 126 | Q29: 0 | R29: 1
A30: 800884 | B30: STK | C30: Ja | D30: 1 | E30: Ja | F30: Ja | H30: Trauben weiss Offenverka kg | I30: 2008008840008 | J30: 3 | K30: CU | O30: Nein | P30: 127 | Q30: 1 | R30: 1 | AC30: 300 | AD30: 400 | AE30: 120 | AF30: 0.014
A31: 800893 | B31: STK | C31: Ja | D31: 1 | E31: Ja | F31: Ja | H31: Trauben dunkel Offenverk kg | I31: 2008008930006 | J31: 3 | K31: CU | O31: Nein | P31: 132 | Q31: 1 | R31: 1 | AC31: 100 | AD31: 100 | AE31: 100 | AF31: 0.001
A32: 800917 | B32: STK | C32: Ja | D32: 1 | E32: Ja | F32: Ja | H32: Blumenkohl | I32: 2008009170005 | J32: 2 | O32: Nein | P32: 218 | Q32: 0 | R32: 1
A33: 800968 | B33: STK | C33: Ja | D33: 1 | E33: Ja | F33: Ja | H33: Rispentomaten Offenverka kg | I33: 2008009680009 | J33: 3 | K33: CU | O33: Nein | P33: 201 | Q33: 1 | R33: 1 | AC33: 600 | AD33: 400 | AE33: 120 | AF33: 0.029
A34: 800970 | B34: STK | C34: Ja | D34: 1 | E34: Ja | F34: Ja | H34: Äpfel Kl. I | I34: 2008009700004 | J34: 2 | O34: Nein | P34: 100 | Q34: 0 | R34: 0.5
A35: 800971 | B35: STK | C35: Ja | D35: 1 | E35: Ja | F35: Ja | H35: Birnen Kl. I | I35: 2008009710003 | J35: 2 | O35: Nein | P35: 101 | Q35: 0 | R35: 1
A36: 800972 | B36: STK | C36: Ja | D36: 1 | E36: Ja | F36: Ja | H36: Clementinen | I36: 2008009720002 | J36: 2 | O36: Nein | P36: 102 | Q36: 0 | R36: 0.1
A37: 800975 | B37: STK | C37: Ja | D37: 1 | E37: Ja | F37: Ja | H37: Nektarinen Offenverkauf kg | I37: 2008009750009 | J37: 3 | K37: CU | O37: Nein | P37: 107 | Q37: 1 | R37: 1 | AC37: 600 | AD37: 400 | AE37: 120 | AF37: 0.029
A38: 800976 | B38: STK | C38: Ja | D38: 1 | E38: Ja | F38: Ja | H38: Äpfel Kl. I | I38: 2008009760015 | J38: 2 | O38: Nein | P38: 110 | Q38: 0 | R38: 0.5
A39: 800978 | B39: STK | C39: Ja | D39: 1 | E39: Ja | F39: Nein | H39: Lauch grün | I39: 2008009780006 | J39: 2 | O39: Nein | P39: 211 | Q39: 0 | R39: 1
A40: 801071 | B40: STK | C40: Ja | D40: 1 | E40: Ja | F40: Ja | H40: Orangen Blond Offenverka kg | I40: 2008010710009 | J40: 3 | K40: CU | O40: Nein | P40: 106 | Q40: 1 | R40: 1 | AC40: 600 | AD40: 400 | AE40: 120 | AF40: 0.029
...

Sheet Barcodes Nav
A1: Artikelnr. | B1: Barcode Type | C1: Code | D1: Barocde aktiv (POS) | E1: Master | F1: Warengruppe | G1: Unterwarengruppe | H1: Status | I1: Variantencode | J1: Einheitencode | K1: Menge pro Einheit | L1: Aktiv gesetzt von | M1: Aktiv gesetzt am
A2: 640332 | B2: PLU | C2: 332 | D2: Nein | E2: Nein | F2: 60 | G2: 40 | H2: 96 | J2: STK | K2: 1
A3: 661105 | B3: PLU | C3: 157 | D3: Ja | E3: Nein | F3: 6 | G3: 95 | H3: 7 | J3: STK | K3: 1
A4: 661334 | B4: PLU | C4: 251 | D4: Ja | E4: Nein | F4: 6 | G4: 95 | H4: 0 | J4: STK | K4: 1
A5: 661455 | B5: PLU | C5: 158 | D5: Ja | E5: Nein | F5: 6 | G5: 75 | H5: 7 | J5: STK | K5: 1
A6: 800269 | B6: PLU | C6: 152 | D6: Ja | E6: Nein | F6: 6 | G6: 75 | H6: 0 | J6: STK | K6: 1
A7: 800693 | B7: PLU | C7: 120 | D7: Ja | E7: Nein | F7: 6 | G7: 95 | H7: 0 | J7: STK | K7: 1
A8: 800705 | B8: PLU | C8: 207 | D8: Ja | E8: Nein | F8: 6 | G8: 95 | H8: 0 | J8: STK | K8: 1
A9: 800708 | B9: PLU | C9: 111 | D9: Ja | E9: Nein | F9: 6 | G9: 95 | H9: 7 | J9: STK | K9: 1
A10: 800709 | B10: PLU | C10: 208 | D10: Ja | E10: Nein | F10: 6 | G10: 95 | H10: 0 | J10: STK | K10: 1
A11: 800717 | B11: PLU | C11: 109 | D11: Ja | E11: Nein | F11: 6 | G11: 95 | H11: 0 | J11: STK | K11: 1
A12: 800755 | B12: PLU | C12: 122 | D12: Ja | E12: Nein | F12: 6 | G12: 95 | H12: 0 | J12: STK | K12: 1
A13: 800806 | B13: PLU | C13: 213 | D13: Ja | E13: Nein | F13: 6 | G13: 95 | H13: 7 | J13: STK | K13: 1
... A51: 803456 | B51: PLU | C51: 242 | D51: Ja | E51: Nein | F51: 6 | G51: 20 | H51: 7 | J51: STK | K51: 1
A52: 999892 | B52: PLU | C52: 892 | D52: Ja | E52: Nein | F52: 87 | G52: 10 | H52: 20 | J52: COLIS | K52: 1 | L52: EGLI | M52: 40484.436
A53: 999893 | B53: PLU | C53: 903 | D53: Nein | E53: Ja | F53: 87 | G53: 20 | H53: 90 | J53: STK | K53: 1
A54: 999894 | B54: PLU | C54: 1128 | D54: Nein | E54: Ja | F54: 79 | G54: 999 | H54: 90 | J54: COLIS | K54: 1
A55: 999901 | B55: PLU | C55: 1 | D55: Ja | E55: Nein | F55: 1 | G55: 200 | H55: 7 | J55: COLIS | K55: 1
A56: 999903 | B56: PLU | C56: 3 | D56: Ja | E56: Nein | F56: 3 | G56: 95 | H56: 7 | J56: COLIS | K56: 1
A57: 999904 | B57: PLU | C57: 4 | D57: Ja | E57: Nein | F57: 4 | G57: 40 | H57: 15 | J57: COLIS | K57: 1
A58: 999905 | B58: PLU | C58: 5 | D58: Ja | E58: Nein | F58: 5 | G58: 999 | H58: 7 | J58: COLIS | K58: 1 | L58: TOMASCHETT | M58: 40912.337
A59: 999906 | B59: PLU | C59: 6 | D59: Ja | E59: Nein | F59: 6 | G59: 999 | H59: 15 | J59: COLIS | K59: 1
A60: 999906 | B60: PLU | C60: 80 | D60: Ja | E60: Nein | F60: 6 | G60: 999 | H60: 15 | J60: COLIS | K60: 1
A61: 999907 | B61: PLU | C61: 7 | D61: Ja | E61: Nein | F61: 7 | G61: 240 | H61: 7 | J61: COLIS | K61: 1
A62: 999908 | B62: PLU | C62: 8 | D62: Ja | E62: Nein | F62: 8 | G62: 260 | H62: 7 | J62: COLIS | K62: 1
A63: 999909 | B63: PLU | C63: 9 | D63: Ja | E63: Nein | F63: 9 | G63: 150 | H63: 7 | J63: COLIS | K63: 1
A64: 999910 | B64: PLU | C64: 10 | D64: Ja | E64: Nein | F64: 10 | G64: 900 | H64: 7 | J64: COLIS | K64: 1
A65: 999920 | B65: PLU | C65: 20 | D65: Ja | E65: Nein | F65: 20 | G65: 999 | H65: 7 | J65: COLIS | K65: 1 | L65: EGLI | M65: 43797.515
A66: 999931 | B66: PLU | C66: 31 | D66: Ja | E66: Nein | F66: 31 | G66: 999 | H66: 7 | J66: COLIS | K66: 1
A67: 999935 | B67: PLU | C67: 35 | D67: Ja | E67: Nein | F67: 35 | G67: 190 | H67: 7 | J67: COLIS | K67: 1
A68: 999936 | B68: PLU | C68: 36 | D68: Ja | E68: Nein | F68: 36 | G68: 900 | H68: 7 | J68: COLIS | K68: 1
A69: 999938 | B69: PLU | C69: 38 | D69: Ja | E69: Nein | F69: 38 | G69: 900 | H69: 7 | J69: COLIS | K69: 1
A70: 999940 | B70: PLU | C70: 40 | D70: Ja | E70: Nein | F70: 40 | G70: 900 | H70: 7 | J70: COLIS | K70: 1
A71: 999941 | B71: PLU | C71: 41 | D71: Ja | E71: Nein | F71: 41 | G71: 100 | H71: 7 | J71: COLIS | K71: 1
A72: 999942 | B72: PLU | C72: 42 | D72: Ja | E72: Nein | F72: 42 | G72: 130 | H72: 7 | J72: COLIS | K72: 1
A73: 999943 | B73: PLU | C73: 43 | D73: Ja | E73: Nein | F73: 43 | G73: 900 | H73: 7 | J73: COLIS | K73: 1
A74: 999944 | B74: PLU | C74: 44 | D74: Ja | E74: Nein | F74: 44 | G74: 900 | H74: 7 | J74: COLIS | K74: 1
A75: 999945 | B75: PLU | C75: 45 | D75: Ja | E75: Nein | F75: 45 | G75: 900 | H75: 7 | J75: COLIS | K75: 1
A76: 999948 | B76: PLU | C76: 48 | D76: Ja | E76: Nein | F76: 48 | G76: 900 | H76: 7 | J76: COLIS | K76: 1
A77: 999949 | B77: PLU | C77: 49 | D77: Ja | E77: Nein | F77: 49 | G77: 900 | H77: 7 | J77: COLIS | K77: 1
...

Sheet Alle PLU Nav ohne DPB PLU
A1: Artikelnr. | B1: Code PLU | C1: Kassentext | D1: Gestellbeschriftung 1 | E1: Gestellbeschriftung 2 | F1: Kassentext | G1: Gestellbeschriftung 1 | H1: Gestellbeschriftung 2 | I1: Kassentext | J1: Gestellbeschriftung 1 | K1: Gestellbeschriftung 2
A2: 640332 | B2: 332 | C2: =VLOOKUP(A2,Texte!A:G,7,0) -> Ch. Mouton Rothschild 7.5dl | D2: =VLOOKUP(A2,Texte!A:H,8,0) -> Ch. Mouton Rothschild Paulliac | E2: =VLOOKUP(A2,Texte!A:I,9,0) -> 0 | F2: =VLOOKUP(A2,Texte!A:J,10,0) -> Ch. Mouton Rothschild 7.5dl | G2: =VLOOKUP(A2,Texte!A:K,11,0) -> Ch. Mouton Rothschild Paulliac | H2: =VLOOKUP(A2,Texte!A:L,12,0) -> 0 | I2: =VLOOKUP(A2,Texte!A:M,13,0) -> Ch. Mouton Rothschild 7.5dl | J2: =VLOOKUP(A2,Texte!A:N,14,0) -> Ch. Mouton Rothschild Paulliac | K2: =VLOOKUP(A2,Texte!A:O,15,0) -> 0
A3: 661105 | B3: 157 | C3: =VLOOKUP(A3,Texte!A:G,7,0) -> Papaya Offenverkauf kg | D3: =VLOOKUP(A3,Texte!A:H,8,0) -> Papaya | E3: =VLOOKUP(A3,Texte!A:I,9,0) -> 0 | F3: =VLOOKUP(A3,Texte!A:J,10,0) -> Papaye vrac kg | G3: =VLOOKUP(A3,Texte!A:K,11,0) -> Papaye | H3: =VLOOKUP(A3,Texte!A:L,12,0) -> 0 | I3: =VLOOKUP(A3,Texte!A:M,13,0) -> Papaia Vendita sfusa kg | J3: =VLOOKUP(A3,Texte!A:N,14,0) -> Papaia | K3: =VLOOKUP(A3,Texte!A:O,15,0) -> 0
A4: 661334 | B4: 251 | C4: =VLOOKUP(A4,Texte!A:G,7,0) -> Maniok kg | D4: =VLOOKUP(A4,Texte!A:H,8,0) -> Maniok | E4: =VLOOKUP(A4,Texte!A:I,9,0) -> 0 | F4: =VLOOKUP(A4,Texte!A:J,10,0) -> Manioc kg | G4: =VLOOKUP(A4,Texte!A:K,11,0) -> Manioc | H4: =VLOOKUP(A4,Texte!A:L,12,0) -> 0 | I4: =VLOOKUP(A4,Texte!A:M,13,0) -> Manioca kg | J4: =VLOOKUP(A4,Texte!A:N,14,0) -> Manioca | K4: =VLOOKUP(A4,Texte!A:O,15,0) -> 0
A5: 661455 | B5: 158 | C5: =VLOOKUP(A5,Texte!A:G,7,0) -> Bio Mini Wassermelone kg | D5: =VLOOKUP(A5,Texte!A:H,8,0) -> Bio Mini Wassermelone | E5: =VLOOKUP(A5,Texte!A:I,9,0) -> 0 | F5: =VLOOKUP(A5,Texte!A:J,10,0) -> Mini pastèque bio kg | G5: =VLOOKUP(A5,Texte!A:K,11,0) -> Mini pastèque bio | H5: =VLOOKUP(A5,Texte!A:L,12,0) -> 0 | I5: =VLOOKUP(A5,Texte!A:M,13,0) -> Bio Mini Anguria kg | J5: =VLOOKUP(A5,Texte!A:N,14,0) -> Bio Mini Anguria | K5: =VLOOKUP(A5,Texte!A:O,15,0) -> 0
A6: 790004 | B6: 141 | C6: =VLOOKUP(A6,Texte!A:G,7,0) -> Test Waage 31. Roger | D6: =VLOOKUP(A6,Texte!A:H,8,0) -> Test Waage 31. Roger | E6: =VLOOKUP(A6,Texte!A:I,9,0) -> Offenverkauf | F6: =VLOOKUP(A6,Texte!A:J,10,0) -> Test Waage 31. Roger Offen | G6: =VLOOKUP(A6,Texte!A:K,11,0) -> Test Waage 31. Roger | H6: =VLOOKUP(A6,Texte!A:L,12,0) -> Offenverkauf | I6: =VLOOKUP(A6,Texte!A:M,13,0) -> Test Waage 31. Roger Offen | J6: =VLOOKUP(A6,Texte!A:N,14,0) -> Test Waage 31. Roger | K6: =VLOOKUP(A6,Texte!A:O,15,0) -> Offenverkauf
A7: 790005 | B7: 142 | C7: =VLOOKUP(A7,Texte!A:G,7,0) -> Test Waage 11.6. Roger | D7: =VLOOKUP(A7,Texte!A:H,8,0) -> Test Waage 11.6. Roger | E7: =VLOOKUP(A7,Texte!A:I,9,0) -> Offenverkauf | F7: =VLOOKUP(A7,Texte!A:J,10,0) -> Test Waage 11.6. Roger Off | G7: =VLOOKUP(A7,Texte!A:K,11,0) -> Test Waage 11.6. Roger | H7: =VLOOKUP(A7,Texte!A:L,12,0) -> Offenverkauf | I7: =VLOOKUP(A7,Texte!A:M,13,0) -> Test Waage 11.6. Roger Off | J7: =VLOOKUP(A7,Texte!A:N,14,0) -> Test Waage 11.6. Roger | K7: =VLOOKUP(A7,Texte!A:O,15,0) -> Offenverkauf
A8: 800269 | B8: 152 | C8: =VLOOKUP(A8,Texte!A:G,7,0) -> Wassermelonen kg | D8: =VLOOKUP(A8,Texte!A:H,8,0) -> Wassermelonen | E8: =VLOOKUP(A8,Texte!A:I,9,0) -> 0 | F8: =VLOOKUP(A8,Texte!A:J,10,0) -> Pastèques kg | G8: =VLOOKUP(A8,Texte!A:K,11,0) -> Pastèques | H8: =VLOOKUP(A8,Texte!A:L,12,0) -> 0 | I8: =VLOOKUP(A8,Texte!A:M,13,0) -> Anguria kg | J8: =VLOOKUP(A8,Texte!A:N,14,0) -> Anguria | K8: =VLOOKUP(A8,Texte!A:O,15,0) -> 0
A9: 800471 | B9: 244 | C9: =VLOOKUP(A9,Texte!A:G,7,0) -> Zwiebeln | D9: =VLOOKUP(A9,Texte!A:H,8,0) -> IP-Suisse Zwiebeln | E9: =VLOOKUP(A9,Texte!A:I,9,0) -> Offenverkauf | F9: =VLOOKUP(A9,Texte!A:J,10,0) -> IP-Suisse Oingons en vrac | G9: =VLOOKUP(A9,Texte!A:K,11,0) -> IP-Suisse Oignons | H9: =VLOOKUP(A9,Texte!A:L,12,0) -> en vrac | I9: =VLOOKUP(A9,Texte!A:M,13,0) -> Cipolle | J9: =VLOOKUP(A9,Texte!A:N,14,0) -> IP-Suisse Cipolle | K9: =VLOOKUP(A9,Texte!A:O,15,0) -> vendita sfusa
A10: 800693 | B10: 120 | C10: =VLOOKUP(A10,Texte!A:G,7,0) -> Pflaumen Offenverkauf kg | D10: =VLOOKUP(A10,Texte!A:H,8,0) -> Pflaumen | E10: =VLOOKUP(A10,Texte!A:I,9,0) -> 0 | F10: =VLOOKUP(A10,Texte!A:J,10,0) -> Prunes vrac kg | G10: =VLOOKUP(A10,Texte!A:K,11,0) -> Prunes | H10: =VLOOKUP(A10,Texte!A:L,12,0) -> 0 | I10: =VLOOKUP(A10,Texte!A:M,13,0) -> Prugne vendita sfusa kg | J10: =VLOOKUP(A10,Texte!A:N,14,0) -> Prugne | K10: =VLOOKUP(A10,Texte!A:O,15,0) -> 0
A11: 800705 | B11: 207 | C11: =VLOOKUP(A11,Texte!A:G,7,0) -> Tomaten Spezial Offenverk kg | D11: =VLOOKUP(A11,Texte!A:H,8,0) -> Tomaten | E11: =VLOOKUP(A11,Texte!A:I,9,0) -> Spezial | F11: =VLOOKUP(A11,Texte!A:J,10,0) -> Tomates Spécial en vrac kg | G11: =VLOOKUP(A11,Texte!A:K,11,0) -> Tomates | H11: =VLOOKUP(A11,Texte!A:L,12,0) -> Spécial | I11: =VLOOKUP(A11,Texte!A:M,13,0) -> Pomodori Speciale vendita kg | J11: =VLOOKUP(A11,Texte!A:N,14,0) -> Pomodori | K11: =VLOOKUP(A11,Texte!A:O,15,0) -> Speciale
A12: 800708 | B12: 111 | C12: =VLOOKUP(A12,Texte!A:G,7,0) -> Zwetschgen Offenverkauf kg | D12: =VLOOKUP(A12,Texte!A:H,8,0) -> Zwetschgen | E12: =VLOOKUP(A12,Texte!A:I,9,0) -> 0 | F12: =VLOOKUP(A12,Texte!A:J,10,0) -> Pruneaux en vrac kg | G12: =VLOOKUP(A12,Texte!A:K,11,0) -> Pruneaux | H12: =VLOOKUP(A12,Texte!A:L,12,0) -> 0 | I12: =VLOOKUP(A12,Texte!A:M,13,0) -> Prugne vendita di merce kg | J12: =VLOOKUP(A12,Texte!A:N,14,0) -> Prugne | K12: =VLOOKUP(A12,Texte!A:O,15,0) -> 0
A13: 800709 | B13: 208 | C13: =VLOOKUP(A13,Texte!A:G,7,0) -> Süss-Kartoffeln Offenver kg | D13: =VLOOKUP(A13,Texte!A:H,8,0) -> Süss-Kartoffeln | E13: =VLOOKUP(A13,Texte!A:I,9,0) -> 0 | F13: =VLOOKUP(A13,Texte!A:J,10,0) -> Patates douces en vrac kg | G13: =VLOOKUP(A13,Texte!A:K,11,0) -> Patates douces | H13: =VLOOKUP(A13,Texte!A:L,12,0) -> 0 | I13: =VLOOKUP(A13,Texte!A:M,13,0) -> Patate dolci vendita sfu kg | J13: =VLOOKUP(A13,Texte!A:N,14,0) -> Patate dolci | K13: =VLOOKUP(A13,Texte!A:O,15,0) -> 0
... A150: 999999 | B150: 99 | C150: =VLOOKUP(A150,Texte!A:G,7,0) -> Gebinde | D150: =VLOOKUP(A150,Texte!A:H,8,0) -> Gebinde | E150: =VLOOKUP(A150,Texte!A:I,9,0) -> 0 | F150: =VLOOKUP(A150,Texte!A:J,10,0) -> Emballages | G150: =VLOOKUP(A150,Texte!A:K,11,0) -> Emballages | H150: =VLOOKUP(A150,Texte!A:L,12,0) -> 0 | I150: =VLOOKUP(A150,Texte!A:M,13,0) -> Contenitori | J150: =VLOOKUP(A150,Texte!A:N,14,0) -> Contenitori | K150: =VLOOKUP(A150,Texte!A:O,15,0) -> 0

Sheet Texte
A1: Artikel Nr. | B1: Warengruppe | C1: Status | D1: Sprachcode | E1: Einheit | F1: Menge pro Einheit | G1: Kassentext | H1: Gestellbeschriftung 1 | I1: Gestellbeschriftung 2 | J1: Kassentext | K1: Gestellbeschriftung 1 | L1: Gestellbeschriftung 2 | M1: Kassentext | N1: Gestellbeschriftung 1 | O1: Gestellbeschriftung 2
A2: 640332 | B2: 60 | C2: 96 | D2: DEU | E2: STK | F2: 1 | G2: Ch. Mouton Rothschild 7.5dl | H2: Ch. Mouton Rothschild Paulliac | J2: Ch. Mouton Rothschild 7.5dl | K2: Ch. Mouton Rothschild Paulliac | M2: Ch. Mouton Rothschild 7.5dl | N2: Ch. Mouton Rothschild Paulliac
A3: 661105 | B3: 6 | C3: 7 | D3: DEU | E3: STK | F3: 1 | G3: Papaya Offenverkauf kg | H3: Papaya | J3: Papaye vrac kg | K3: Papaye | M3: Papaia Vendita sfusa kg | N3: Papaia
A4: 661334 | B4: 6 | C4: 0 | D4: DEU | E4: STK | F4: 1 | G4: Maniok kg | H4: Maniok | J4: Manioc kg | K4: Manioc | M4: Manioca kg | N4: Manioca
A5: 661455 | B5: 6 | C5: 7 | D5: DEU | E5: STK | F5: 1 | G5: Bio Mini Wassermelone kg | H5: Bio Mini Wassermelone | J5: Mini pastèque bio kg | K5: Mini pastèque bio | M5: Bio Mini Anguria kg | N5: Bio Mini Anguria
A6: 790004 | B6: 6 | C6: 92 | D6: DEU | E6: STK | F6: 1 | G6: Test Waage 31. Roger | H6: Test Waage 31. Roger | I6: Offenverkauf | J6: Test Waage 31. Roger Offen | K6: Test Waage 31. Roger | L6: Offenverkauf | M6: Test Waage 31. Roger Offen | N6: Test Waage 31. Roger | O6: Offenverkauf
A7: 790005 | B7: 6 | C7: 92 | D7: DEU | E7: STK | F7: 1 | G7: Test Waage 11.6. Roger | H7: Test Waage 11.6. Roger | I7: Offenverkauf | J7: Test Waage 11.6. Roger Off | K7: Test Waage 11.6. Roger | L7: Offenverkauf | M7: Test Waage 11.6. Roger Off | N7: Test Waage 11.6. Roger | O7: Offenverkauf
A8: 800269 | B8: 6 | C8: 0 | D8: DEU | E8: STK | F8: 1 | G8: Wassermelonen kg | H8: Wassermelonen | J8: Pastèques kg | K8: Pastèques | M8: Anguria kg | N8: Anguria
A9: 800471 | B9: 6 | C9: 92 | D9: DEU | E9: STK | F9: 1 | G9: Zwiebeln | H9: IP-Suisse Zwiebeln | I9: Offenverkauf | J9: IP-Suisse Oingons en vrac | K9: IP-Suisse Oignons | L9: en vrac | M9: Cipolle | N9: IP-Suisse Cipolle | O9: vendita sfusa
A10: 800693 | B10: 6 | C10: 0 | D10: DEU | E10: STK | F10: 1 | G10: Pflaumen Offenverkauf kg | H10: Pflaumen | J10: Prunes vrac kg | K10: Prunes | M10: Prugne vendita sfusa kg | N10: Prugne
A11: 800705 | B11: 6 | C11: 0 | D11: DEU | E11: STK | F11: 1 | G11: Tomaten Spezial Offenverk kg | H11: Tomaten | I11: Spezial | J11: Tomates Spécial en vrac kg | K11: Tomates | L11: Spécial | M11: Pomodori Speciale vendita kg | N11: Pomodori | O11: Speciale
A12: 800708 | B12: 6 | C12: 7 | D12: DEU | E12: STK | F12: 1 | G12: Zwetschgen Offenverkauf kg | H12: Zwetschgen | J12: Pruneaux en vrac kg | K12: Pruneaux | M12: Prugne vendita di merce kg | N12: Prugne
A13: 800709 | B13: 6 | C13: 0 | D13: DEU | E13: STK | F13: 1 | G13: Süss-Kartoffeln Offenver kg | H13: Süss-Kartoffeln | J13: Patates douces en vrac kg | K13: Patates douces | M13: Patate dolci vendita sfu kg | N13: Patate dolci
A14: 800717 | B14: 6 | C14: 0 | D14: DEU | E14: STK | F14: 1 | G14: Pfirsiche Offenverkauf kg | H14: Pfirsiche | J14: Pêches en vrac kg | K14: Pêches | M14: Pesche vendita sfusa kg | N14: Pesche
A15: 800719 | B15: 6 | C15: 15 | D15: DEU | E15: STK | F15: 1 | G15: Satsumas Offenverkauf kg | H15: Satsumas | I15: Offenverkauf | J15: Satsumas Offenverkauf kg | K15: Satsumas | L15: Offenverkauf | M15: Satsumas Offenverkauf kg | N15: Satsumas | O15: Offenverkauf
A16: 800753 | B16: 6 | C16: 15 | D16: DEU | E16: STK | F16: 1 | G16: Birnen Abate Fetel | H16: Birnen Abate Fetel | I16: Offenverkauf | J16: Poires Abate Fetel | K16: Poires Abate Fetel | L16: en vrac | M16: Birnen Abate Fetel | N16: Birnen Abate Fetel | O16: vendita sfusa
A17: 800754 | B17: 6 | C17: 15 | D17: DEU | E17: STK | F17: 1 | G17: Äpfel Pink Lady | H17: Äpfel Pink Lady | I17: Offenverkauf | J17: Pommes Pink Lady | K17: Pommes Pink Lady | L17: en vrac | M17: Mele Pink Lady | N17: Mele Pink Lady | O17: vendita sfusa
A18: 800755 | B18: 6 | C18: 0 | D18: DEU | E18: STK | F18: 1 | G18: Äpfel rot offen Sorte sie kg | H18: Äpfel rot | I18: offen | J18: Pommes rouges en vrac Sor kg | K18: Pommes rouges | L18: en vrac | M18: Mele rosse vendita sfu va kg | N18: Mele rosse | O18: vendita sfusa
A19: 800785 | B19: 6 | C19: 15 | D19: DEU | E19: STK | F19: 1 | G19: Satsumas | H19: Satsumas | I19: Offenverkauf | J19: Mandarines | K19: Mandarines | L19: en vrac | M19: Mandarini | N19: Mandarini | O19: vendita sfusa
A20: 800806 | B20: 6 | C20: 7 | D20: DEU | E20: STK | F20: 1 | G20: Zwiebeln Offenverkauf kg | H20: Zwiebeln | J20: Oignons vrac kg | K20: Oignons | M20: Cipolle vendita sfusa kg | N20: Cipolle
A21: 800807 | B21: 6 | C21: 0 | D21: DEU | E21: STK | F21: 1 | G21: Birnen offen Sorte siehe kg | H21: Birnen | I21: offen | J21: Poires en vrac Sorte voir kg | K21: Poires | L21: en vrac | M21: Pere vendita sfusa variet kg | N21: Pere | O21: vendita sfusa
A22: 800816 | B22: 6 | C22: 15 | D22: DEU | E22: STK | F22: 1 | G22: Orangen | H22: Orangen | I22: Offenverkauf | J22: Oranges | K22: Oranges | L22: en vrac | M22: Arance | N22: Arance | O22: vendita sfusa
A23: 800822 | B23: 6 | C23: 0 | D23: DEU | E23: STK | F23: 1 | G23: Auberginen Offenverkauf kg | H23: Auberginen | J23: Aubergines en vrac kg | K23: Aubergines | M23: Melanzane vendita sfusa kg | N23: Melanzane
A24: 800826 | B24: 6 | C24: 15 | D24: DEU | E24: STK | F24: 1 | G24: Spitzpaprika rot Offenverka | H24: Sweet-Paprika Ramiro | I24: Offenverkauf | J24: Poivrons doux pointus vrac | K24: Poivrons doux pointus Ramiro | L24: en vrac | M24: Pepperoni Palermo rosso ven | N24: Peperoni dolci Ramiro | O24: vendita sfusa
A25: 800827 | B25: 6 | C25: 15 | D25: DEU | E25: STK | F25: 1 | G25: Lollo rot/grün | H25: Salat Gewicht | I25: Offenverkauf | J25: Lollo rot/grün | K25: Salade rouge/verte | L25: vrac | M25: Lollo rot/grün | N25: Insalata rosso / verde | O25: vendita sfusa
A26: 800828 | B26: 6 | C26: 92 | D26: DEU | E26: STK | F26: 1 | G26: Endiviensalat | H26: Endiviensalat | I26: Offenverkauf | J26: Scarole | K26: Scarole | L26: en vrac | M26: Indivia Scarola | N26: Indivia Scarola | O26: vendita sfusa
A27: 800834 | B27: 6 | C27: 7 | D27: DEU | E27: STK | F27: 1 | G27: Chiquita Bananen Offenver kg | H27: Chiquita | I27: Bananen | J27: Chiquita Bananes vrac kg | K27: Chiquita | L27: Bananes | M27: Chiquita banane vendita s kg | N27: Chiquita | O27: banane
A28: 800855 | B28: 6 | C28: 15 | D28: DEU | E28: STK | F28: 1 | G28: Flachpfirsiche | H28: Flachpfirsiche | I28: Offenverkauf | J28: Flachpfirsiche | K28: Pêches plates | L28: vrac | M28: Flachpfirsiche | N28: Pesche piatte | O28: vendita sfusa
A29: 800882 | B29: 6 | C29: 0 | D29: DEU | E29: STK | F29: 1 | G29: Tomaten Peretti Offenver kg | H29: Tomaten Peretti | J29: Tomates Peretti vrac kg | K29: Tomates Peretti | M29: Pomodori Peretti vendita kg | N29: Pomodori Peretti
A30: 800883 | B30: 6 | C30: 15 | D30: DEU | E30: STK | F30: 1 | G30: Nektarinen flach | H30: Nektarinen flach | I30: Offenverkauf | J30: Nectarines | K30: Nectarines | L30: en vrac | M30: Nettarine | N30: Nettarine | O30: vendita sfusa
A31: 800884 | B31: 6 | C31: 0 | D31: DEU | E31: STK | F31: 1 | G31: Trauben weiss Offenverka kg | H31: Trauben weiss | J31: Raisin blanc vrac kg | K31: Raisin | L31: blanc | M31: Uva bianca vendita di mer kg | N31: Uva | O31: bianca
A32: 800893 | B32: 6 | C32: 0 | D32: DEU | E32: STK | F32: 1 | G32: Trauben dunkel Offenverk kg | H32: Trauben dunkel | J32: Raisin noir vrac kg | K32: Raisin | L32: noir | M32: Uva scura Vendita sfusa kg | N32: Uva | O32: scura
A33: 800917 | B33: 6 | C33: 15 | D33: DEU | E33: STK | F33: 1 | G33: Blumenkohl | H33: Romanesco | I33: Offenverkauf | J33: Chou-fleur | K33: Romanesco | L33: en vrac | M33: Cavolfiori | N33: Romanesco | O33: vendita sfusa
A34: 800968 | B34: 6 | C34: 0 | D34: DEU | E34: STK | F34: 1 | G34: Rispentomaten Offenverka kg | H34: Rispentomaten | J34: Tomates grappes en vrac kg | K34: Tomates grappes | M34: Pomodori ramato vendita kg | N34: Pomodori ramato
A35: 800970 | B35: 6 | C35: 15 | D35: DEU | E35: STK | F35: 1 | G35: Äpfel Kl. I | H35: Äpfel Kl. I , Jonagold | I35: Offenverkauf | J35: Pommes Kl. I | K35: Pommes Cl. I , Jonagold | L35: en vrac | M35: Mele Kl. I | N35: Mele Cl I , Jonagold | O35: vendita di merce sfusa
A36: 800971 | B36: 6 | C36: 15 | D36: DEU | E36: STK | F36: 1 | G36: Birnen Kl. I | H36: Birnen Kl. I | I36: Offenverkauf | J36: Poires cl. I | K36: Poires cl. I | L36: vrac | M36: Pere Kl. I | N36: Pere Cl. I | O36: vendita sfusa
A37: 800972 | B37: 6 | C37: 15 | D37: DEU | E37: STK | F37: 1 | G37: Clementinen | H37: Clementinen | I37: Offenverkauf | J37: Clementines | K37: Clementines | L37: en vrac | M37: Clementine | N37: Clementine | O37: vendita sfusa
A38: 800975 | B38: 6 | C38: 0 | D38: DEU | E38: STK | F38: 1 | G38: Nektarinen Offenverkauf kg | H38: Nektarinen | J38: Nectarines en vrac kg | K38: Nectarines | M38: Nettarine vendita sfusa kg | N38: Nettarine
A39: 800976 | B39: 6 | C39: 15 | D39: DEU | E39: STK | F39: 1 | G39: Äpfel Kl. I | H39: Äpfel Kl. I | I39: Offenverkauf | J39: Pommes Kl. I | K39: Pommes Kl. I | L39: en vrac | M39: Mele Kl. I | N39: Mele Kl. I | O39: vendita di merce sfusa
A40: 800978 | B40: 6 | C40: 15 | D40: DEU | E40: STK | F40: 1 | G40: Lauch grün | H40: Lauch grün | I40: Offenverkauf | J40: Poireau | K40: Poireau | L40: vrac | M40: Porro | N40: Porro | O40: vendita sfusa
...
