Workbook
Name EntitiesCol: Entities!$SRS$2
Name EntitiesRow: Entities!$A$1000000
Name RelationshipsCol: [1]Relationships!$SSS$2
Name RelationshipsRow: [1]Relationships!$A$1000000
Name RSC__refxartikeltypsap: 'Reference Data'!$T$2:$T$5
Name RSC__refxbooleanalkoholhaltig: 'Reference Data'!$U$2:$U$5
Name RSC__refxboolen: 'Reference Data'!$V$2:$V$5
Name RSC__refxgtintyperegioartikel: 'Reference Data'!$AP$2:$AP$5
Name RSC__refxshopinshop: 'Reference Data'!$AO$2:$AO$5
Name RSC__refxsystemsap: 'Reference Data'!$AQ$2:$AQ$5
Name RSC_atxalkoholhaltig__de_DE: 'Reference Data'!$M$2:$M$2
Name RSC_atxalkoholhaltig__fr_FR: 'Reference Data'!$L$2:$L$2
Name RSC_atxalkoholhaltig__it_IT: 'Reference Data'!$G$2:$G$2
Name RSC_atxwarengruppesap__de_DE: 'Reference Data'!$B$2:$B$2
Name RSC_atxwarengruppesap__fr_FR: 'Reference Data'!$E$2:$E$2
Name RSC_atxwarengruppesap__it_IT: 'Reference Data'!$O$2:$O$2
Name RSC_axartikelslpmstruktur__de_DE: 'Reference Data'!$C$2:$C$2
Name RSC_axartikelslpmstruktur__fr_FR: 'Reference Data'!$H$2:$H$2
Name RSC_axartikelslpmstruktur__it_IT: 'Reference Data'!$A$2:$A$2
Name RSC_axartikeltypsap__de_DE: 'Reference Data'!$J$2:$J$2
Name RSC_axartikeltypsap__fr_FR: 'Reference Data'!$I$2:$I$2
Name RSC_axartikeltypsap__it_IT: 'Reference Data'!$P$2:$P$2
Name RSC_axmhdvorhanden__de_DE: 'Reference Data'!$N$2:$N$2
Name RSC_axmhdvorhanden__fr_FR: 'Reference Data'!$Q$2:$Q$2
Name RSC_axmhdvorhanden__it_IT: 'Reference Data'!$D$2:$D$2
Name RSC_axtaxdummyfilter__de_DE: 'Reference Data'!$K$2:$K$2
Name RSC_axtaxdummyfilter__fr_FR: 'Reference Data'!$R$2:$R$2
Name RSC_axtaxdummyfilter__it_IT: 'Reference Data'!$F$2:$F$2
Name RSC_de_DE_refxaltersbegrtyp: 'Reference Data'!$AL$2:$AL$9
Name RSC_de_DE_refxartikelartsap: 'Reference Data'!$W$2:$W$14
Name RSC_de_DE_refxmengeneinheit: 'Reference Data'!$AC$2:$AC$14
Name RSC_de_DE_refxsaisontypsap: 'Reference Data'!$Z$2:$Z$7
Name RSC_de_DE_refxtaxclass: 'Reference Data'!$AI$2:$AI$6
Name RSC_de_DE_refxvergleichspreiseinheit: 'Reference Data'!$AF$2:$AF$6
Name RSC_ENTITY_NAME: 'Reference Data'!$S$2:$S$2
Name RSC_fr_FR_refxaltersbegrtyp: 'Reference Data'!$AM$2:$AM$9
Name RSC_fr_FR_refxartikelartsap: 'Reference Data'!$X$2:$X$6
Name RSC_fr_FR_refxmengeneinheit: 'Reference Data'!$AD$2:$AD$14
Name RSC_fr_FR_refxsaisontypsap: 'Reference Data'!$AA$2:$AA$7
Name RSC_fr_FR_refxtaxclass: 'Reference Data'!$AJ$2:$AJ$6
Name RSC_fr_FR_refxvergleichspreiseinheit: 'Reference Data'!$AG$2:$AG$3
Name RSC_it_IT_refxaltersbegrtyp: 'Reference Data'!$AN$2:$AN$9
Name RSC_it_IT_refxartikelartsap: 'Reference Data'!$Y$2:$Y$6
Name RSC_it_IT_refxmengeneinheit: 'Reference Data'!$AE$2:$AE$14
Name RSC_it_IT_refxsaisontypsap: 'Reference Data'!$AB$2:$AB$7
Name RSC_it_IT_refxtaxclass: 'Reference Data'!$AK$2:$AK$6
Name RSC_it_IT_refxvergleichspreiseinheit: 'Reference Data'!$AH$2:$AH$3

Sheet Help
B3: These are all read only
A4: TEMPLATE NAME | B4: RS EXCEL
A5: TEMPLATE VERSION | B5: V1.0
A6: MULTI VALUES DELIMITER | B6: ||
A7: CONTEXT PATH DELIMITER | B7: >>
A8: LEGENDS | B8: INHERITED VALUE(S)
B9: GOVERNANCE ERROR(S)
A12: Type
A13: SYSTEM/RELATIONSHIPS | B13: COLLECTION | C13: MANDATORY | D13: MANDATORY COLLECTION
A14: GLOBAL | B14: COLLECTION | C14: MANDATORY | D14: MANDATORY COLLECTION
A15: GLOBAL ENHANCER | B15: COLLECTION | C15: MANDATORY | D15: MANDATORY COLLECTION
A16: CONTEXT | B16: COLLECTION | C16: MANDATORY | D16: MANDATORY COLLECTION
A17: CONTEXT ENHANCER | B17: COLLECTION | C17: MANDATORY | D17: MANDATORY COLLECTION

Sheet Entities
A1: System Attributes | E1: Enhancer Attribute(s) | G1: Matching Attribute(s) | H1: 01 - Rumpfinformationen | J1: 99 - intern | L1: 01 - Rumpfinformationen | O1: 03 - Texte | U1: 99 - intern | AA1: 01 - Rumpfinformationen | AG1: 05 - Kasse | AL1: 99 - intern
A2: Action | B2: Type | C2: ID | D2: Name | E2: Artikeltyp | F2: Warengruppe//de-DE | G2: MDM ID | H2: Artikelart//de-DE | I2: Saison Typ//de-DE | J2: GTIN Suche | K2: Ergänzte Regio-Artikel-GTIN | L2: Artikeltext//de-DE | M2: Artikeltext//fr-FR | N2: Artikeltext//it-IT | O2: Gestellbeschriftung 1//de-DE | P2: Gestellbeschriftung 1//fr-FR | Q2: Gestellbeschriftung 1//it-IT | R2: Gestellbeschriftung 2//de-DE | S2: Gestellbeschriftung 2//fr-FR | T2: Gestellbeschriftung 2//it-IT | U2: Gestellbeschriftung 3 Regio//de-DE | V2: Gestellbeschriftung 3 Regio//fr-FR | W2: Gestellbeschriftung 3 Regio//it-IT | X2: Cash receipt text Regio//de-DE | Y2: Cash receipt text Regio//fr-FR | Z2: Cash receipt text Regio//it-IT | AA2: Nettoinhalt | AB2: Inhaltsmengeneinheit Grundpreis//de-DE | AC2: Grundpreiseinheit//de-DE | AD2: Basismengeneinheit//de-DE | AE2: Steuerklassifikation//de-DE | AF2: Altersbegrenzungs-Typ//de-DE | AG2: Rabatt zugelassen | AH2: Rückgabe zugelassen | AI2: Preisänderung Kasse erlaubt | AJ2: Automatischer Bondruck | AK2: Shop-In-Shop | AL2: Ist Fremdartikel | AM2: GTIN-Typ Regioapp | AN2: Ist Regioartikel | AO2: SAP System Integration
B3: exartikel | C3: fb03a8a8-92fa-4327-9d81-07b476c5f202 | D3: 1602056 - 661812 - Importierter Artikeltext PLU | E3: 00 - Einzelartikel | F3: Warengruppe>>Getränke>>Tafelgetränke>>Säfte gekühlt | G3: 1602056 | H3: ZHAW - Handelsware ohne Charge | I3: In/Out | J3: 753 | L3: Importierter Artikeltext PLU | M3: Importierter Artikeltext PLU | N3: Importierter Artikeltext PLU | O3: Kirschsaft | P3: Kirschsaft | Q3: Kirschsaft | R3: frisch ab Presse | S3: frisch ab Presse | T3: frisch ab Presse | U3: ca. 250 ml | X3: Kirschsaft ca. 250 ml | AA3: 0.25 | AB3: Milliliter | AC3: 100 | AD3: (PCE) Stück | AE3: 1 - Normalsatz | AF3: Keine | AG3: false | AH3: false | AI3: false | AJ3: false | AL3: false | AM3: PLU | AN3: true | AO3: S4H
B4: exartikel | E4: 00 - Einzelartikel | F4: ="Warengruppe>>"&Migrationsartikel!V2&">>"&Migrationsartikel!W2&">>"&Migrationsartikel!X2 -> Warengruppe>>Backwaren & Convenience>>Brot und Backwaren>>Backwaren andere | H4: ZHAW - Handelsware ohne Charge | I4: In/Out | J4: =Migrationsartikel!B2 -> 700 | L4: =Migrationsartikel!F2&" "&Migrationsartikel!G2&" "&Migrationsartikel!H2 -> Baguette aus der Region 250g | M4: =Migrationsartikel!J2&" "&Migrationsartikel!K2&" "&Migrationsartikel!L2 -> Baguette de la région 250g | N4: =Migrationsartikel!N2&" "&Migrationsartikel!O2&" "&Migrationsartikel!P2 -> Baguette della regione 250g | O4: =Migrationsartikel!F2 -> Baguette | P4: =Migrationsartikel!J2 -> Baguette | Q4: =Migrationsartikel!N2 -> Baguette | R4: =Migrationsartikel!G2 -> aus der Region | S4: =Migrationsartikel!K2 -> de la région | T4: =Migrationsartikel!O2 -> della regione | U4: =Migrationsartikel!H2 -> 250g | V4: =Migrationsartikel!L2 -> 250g | W4: =Migrationsartikel!P2 -> 250g | X4: =Migrationsartikel!I2 -> Baguette 250g | Y4: =Migrationsartikel!M2 -> Baguette 250g | Z4: =Migrationsartikel!Q2 -> Baguette 250g | AA4: =Migrationsartikel!R2 -> 0.25 | AB4: =Migrationsartikel!T2 -> Gramm | AC4: =Migrationsartikel!S2 -> 100 | AD4: =Migrationsartikel!U2 -> (PCE) Stück | AE4: 1 - Normalsatz | AF4: Keine | AG4: =IF(Migrationsartikel!AB2="ja","true",FALSE) -> true | AH4: =IF(Migrationsartikel!AC2="ja","true",FALSE) -> true | AI4: =IF(Migrationsartikel!AD2="ja","true",FALSE) -> true | AJ4: =IF(Migrationsartikel!AE2="ja","true",FALSE) -> true | AK4: =IF(Migrationsartikel!AF2="ja","Denner Partner","") | AL4: =IF(Migrationsartikel!AG2="ja","true","false") -> false | AM4: =IF(J4<>"","PLU","Kassentastenbelegung (ohne GTIN/PLU)") -> PLU | AN4: true | AO4: S4H
B5: exartikel | E5: 1 - Einzelartikel | F5: ="Warengruppe>>"&Migrationsartikel!V3&">>"&Migrationsartikel!W3&">>"&Migrationsartikel!X3 -> Warengruppe>>Backwaren & Convenience>>Brot und Backwaren>>Backwaren andere | H5: ZHAW - Handelsware ohne Charge | I5: In/Out | J5: =Migrationsartikel!B3 -> 701 | L5: =Migrationsartikel!F3&" "&Migrationsartikel!G3&" "&Migrationsartikel!H3 -> Baslerbrot aus der Region 250g | M5: =Migrationsartikel!J3&" "&Migrationsartikel!K3&" "&Migrationsartikel!L3 -> Pain bâlois de la région 250g | N5: =Migrationsartikel!N3&" "&Migrationsartikel!O3&" "&Migrationsartikel!P3 -> Pane di Basilea della regione 250g | O5: =Migrationsartikel!F3 -> Baslerbrot | P5: =Migrationsartikel!J3 -> Pain bâlois | Q5: =Migrationsartikel!N3 -> Pane di Basilea | R5: =Migrationsartikel!G3 -> aus der Region | S5: =Migrationsartikel!K3 -> de la région | T5: =Migrationsartikel!O3 -> della regione | U5: =Migrationsartikel!H3 -> 250g | V5: =Migrationsartikel!L3 -> 250g | W5: =Migrationsartikel!P3 -> 250g | X5: =Migrationsartikel!I3 -> Baslerbrot 250g | Y5: =Migrationsartikel!M3 -> Pain bâlois 250g | Z5: =Migrationsartikel!Q3 -> Pane di Basilea 250g | AA5: =Migrationsartikel!R3 -> 0.25 | AB5: =Migrationsartikel!T3 -> Gramm | AC5: =Migrationsartikel!S3 -> 100 | AD5: =Migrationsartikel!U3 -> (PCE) Stück | AE5: 1 - Normalsatz | AF5: Keine | AG5: =IF(Migrationsartikel!AB3="ja","true",FALSE) -> true | AH5: =IF(Migrationsartikel!AC3="ja","true",FALSE) -> true | AI5: =IF(Migrationsartikel!AD3="ja","true",FALSE) -> true | AJ5: =IF(Migrationsartikel!AE3="ja","true",FALSE) -> true | AK5: =IF(Migrationsartikel!AF3="ja","Denner Partner","") | AL5: =IF(Migrationsartikel!AG3="ja","true","false") -> false | AM5: =IF(J5<>"","PLU","Kassentastenbelegung (ohne GTIN/PLU)") -> PLU | AN5: true | AO5: S4H
B6: exartikel | E6: 2 - Einzelartikel | F6: ="Warengruppe>>"&Migrationsartikel!V4&">>"&Migrationsartikel!W4&">>"&Migrationsartikel!X4 -> Warengruppe>>Backwaren & Convenience>>Brot und Backwaren>>Backwaren andere | H6: ZHAW - Handelsware ohne Charge | I6: In/Out | J6: =Migrationsartikel!B4 -> 702 | L6: =Migrationsartikel!F4&" "&Migrationsartikel!G4&" "&Migrationsartikel!H4 -> Baslerbrot aus der Region 500g | M6: =Migrationsartikel!J4&" "&Migrationsartikel!K4&" "&Migrationsartikel!L4 -> Pain bâlois de la région 500g | N6: =Migrationsartikel!N4&" "&Migrationsartikel!O4&" "&Migrationsartikel!P4 -> Pane di Basilea della regione 500g | O6: =Migrationsartikel!F4 -> Baslerbrot | P6: =Migrationsartikel!J4 -> Pain bâlois | Q6: =Migrationsartikel!N4 -> Pane di Basilea | R6: =Migrationsartikel!G4 -> aus der Region | S6: =Migrationsartikel!K4 -> de la région | T6: =Migrationsartikel!O4 -> della regione | U6: =Migrationsartikel!H4 -> 500g | V6: =Migrationsartikel!L4 -> 500g | W6: =Migrationsartikel!P4 -> 500g | X6: =Migrationsartikel!I4 -> Baslerbrot 500g | Y6: =Migrationsartikel!M4 -> Pain bâlois 500g | Z6: =Migrationsartikel!Q4 -> Pane di Basilea 500g | AA6: =Migrationsartikel!R4 -> 0.5 | AB6: =Migrationsartikel!T4 -> Gramm | AC6: =Migrationsartikel!S4 -> 100 | AD6: =Migrationsartikel!U4 -> (PCE) Stück | AE6: 1 - Normalsatz | AF6: Keine | AG6: =IF(Migrationsartikel!AB4="ja","true",FALSE) -> true | AH6: =IF(Migrationsartikel!AC4="ja","true",FALSE) -> true | AI6: =IF(Migrationsartikel!AD4="ja","true",FALSE) -> true | AJ6: =IF(Migrationsartikel!AE4="ja","true",FALSE) -> true | AK6: =IF(Migrationsartikel!AF4="ja","Denner Partner","") | AL6: =IF(Migrationsartikel!AG4="ja","true","false") -> false | AM6: =IF(J6<>"","PLU","Kassentastenbelegung (ohne GTIN/PLU)") -> PLU | AN6: true | AO6: S4H
B7: exartikel | E7: 3 - Einzelartikel | F7: ="Warengruppe>>"&Migrationsartikel!V5&">>"&Migrationsartikel!W5&">>"&Migrationsartikel!X5 -> Warengruppe>>Backwaren & Convenience>>Brot und Backwaren>>Backwaren andere | H7: ZHAW - Handelsware ohne Charge | I7: In/Out | J7: =Migrationsartikel!B5 -> 703 | L7: =Migrationsartikel!F5&" "&Migrationsartikel!G5&" "&Migrationsartikel!H5 -> Berliner aus der Region 1Stk | M7: =Migrationsartikel!J5&" "&Migrationsartikel!K5&" "&Migrationsartikel!L5 -> Boule de Berlin de la région 1pce | N7: =Migrationsartikel!N5&" "&Migrationsartikel!O5&" "&Migrationsartikel!P5 -> Berliner della regione 1pz | O7: =Migrationsartikel!F5 -> Berliner | P7: =Migrationsartikel!J5 -> Boule de Berlin | Q7: =Migrationsartikel!N5 -> Berliner | R7: =Migrationsartikel!G5 -> aus der Region | S7: =Migrationsartikel!K5 -> de la région | T7: =Migrationsartikel!O5 -> della regione | U7: =Migrationsartikel!H5 -> 1Stk | V7: =Migrationsartikel!L5 -> 1pce | W7: =Migrationsartikel!P5 -> 1pz | X7: =Migrationsartikel!I5 -> Berliner | Y7: =Migrationsartikel!M5 -> Boule de Berlin | Z7: =Migrationsartikel!Q5 -> Berliner | AA7: =Migrationsartikel!R5 -> 1 | AB7: =Migrationsartikel!T5 -> Stück | AC7: =Migrationsartikel!S5 -> 1 | AD7: =Migrationsartikel!U5 -> (PCE) Stück | AE7: 1 - Normalsatz | AF7: Keine | AG7: =IF(Migrationsartikel!AB5="ja","true",FALSE) -> true | AH7: =IF(Migrationsartikel!AC5="ja","true",FALSE) -> true | AI7: =IF(Migrationsartikel!AD5="ja","true",FALSE) -> true | AJ7: =IF(Migrationsartikel!AE5="ja","true",FALSE) -> true | AK7: =IF(Migrationsartikel!AF5="ja","Denner Partner","") | AL7: =IF(Migrationsartikel!AG5="ja","true","false") -> false | AM7: =IF(J7<>"","PLU","Kassentastenbelegung (ohne GTIN/PLU)") -> PLU | AN7: true | AO7: S4H
B8: exartikel | E8: 4 - Einzelartikel | F8: ="Warengruppe>>"&Migrationsartikel!V6&">>"&Migrationsartikel!W6&">>"&Migrationsartikel!X6 -> Warengruppe>>Backwaren & Convenience>>Brot und Backwaren>>Backwaren andere | H8: ZHAW - Handelsware ohne Charge | I8: In/Out | J8: =Migrationsartikel!B6 -> 704 | L8: =Migrationsartikel!F6&" "&Migrationsartikel!G6&" "&Migrationsartikel!H6 -> Birewegge aus der Region 1Stk | M8: =Migrationsartikel!J6&" "&Migrationsartikel!K6&" "&Migrationsartikel!L6 -> Birewegge de la région 1pce | N8: =Migrationsartikel!N6&" "&Migrationsartikel!O6&" "&Migrationsartikel!P6 -> Birewegge della regione 1pz | O8: =Migrationsartikel!F6 -> Birewegge | P8: =Migrationsartikel!J6 -> Birewegge | Q8: =Migrationsartikel!N6 -> Birewegge | R8: =Migrationsartikel!G6 -> aus der Region | S8: =Migrationsartikel!K6 -> de la région | T8: =Migrationsartikel!O6 -> della regione | U8: =Migrationsartikel!H6 -> 1Stk | V8: =Migrationsartikel!L6 -> 1pce | W8: =Migrationsartikel!P6 -> 1pz | X8: =Migrationsartikel!I6 -> Birewegge | Y8: =Migrationsartikel!M6 -> Birewegge | Z8: =Migrationsartikel!Q6 -> Birewegge | AA8: =Migrationsartikel!R6 -> 1 | AB8: =Migrationsartikel!T6 -> Stück | AC8: =Migrationsartikel!S6 -> 1 | AD8: =Migrationsartikel!U6 -> (PCE) Stück | AE8: 1 - Normalsatz | AF8: Keine | AG8: =IF(Migrationsartikel!AB6="ja","true",FALSE) -> true | AH8: =IF(Migrationsartikel!AC6="ja","true",FALSE) -> true | AI8: =IF(Migrationsartikel!AD6="ja","true",FALSE) -> true | AJ8: =IF(Migrationsartikel!AE6="ja","true",FALSE) -> true | AK8: =IF(Migrationsartikel!AF6="ja","Denner Partner","") | AL8: =IF(Migrationsartikel!AG6="ja","true","false") -> false | AM8: =IF(J8<>"","PLU","Kassentastenbelegung (ohne GTIN/PLU)") -> PLU | AN8: true | AO8: S4H
B9: exartikel | E9: 5 - Einzelartikel | F9: ="Warengruppe>>"&Migrationsartikel!V7&">>"&Migrationsartikel!W7&">>"&Migrationsartikel!X7 -> Warengruppe>>Backwaren & Convenience>>Brot und Backwaren>>Backwaren andere | H9: ZHAW - Handelsware ohne Charge | I9: In/Out | J9: =Migrationsartikel!B7 -> 705 | L9: =Migrationsartikel!F7&" "&Migrationsartikel!G7&" "&Migrationsartikel!H7 -> Bricelets aus der Region 1Stk | M9: =Migrationsartikel!J7&" "&Migrationsartikel!K7&" "&Migrationsartikel!L7 -> Bricelets de la région 1pce | N9: =Migrationsartikel!N7&" "&Migrationsartikel!O7&" "&Migrationsartikel!P7 -> Bricelets della regione 1pz | O9: =Migrationsartikel!F7 -> Bricelets | P9: =Migrationsartikel!J7 -> Bricelets | Q9: =Migrationsartikel!N7 -> Bricelets | R9: =Migrationsartikel!G7 -> aus der Region | S9: =Migrationsartikel!K7 -> de la région | T9: =Migrationsartikel!O7 -> della regione | U9: =Migrationsartikel!H7 -> 1Stk | V9: =Migrationsartikel!L7 -> 1pce | W9: =Migrationsartikel!P7 -> 1pz | X9: =Migrationsartikel!I7 -> Bricelets | Y9: =Migrationsartikel!M7 -> Bricelets | Z9: =Migrationsartikel!Q7 -> Bricelets | AA9: =Migrationsartikel!R7 -> 1 | AB9: =Migrationsartikel!T7 -> Stück | AC9: =Migrationsartikel!S7 -> 1 | AD9: =Migrationsartikel!U7 -> (PCE) Stück | AE9: 1 - Normalsatz | AF9: Keine | AG9: =IF(Migrationsartikel!AB7="ja","true",FALSE) -> true | AH9: =IF(Migrationsartikel!AC7="ja","true",FALSE) -> true | AI9: =IF(Migrationsartikel!AD7="ja","true",FALSE) -> true | AJ9: =IF(Migrationsartikel!AE7="ja","true",FALSE) -> true | AK9: =IF(Migrationsartikel!AF7="ja","Denner Partner","") | AL9: =IF(Migrationsartikel!AG7="ja","true","false") -> false | AM9: =IF(J9<>"","PLU","Kassentastenbelegung (ohne GTIN/PLU)") -> PLU | AN9: true | AO9: S4H
B10: exartikel | E10: 6 - Einzelartikel | F10: ="Warengruppe>>"&Migrationsartikel!V8&">>"&Migrationsartikel!W8&">>"&Migrationsartikel!X8 -> Warengruppe>>Backwaren & Convenience>>Brot und Backwaren>>Backwaren andere | H10: ZHAW - Handelsware ohne Charge | I10: In/Out | J10: =Migrationsartikel!B8 -> 706 | L10: =Migrationsartikel!F8&" "&Migrationsartikel!G8&" "&Migrationsartikel!H8 -> Brioche mit Füllung aus der Region 1Stk | M10: =Migrationsartikel!J8&" "&Migrationsartikel!K8&" "&Migrationsartikel!L8 -> Brioche fourée de la région 1pce | N10: =Migrationsartikel!N8&" "&Migrationsartikel!O8&" "&Migrationsartikel!P8 -> Brioche ripiena della regione 1pz | O10: =Migrationsartikel!F8 -> Brioche mit Füllung | P10: =Migrationsartikel!J8 -> Brioche fourée | Q10: =Migrationsartikel!N8 -> Brioche ripiena | R10: =Migrationsartikel!G8 -> aus der Region | S10: =Migrationsartikel!K8 -> de la région | T10: =Migrationsartikel!O8 -> della regione | U10: =Migrationsartikel!H8 -> 1Stk | V10: =Migrationsartikel!L8 -> 1pce | W10: =Migrationsartikel!P8 -> 1pz | X10: =Migrationsartikel!I8 -> Brioche mit Füllung | Y10: =Migrationsartikel!M8 -> Brioche fourée | Z10: =Migrationsartikel!Q8 -> Brioche ripiena | AA10: =Migrationsartikel!R8 -> 1 | AB10: =Migrationsartikel!T8 -> Stück | AC10: =Migrationsartikel!S8 -> 1 | AD10: =Migrationsartikel!U8 -> (PCE) Stück | AE10: 1 - Normalsatz | AF10: Keine | AG10: =IF(Migrationsartikel!AB8="ja","true",FALSE) -> true | AH10: =IF(Migrationsartikel!AC8="ja","true",FALSE) -> true | AI10: =IF(Migrationsartikel!AD8="ja","true",FALSE) -> true | AJ10: =IF(Migrationsartikel!AE8="ja","true",FALSE) -> true | AK10: =IF(Migrationsartikel!AF8="ja","Denner Partner","") | AL10: =IF(Migrationsartikel!AG8="ja","true","false") -> false | AM10: =IF(J10<>"","PLU","Kassentastenbelegung (ohne GTIN/PLU)") -> PLU | AN10: true | AO10: S4H
B11: exartikel | E11: 7 - Einzelartikel | F11: ="Warengruppe>>"&Migrationsartikel!V9&">>"&Migrationsartikel!W9&">>"&Migrationsartikel!X9 -> Warengruppe>>Backwaren & Convenience>>Brot und Backwaren>>Backwaren andere | H11: ZHAW - Handelsware ohne Charge | I11: In/Out | J11: =Migrationsartikel!B9 -> 707 | L11: =Migrationsartikel!F9&" "&Migrationsartikel!G9&" "&Migrationsartikel!H9 -> Brot vom Beck aus der Region 1Stk | M11: =Migrationsartikel!J9&" "&Migrationsartikel!K9&" "&Migrationsartikel!L9 -> Pain du boulanger de la région 1pce | N11: =Migrationsartikel!N9&" "&Migrationsartikel!O9&" "&Migrationsartikel!P9 -> Pane del panettiere della regione 1pz | O11: =Migrationsartikel!F9 -> Brot vom Beck | P11: =Migrationsartikel!J9 -> Pain du boulanger | Q11: =Migrationsartikel!N9 -> Pane del panettiere | R11: =Migrationsartikel!G9 -> aus der Region | S11: =Migrationsartikel!K9 -> de la région | T11: =Migrationsartikel!O9 -> della regione | U11: =Migrationsartikel!H9 -> 1Stk | V11: =Migrationsartikel!L9 -> 1pce | W11: =Migrationsartikel!P9 -> 1pz | X11: =Migrationsartikel!I9 -> Brot vom Beck | Y11: =Migrationsartikel!M9 -> Pain du boulanger | Z11: =Migrationsartikel!Q9 -> Pane del panettiere | AA11: =Migrationsartikel!R9 -> 1 | AB11: =Migrationsartikel!T9 -> Stück | AC11: =Migrationsartikel!S9 -> 1 | AD11: =Migrationsartikel!U9 -> (PCE) Stück | AE11: 1 - Normalsatz | AF11: Keine | AG11: =IF(Migrationsartikel!AB9="ja","true",FALSE) -> true | AH11: =IF(Migrationsartikel!AC9="ja","true",FALSE) -> true | AI11: =IF(Migrationsartikel!AD9="ja","true",FALSE) -> true | AJ11: =IF(Migrationsartikel!AE9="ja","true",FALSE) -> true | AK11: =IF(Migrationsartikel!AF9="ja","Denner Partner","") | AL11: =IF(Migrationsartikel!AG9="ja","true","false") -> false | AM11: =IF(J11<>"","PLU","Kassentastenbelegung (ohne GTIN/PLU)") -> PLU | AN11: true | AO11: S4H
B12: exartikel | E12: 8 - Einzelartikel | F12: ="Warengruppe>>"&Migrationsartikel!V10&">>"&Migrationsartikel!W10&">>"&Migrationsartikel!X10 -> Warengruppe>>Backwaren & Convenience>>Brot und Backwaren>>Backwaren andere | H12: ZHAW - Handelsware ohne Charge | I12: In/Out | J12: =Migrationsartikel!B10 -> 708 | L12: =Migrationsartikel!F10&" "&Migrationsartikel!G10&" "&Migrationsartikel!H10 -> Brottheke aus der Region 1Stk | M12: =Migrationsartikel!J10&" "&Migrationsartikel!K10&" "&Migrationsartikel!L10 -> Comptoir à pain de la région 1pce | N12: =Migrationsartikel!N10&" "&Migrationsartikel!O10&" "&Migrationsartikel!P10 -> Banco pane della regione 1pz | O12: =Migrationsartikel!F10 -> Brottheke | P12: =Migrationsartikel!J10 -> Comptoir à pain | Q12: =Migrationsartikel!N10 -> Banco pane | R12: =Migrationsartikel!G10 -> aus der Region | S12: =Migrationsartikel!K10 -> de la région | T12: =Migrationsartikel!O10 -> della regione | U12: =Migrationsartikel!H10 -> 1Stk | V12: =Migrationsartikel!L10 -> 1pce | W12: =Migrationsartikel!P10 -> 1pz | X12: =Migrationsartikel!I10 -> Brottheke | Y12: =Migrationsartikel!M10 -> Comptoir à pain | Z12: =Migrationsartikel!Q10 -> Banco pane | AA12: =Migrationsartikel!R10 -> 1 | AB12: =Migrationsartikel!T10 -> Stück | AC12: =Migrationsartikel!S10 -> 1 | AD12: =Migrationsartikel!U10 -> (PCE) Stück | AE12: 1 - Normalsatz | AF12: Keine | AG12: =IF(Migrationsartikel!AB10="ja","true",FALSE) -> true | AH12: =IF(Migrationsartikel!AC10="ja","true",FALSE) -> true | AI12: =IF(Migrationsartikel!AD10="ja","true",FALSE) -> true | AJ12: =IF(Migrationsartikel!AE10="ja","true",FALSE) -> true | AK12: =IF(Migrationsartikel!AF10="ja","Denner Partner","") | AL12: =IF(Migrationsartikel!AG10="ja","true","false") -> false | AM12: =IF(J12<>"","PLU","Kassentastenbelegung (ohne GTIN/PLU)") -> PLU | AN12: true | AO12: S4H
B13: exartikel | E13: 9 - Einzelartikel | F13: ="Warengruppe>>"&Migrationsartikel!V11&">>"&Migrationsartikel!W11&">>"&Migrationsartikel!X11 -> Warengruppe>>Backwaren & Convenience>>Brot und Backwaren>>Backwaren andere | H13: ZHAW - Handelsware ohne Charge | I13: In/Out | J13: =Migrationsartikel!B11 -> 709 | L13: =Migrationsartikel!F11&" "&Migrationsartikel!G11&" "&Migrationsartikel!H11 -> Bürli aus der Region 1Stk | M13: =Migrationsartikel!J11&" "&Migrationsartikel!K11&" "&Migrationsartikel!L11 -> Bürli de la région 1pce | N13: =Migrationsartikel!N11&" "&Migrationsartikel!O11&" "&Migrationsartikel!P11 -> Bürli della regione 1pz | O13: =Migrationsartikel!F11 -> Bürli | P13: =Migrationsartikel!J11 -> Bürli | Q13: =Migrationsartikel!N11 -> Bürli | R13: =Migrationsartikel!G11 -> aus der Region | S13: =Migrationsartikel!K11 -> de la région | T13: =Migrationsartikel!O11 -> della regione | U13: =Migrationsartikel!H11 -> 1Stk | V13: =Migrationsartikel!L11 -> 1pce | W13: =Migrationsartikel!P11 -> 1pz | X13: =Migrationsartikel!I11 -> Bürli | Y13: =Migrationsartikel!M11 -> Bürli | Z13: =Migrationsartikel!Q11 -> Bürli | AA13: =Migrationsartikel!R11 -> 1 | AB13: =Migrationsartikel!T11 -> Stück | AC13: =Migrationsartikel!S11 -> 1 | AD13: =Migrationsartikel!U11 -> (PCE) Stück | AE13: 1 - Normalsatz | AF13: Keine | AG13: =IF(Migrationsartikel!AB11="ja","true",FALSE) -> true | AH13: =IF(Migrationsartikel!AC11="ja","true",FALSE) -> true | AI13: =IF(Migrationsartikel!AD11="ja","true",FALSE) -> true | AJ13: =IF(Migrationsartikel!AE11="ja","true",FALSE) -> true | AK13: =IF(Migrationsartikel!AF11="ja","Denner Partner","") | AL13: =IF(Migrationsartikel!AG11="ja","true","false") -> false | AM13: =IF(J13<>"","PLU","Kassentastenbelegung (ohne GTIN/PLU)") -> PLU | AN13: true | AO13: S4H
B14: exartikel | E14: 10 - Einzelartikel | F14: ="Warengruppe>>"&Migrationsartikel!V12&">>"&Migrationsartikel!W12&">>"&Migrationsartikel!X12 -> Warengruppe>>Backwaren & Convenience>>Brot und Backwaren>>Backwaren andere | H14: ZHAW - Handelsware ohne Charge | I14: In/Out | J14: =Migrationsartikel!B12 -> 710 | L14: =Migrationsartikel!F12&" "&Migrationsartikel!G12&" "&Migrationsartikel!H12 -> Buttergipfel aus der Region 1Stk | M14: =Migrationsartikel!J12&" "&Migrationsartikel!K12&" "&Migrationsartikel!L12 -> Croissant au beurre de la région 1pce | N14: =Migrationsartikel!N12&" "&Migrationsartikel!O12&" "&Migrationsartikel!P12 -> Cornetto al burro della regione 1pz | O14: =Migrationsartikel!F12 -> Buttergipfel | P14: =Migrationsartikel!J12 -> Croissant au beurre | Q14: =Migrationsartikel!N12 -> Cornetto al burro | R14: =Migrationsartikel!G12 -> aus der Region | S14: =Migrationsartikel!K12 -> de la région | T14: =Migrationsartikel!O12 -> della regione | U14: =Migrationsartikel!H12 -> 1Stk | V14: =Migrationsartikel!L12 -> 1pce | W14: =Migrationsartikel!P12 -> 1pz | X14: =Migrationsartikel!I12 -> Buttergipfel | Y14: =Migrationsartikel!M12 -> Croissant au beurre | Z14: =Migrationsartikel!Q12 -> Cornetto al burro | AA14: =Migrationsartikel!R12 -> 1 | AB14: =Migrationsartikel!T12 -> Stück | AC14: =Migrationsartikel!S12 -> 1 | AD14: =Migrationsartikel!U12 -> (PCE) Stück | AE14: 1 - Normalsatz | AF14: Keine | AG14: =IF(Migrationsartikel!AB12="ja","true",FALSE) -> true | AH14: =IF(Migrationsartikel!AC12="ja","true",FALSE) -> true | AI14: =IF(Migrationsartikel!AD12="ja","true",FALSE) -> true | AJ14: =IF(Migrationsartikel!AE12="ja","true",FALSE) -> true | AK14: =IF(Migrationsartikel!AF12="ja","Denner Partner","") | AL14: =IF(Migrationsartikel!AG12="ja","true","false") -> false | AM14: =IF(J14<>"","PLU","Kassentastenbelegung (ohne GTIN/PLU)") -> PLU | AN14: true | AO14: S4H
B15: exartikel | E15: 11 - Einzelartikel | F15: ="Warengruppe>>"&Migrationsartikel!V13&">>"&Migrationsartikel!W13&">>"&Migrationsartikel!X13 -> Warengruppe>>Backwaren & Convenience>>Brot und Backwaren>>Backwaren andere | H15: ZHAW - Handelsware ohne Charge | I15: In/Out | J15: =Migrationsartikel!B13 -> 711 | L15: =Migrationsartikel!F13&" "&Migrationsartikel!G13&" "&Migrationsartikel!H13 -> Butterzopf aus der Region 300g | M15: =Migrationsartikel!J13&" "&Migrationsartikel!K13&" "&Migrationsartikel!L13 -> Tresse de la région 300g | N15: =Migrationsartikel!N13&" "&Migrationsartikel!O13&" "&Migrationsartikel!P13 -> Treccia della regione 300g | O15: =Migrationsartikel!F13 -> Butterzopf | P15: =Migrationsartikel!J13 -> Tresse | Q15: =Migrationsartikel!N13 -> Treccia | R15: =Migrationsartikel!G13 -> aus der Region | S15: =Migrationsartikel!K13 -> de la région | T15: =Migrationsartikel!O13 -> della regione | U15: =Migrationsartikel!H13 -> 300g | V15: =Migrationsartikel!L13 -> 300g | W15: =Migrationsartikel!P13 -> 300g | X15: =Migrationsartikel!I13 -> Butterzopf 300g | Y15: =Migrationsartikel!M13 -> Tresse 300g | Z15: =Migrationsartikel!Q13 -> Treccia 300g | AA15: =Migrationsartikel!R13 -> 0.3 | AB15: =Migrationsartikel!T13 -> Gramm | AC15: =Migrationsartikel!S13 -> 100 | AD15: =Migrationsartikel!U13 -> (PCE) Stück | AE15: 1 - Normalsatz | AF15: Keine | AG15: =IF(Migrationsartikel!AB13="ja","true",FALSE) -> true | AH15: =IF(Migrationsartikel!AC13="ja","true",FALSE) -> true | AI15: =IF(Migrationsartikel!AD13="ja","true",FALSE) -> true | AJ15: =IF(Migrationsartikel!AE13="ja","true",FALSE) -> true | AK15: =IF(Migrationsartikel!AF13="ja","Denner Partner","") | AL15: =IF(Migrationsartikel!AG13="ja","true","false") -> false | AM15: =IF(J15<>"","PLU","Kassentastenbelegung (ohne GTIN/PLU)") -> PLU | AN15: true | AO15: S4H
... B330: exartikel | E330: 326 - Einzelartikel | F330: ="Warengruppe>>"&Migrationsartikel!V328&">>"&Migrationsartikel!W328&">>"&Migrationsartikel!X328 -> Warengruppe>>>>>> | H330: ZHAW - Handelsware ohne Charge | I330: In/Out | J330: =Migrationsartikel!B328 -> 0 | L330: =Migrationsartikel!F328&" "&Migrationsartikel!G328&" "&Migrationsartikel!H328 | M330: =Migrationsartikel!J328&" "&Migrationsartikel!K328&" "&Migrationsartikel!L328 | N330: =Migrationsartikel!N328&" "&Migrationsartikel!O328&" "&Migrationsartikel!P328 | O330: =Migrationsartikel!F328 -> 0 | P330: =Migrationsartikel!J328 -> 0 | Q330: =Migrationsartikel!N328 -> 0 | R330: =Migrationsartikel!G328 -> 0 | S330: =Migrationsartikel!K328 -> 0 | T330: =Migrationsartikel!O328 -> 0 | U330: =Migrationsartikel!H328 -> 0 | V330: =Migrationsartikel!L328 -> 0 | W330: =Migrationsartikel!P328 -> 0 | X330: =Migrationsartikel!I328 -> 0 | Y330: =Migrationsartikel!M328 -> 0 | Z330: =Migrationsartikel!Q328 -> 0 | AA330: =Migrationsartikel!R328 -> 0 | AB330: =Migrationsartikel!T328 -> 0 | AC330: =Migrationsartikel!S328 -> 0 | AD330: =Migrationsartikel!U328 -> 0 | AE330: 1 - Normalsatz | AF330: Keine | AG330: =IF(Migrationsartikel!AB328="ja","true",FALSE) -> FALSE | AH330: =IF(Migrationsartikel!AC328="ja","true",FALSE) -> FALSE | AI330: =IF(Migrationsartikel!AD328="ja","true",FALSE) -> FALSE | AJ330: =IF(Migrationsartikel!AE328="ja","true",FALSE) -> FALSE | AK330: =IF(Migrationsartikel!AF328="ja","Denner Partner","") | AL330: =IF(Migrationsartikel!AG328="ja","true","false") -> false | AM330: =IF(J330<>"","PLU","Kassentastenbelegung (ohne GTIN/PLU)") -> PLU | AN330: true | AO330: S4H
B331: exartikel | E331: 327 - Einzelartikel | F331: ="Warengruppe>>"&Migrationsartikel!V329&">>"&Migrationsartikel!W329&">>"&Migrationsartikel!X329 -> Warengruppe>>>>>> | H331: ZHAW - Handelsware ohne Charge | I331: In/Out | J331: =Migrationsartikel!B329 -> 0 | O331: =Migrationsartikel!F329 -> 0 | P331: =Migrationsartikel!J329 -> 0 | Q331: =Migrationsartikel!N329 -> 0 | R331: =Migrationsartikel!G329 -> 0 | S331: =Migrationsartikel!K329 -> 0 | T331: =Migrationsartikel!O329 -> 0 | U331: =Migrationsartikel!H329 -> 0 | V331: =Migrationsartikel!L329 -> 0 | W331: =Migrationsartikel!P329 -> 0 | X331: =Migrationsartikel!I329 -> 0 | Y331: =Migrationsartikel!M329 -> 0 | Z331: =Migrationsartikel!Q329 -> 0 | AA331: =Migrationsartikel!R329 -> 0 | AB331: =Migrationsartikel!T329 -> 0 | AC331: =Migrationsartikel!S329 -> 0 | AD331: =Migrationsartikel!U329 -> 0 | AE331: 1 - Normalsatz | AF331: Keine | AG331: =IF(Migrationsartikel!AB329="ja","true",FALSE) -> FALSE | AH331: =IF(Migrationsartikel!AC329="ja","true",FALSE) -> FALSE | AI331: =IF(Migrationsartikel!AD329="ja","true",FALSE) -> FALSE | AJ331: =IF(Migrationsartikel!AE329="ja","true",FALSE) -> FALSE | AK331: =IF(Migrationsartikel!AF329="ja","Denner Partner","") | AL331: =IF(Migrationsartikel!AG329="ja","true","false") -> false | AM331: =IF(J331<>"","PLU","Kassentastenbelegung (ohne GTIN/PLU)") -> PLU | AN331: true | AO331: S4H
B332: exartikel | E332: 328 - Einzelartikel | F332: ="Warengruppe>>"&Migrationsartikel!V330&">>"&Migrationsartikel!W330&">>"&Migrationsartikel!X330 -> Warengruppe>>>>>> | H332: ZHAW - Handelsware ohne Charge | I332: In/Out | J332: =Migrationsartikel!B330 -> 0 | O332: =Migrationsartikel!F330 -> 0 | P332: =Migrationsartikel!J330 -> 0 | Q332: =Migrationsartikel!N330 -> 0 | R332: =Migrationsartikel!G330 -> 0 | S332: =Migrationsartikel!K330 -> 0 | T332: =Migrationsartikel!O330 -> 0 | U332: =Migrationsartikel!H330 -> 0 | V332: =Migrationsartikel!L330 -> 0 | W332: =Migrationsartikel!P330 -> 0 | X332: =Migrationsartikel!I330 -> 0 | Y332: =Migrationsartikel!M330 -> 0 | Z332: =Migrationsartikel!Q330 -> 0 | AA332: =Migrationsartikel!R330 -> 0 | AB332: =Migrationsartikel!T330 -> 0 | AC332: =Migrationsartikel!S330 -> 0 | AD332: =Migrationsartikel!U330 -> 0 | AE332: 1 - Normalsatz | AF332: Keine | AG332: =IF(Migrationsartikel!AB330="ja","true",FALSE) -> FALSE | AH332: =IF(Migrationsartikel!AC330="ja","true",FALSE) -> FALSE | AI332: =IF(Migrationsartikel!AD330="ja","true",FALSE) -> FALSE | AJ332: =IF(Migrationsartikel!AE330="ja","true",FALSE) -> FALSE | AK332: =IF(Migrationsartikel!AF330="ja","Denner Partner","") | AL332: =IF(Migrationsartikel!AG330="ja","true","false") -> false | AM332: =IF(J332<>"","PLU","Kassentastenbelegung (ohne GTIN/PLU)") -> PLU | AN332: true | AO332: S4H
B333: exartikel | E333: 329 - Einzelartikel | F333: ="Warengruppe>>"&Migrationsartikel!V331&">>"&Migrationsartikel!W331&">>"&Migrationsartikel!X331 -> Warengruppe>>>>>> | H333: ZHAW - Handelsware ohne Charge | I333: In/Out | J333: =Migrationsartikel!B331 -> 0 | O333: =Migrationsartikel!F331 -> 0 | P333: =Migrationsartikel!J331 -> 0 | Q333: =Migrationsartikel!N331 -> 0 | R333: =Migrationsartikel!G331 -> 0 | S333: =Migrationsartikel!K331 -> 0 | T333: =Migrationsartikel!O331 -> 0 | U333: =Migrationsartikel!H331 -> 0 | V333: =Migrationsartikel!L331 -> 0 | W333: =Migrationsartikel!P331 -> 0 | X333: =Migrationsartikel!I331 -> 0 | Y333: =Migrationsartikel!M331 -> 0 | Z333: =Migrationsartikel!Q331 -> 0 | AA333: =Migrationsartikel!R331 -> 0 | AB333: =Migrationsartikel!T331 -> 0 | AC333: =Migrationsartikel!S331 -> 0 | AD333: =Migrationsartikel!U331 -> 0 | AE333: 1 - Normalsatz | AF333: Keine | AG333: =IF(Migrationsartikel!AB331="ja","true",FALSE) -> FALSE | AH333: =IF(Migrationsartikel!AC331="ja","true",FALSE) -> FALSE | AI333: =IF(Migrationsartikel!AD331="ja","true",FALSE) -> FALSE | AJ333: =IF(Migrationsartikel!AE331="ja","true",FALSE) -> FALSE | AK333: =IF(Migrationsartikel!AF331="ja","Denner Partner","") | AL333: =IF(Migrationsartikel!AG331="ja","true","false") -> false | AM333: =IF(J333<>"","PLU","Kassentastenbelegung (ohne GTIN/PLU)") -> PLU | AN333: true | AO333: S4H
B334: exartikel | E334: 330 - Einzelartikel | F334: ="Warengruppe>>"&Migrationsartikel!V332&">>"&Migrationsartikel!W332&">>"&Migrationsartikel!X332 -> Warengruppe>>>>>> | H334: ZHAW - Handelsware ohne Charge | I334: In/Out | J334: =Migrationsartikel!B332 -> 0 | O334: =Migrationsartikel!F332 -> 0 | P334: =Migrationsartikel!J332 -> 0 | Q334: =Migrationsartikel!N332 -> 0 | R334: =Migrationsartikel!G332 -> 0 | S334: =Migrationsartikel!K332 -> 0 | T334: =Migrationsartikel!O332 -> 0 | U334: =Migrationsartikel!H332 -> 0 | V334: =Migrationsartikel!L332 -> 0 | W334: =Migrationsartikel!P332 -> 0 | X334: =Migrationsartikel!I332 -> 0 | Y334: =Migrationsartikel!M332 -> 0 | Z334: =Migrationsartikel!Q332 -> 0 | AA334: =Migrationsartikel!R332 -> 0 | AB334: =Migrationsartikel!T332 -> 0 | AC334: =Migrationsartikel!S332 -> 0 | AD334: =Migrationsartikel!U332 -> 0 | AE334: 1 - Normalsatz | AF334: Keine | AG334: =IF(Migrationsartikel!AB332="ja","true",FALSE) -> FALSE | AH334: =IF(Migrationsartikel!AC332="ja","true",FALSE) -> FALSE | AI334: =IF(Migrationsartikel!AD332="ja","true",FALSE) -> FALSE | AJ334: =IF(Migrationsartikel!AE332="ja","true",FALSE) -> FALSE | AK334: =IF(Migrationsartikel!AF332="ja","Denner Partner","") | AL334: =IF(Migrationsartikel!AG332="ja","true","false") -> false | AM334: =IF(J334<>"","PLU","Kassentastenbelegung (ohne GTIN/PLU)") -> PLU | AN334: true | AO334: S4H
B335: exartikel | E335: 331 - Einzelartikel | F335: ="Warengruppe>>"&Migrationsartikel!V333&">>"&Migrationsartikel!W333&">>"&Migrationsartikel!X333 -> Warengruppe>>>>>> | H335: ZHAW - Handelsware ohne Charge | I335: In/Out | J335: =Migrationsartikel!B333 -> 0 | O335: =Migrationsartikel!F333 -> 0 | P335: =Migrationsartikel!J333 -> 0 | Q335: =Migrationsartikel!N333 -> 0 | R335: =Migrationsartikel!G333 -> 0 | S335: =Migrationsartikel!K333 -> 0 | T335: =Migrationsartikel!O333 -> 0 | U335: =Migrationsartikel!H333 -> 0 | V335: =Migrationsartikel!L333 -> 0 | W335: =Migrationsartikel!P333 -> 0 | X335: =Migrationsartikel!I333 -> 0 | Y335: =Migrationsartikel!M333 -> 0 | Z335: =Migrationsartikel!Q333 -> 0 | AA335: =Migrationsartikel!R333 -> 0 | AB335: =Migrationsartikel!T333 -> 0 | AC335: =Migrationsartikel!S333 -> 0 | AD335: =Migrationsartikel!U333 -> 0 | AE335: 1 - Normalsatz | AF335: Keine | AG335: =IF(Migrationsartikel!AB333="ja","true",FALSE) -> FALSE | AH335: =IF(Migrationsartikel!AC333="ja","true",FALSE) -> FALSE | AI335: =IF(Migrationsartikel!AD333="ja","true",FALSE) -> FALSE | AJ335: =IF(Migrationsartikel!AE333="ja","true",FALSE) -> FALSE | AK335: =IF(Migrationsartikel!AF333="ja","Denner Partner","") | AL335: =IF(Migrationsartikel!AG333="ja","true","false") -> false | AM335: =IF(J335<>"","PLU","Kassentastenbelegung (ohne GTIN/PLU)") -> PLU | AN335: true | AO335: S4H
B336: exartikel | E336: 332 - Einzelartikel | F336: ="Warengruppe>>"&Migrationsartikel!V334&">>"&Migrationsartikel!W334&">>"&Migrationsartikel!X334 -> Warengruppe>>>>>> | H336: ZHAW - Handelsware ohne Charge | I336: In/Out | J336: =Migrationsartikel!B334 -> 0 | O336: =Migrationsartikel!F334 -> 0 | P336: =Migrationsartikel!J334 -> 0 | Q336: =Migrationsartikel!N334 -> 0 | R336: =Migrationsartikel!G334 -> 0 | S336: =Migrationsartikel!K334 -> 0 | T336: =Migrationsartikel!O334 -> 0 | U336: =Migrationsartikel!H334 -> 0 | V336: =Migrationsartikel!L334 -> 0 | W336: =Migrationsartikel!P334 -> 0 | X336: =Migrationsartikel!I334 -> 0 | Y336: =Migrationsartikel!M334 -> 0 | Z336: =Migrationsartikel!Q334 -> 0 | AA336: =Migrationsartikel!R334 -> 0 | AB336: =Migrationsartikel!T334 -> 0 | AC336: =Migrationsartikel!S334 -> 0 | AD336: =Migrationsartikel!U334 -> 0 | AE336: 1 - Normalsatz | AF336: Keine | AG336: =IF(Migrationsartikel!AB334="ja","true",FALSE) -> FALSE | AH336: =IF(Migrationsartikel!AC334="ja","true",FALSE) -> FALSE | AI336: =IF(Migrationsartikel!AD334="ja","true",FALSE) -> FALSE | AJ336: =IF(Migrationsartikel!AE334="ja","true",FALSE) -> FALSE | AK336: =IF(Migrationsartikel!AF334="ja","Denner Partner","") | AL336: =IF(Migrationsartikel!AG334="ja","true","false") -> false | AM336: =IF(J336<>"","PLU","Kassentastenbelegung (ohne GTIN/PLU)") -> PLU | AN336: true | AO336: S4H
B337: exartikel | E337: 333 - Einzelartikel | F337: ="Warengruppe>>"&Migrationsartikel!V335&">>"&Migrationsartikel!W335&">>"&Migrationsartikel!X335 -> Warengruppe>>>>>> | H337: ZHAW - Handelsware ohne Charge | I337: In/Out | J337: =Migrationsartikel!B335 -> 0 | O337: =Migrationsartikel!F335 -> 0 | P337: =Migrationsartikel!J335 -> 0 | Q337: =Migrationsartikel!N335 -> 0 | R337: =Migrationsartikel!G335 -> 0 | S337: =Migrationsartikel!K335 -> 0 | T337: =Migrationsartikel!O335 -> 0 | U337: =Migrationsartikel!H335 -> 0 | V337: =Migrationsartikel!L335 -> 0 | W337: =Migrationsartikel!P335 -> 0 | X337: =Migrationsartikel!I335 -> 0 | Y337: =Migrationsartikel!M335 -> 0 | Z337: =Migrationsartikel!Q335 -> 0 | AA337: =Migrationsartikel!R335 -> 0 | AB337: =Migrationsartikel!T335 -> 0 | AC337: =Migrationsartikel!S335 -> 0 | AD337: =Migrationsartikel!U335 -> 0 | AE337: 1 - Normalsatz | AF337: Keine | AG337: =IF(Migrationsartikel!AB335="ja","true",FALSE) -> FALSE | AH337: =IF(Migrationsartikel!AC335="ja","true",FALSE) -> FALSE | AI337: =IF(Migrationsartikel!AD335="ja","true",FALSE) -> FALSE | AJ337: =IF(Migrationsartikel!AE335="ja","true",FALSE) -> FALSE | AK337: =IF(Migrationsartikel!AF335="ja","Denner Partner","") | AL337: =IF(Migrationsartikel!AG335="ja","true","false") -> false | AM337: =IF(J337<>"","PLU","Kassentastenbelegung (ohne GTIN/PLU)") -> PLU | AN337: true | AO337: S4H
B338: exartikel | E338: 334 - Einzelartikel | F338: ="Warengruppe>>"&Migrationsartikel!V336&">>"&Migrationsartikel!W336&">>"&Migrationsartikel!X336 -> Warengruppe>>>>>> | H338: ZHAW - Handelsware ohne Charge | I338: In/Out | J338: =Migrationsartikel!B336 -> 0 | O338: =Migrationsartikel!F336 -> 0 | P338: =Migrationsartikel!J336 -> 0 | Q338: =Migrationsartikel!N336 -> 0 | R338: =Migrationsartikel!G336 -> 0 | S338: =Migrationsartikel!K336 -> 0 | T338: =Migrationsartikel!O336 -> 0 | U338: =Migrationsartikel!H336 -> 0 | V338: =Migrationsartikel!L336 -> 0 | W338: =Migrationsartikel!P336 -> 0 | X338: =Migrationsartikel!I336 -> 0 | Y338: =Migrationsartikel!M336 -> 0 | Z338: =Migrationsartikel!Q336 -> 0 | AA338: =Migrationsartikel!R336 -> 0 | AB338: =Migrationsartikel!T336 -> 0 | AC338: =Migrationsartikel!S336 -> 0 | AD338: =Migrationsartikel!U336 -> 0 | AE338: 1 - Normalsatz | AF338: Keine | AG338: =IF(Migrationsartikel!AB336="ja","true",FALSE) -> FALSE | AH338: =IF(Migrationsartikel!AC336="ja","true",FALSE) -> FALSE | AI338: =IF(Migrationsartikel!AD336="ja","true",FALSE) -> FALSE | AJ338: =IF(Migrationsartikel!AE336="ja","true",FALSE) -> FALSE | AK338: =IF(Migrationsartikel!AF336="ja","Denner Partner","") | AL338: =IF(Migrationsartikel!AG336="ja","true","false") -> false | AM338: =IF(J338<>"","PLU","Kassentastenbelegung (ohne GTIN/PLU)") -> PLU | AN338: true | AO338: S4H
B339: exartikel | E339: 335 - Einzelartikel | F339: ="Warengruppe>>"&Migrationsartikel!V337&">>"&Migrationsartikel!W337&">>"&Migrationsartikel!X337 -> Warengruppe>>>>>> | H339: ZHAW - Handelsware ohne Charge | I339: In/Out | J339: =Migrationsartikel!B337 -> 0 | O339: =Migrationsartikel!F337 -> 0 | P339: =Migrationsartikel!J337 -> 0 | Q339: =Migrationsartikel!N337 -> 0 | R339: =Migrationsartikel!G337 -> 0 | S339: =Migrationsartikel!K337 -> 0 | T339: =Migrationsartikel!O337 -> 0 | U339: =Migrationsartikel!H337 -> 0 | V339: =Migrationsartikel!L337 -> 0 | W339: =Migrationsartikel!P337 -> 0 | X339: =Migrationsartikel!I337 -> 0 | Y339: =Migrationsartikel!M337 -> 0 | Z339: =Migrationsartikel!Q337 -> 0 | AA339: =Migrationsartikel!R337 -> 0 | AB339: =Migrationsartikel!T337 -> 0 | AC339: =Migrationsartikel!S337 -> 0 | AD339: =Migrationsartikel!U337 -> 0 | AE339: 1 - Normalsatz | AF339: Keine | AG339: =IF(Migrationsartikel!AB337="ja","true",FALSE) -> FALSE | AH339: =IF(Migrationsartikel!AC337="ja","true",FALSE) -> FALSE | AI339: =IF(Migrationsartikel!AD337="ja","true",FALSE) -> FALSE | AJ339: =IF(Migrationsartikel!AE337="ja","true",FALSE) -> FALSE | AK339: =IF(Migrationsartikel!AF337="ja","Denner Partner","") | AL339: =IF(Migrationsartikel!AG337="ja","true","false") -> false | AM339: =IF(J339<>"","PLU","Kassentastenbelegung (ohne GTIN/PLU)") -> PLU | AN339: true | AO339: S4H
B340: exartikel | E340: 336 - Einzelartikel | F340: ="Warengruppe>>"&Migrationsartikel!V338&">>"&Migrationsartikel!W338&">>"&Migrationsartikel!X338 -> Warengruppe>>>>>> | H340: ZHAW - Handelsware ohne Charge | I340: In/Out | J340: =Migrationsartikel!B338 -> 0 | O340: =Migrationsartikel!F338 -> 0 | P340: =Migrationsartikel!J338 -> 0 | Q340: =Migrationsartikel!N338 -> 0 | R340: =Migrationsartikel!G338 -> 0 | S340: =Migrationsartikel!K338 -> 0 | T340: =Migrationsartikel!O338 -> 0 | U340: =Migrationsartikel!H338 -> 0 | V340: =Migrationsartikel!L338 -> 0 | W340: =Migrationsartikel!P338 -> 0 | X340: =Migrationsartikel!I338 -> 0 | Y340: =Migrationsartikel!M338 -> 0 | Z340: =Migrationsartikel!Q338 -> 0 | AA340: =Migrationsartikel!R338 -> 0 | AB340: =Migrationsartikel!T338 -> 0 | AC340: =Migrationsartikel!S338 -> 0 | AD340: =Migrationsartikel!U338 -> 0 | AE340: 1 - Normalsatz | AF340: Keine | AG340: =IF(Migrationsartikel!AB338="ja","true",FALSE) -> FALSE | AH340: =IF(Migrationsartikel!AC338="ja","true",FALSE) -> FALSE | AI340: =IF(Migrationsartikel!AD338="ja","true",FALSE) -> FALSE | AJ340: =IF(Migrationsartikel!AE338="ja","true",FALSE) -> FALSE | AK340: =IF(Migrationsartikel!AF338="ja","Denner Partner","") | AL340: =IF(Migrationsartikel!AG338="ja","true","false") -> false | AM340: =IF(J340<>"","PLU","Kassentastenbelegung (ohne GTIN/PLU)") -> PLU | AN340: true | AO340: S4H
B341: exartikel | E341: 337 - Einzelartikel | F341: ="Warengruppe>>"&Migrationsartikel!V339&">>"&Migrationsartikel!W339&">>"&Migrationsartikel!X339 -> Warengruppe>>>>>> | H341: ZHAW - Handelsware ohne Charge | I341: In/Out | J341: =Migrationsartikel!B339 -> 0 | O341: =Migrationsartikel!F339 -> 0 | P341: =Migrationsartikel!J339 -> 0 | Q341: =Migrationsartikel!N339 -> 0 | R341: =Migrationsartikel!G339 -> 0 | S341: =Migrationsartikel!K339 -> 0 | T341: =Migrationsartikel!O339 -> 0 | U341: =Migrationsartikel!H339 -> 0 | V341: =Migrationsartikel!L339 -> 0 | W341: =Migrationsartikel!P339 -> 0 | X341: =Migrationsartikel!I339 -> 0 | Y341: =Migrationsartikel!M339 -> 0 | Z341: =Migrationsartikel!Q339 -> 0 | AA341: =Migrationsartikel!R339 -> 0 | AB341: =Migrationsartikel!T339 -> 0 | AC341: =Migrationsartikel!S339 -> 0 | AD341: =Migrationsartikel!U339 -> 0 | AE341: 1 - Normalsatz | AF341: Keine | AG341: =IF(Migrationsartikel!AB339="ja","true",FALSE) -> FALSE | AH341: =IF(Migrationsartikel!AC339="ja","true",FALSE) -> FALSE | AI341: =IF(Migrationsartikel!AD339="ja","true",FALSE) -> FALSE | AJ341: =IF(Migrationsartikel!AE339="ja","true",FALSE) -> FALSE | AK341: =IF(Migrationsartikel!AF339="ja","Denner Partner","") | AL341: =IF(Migrationsartikel!AG339="ja","true","false") -> false | AM341: =IF(J341<>"","PLU","Kassentastenbelegung (ohne GTIN/PLU)") -> PLU | AN341: true | AO341: S4H
B342: exartikel | E342: 338 - Einzelartikel | F342: ="Warengruppe>>"&Migrationsartikel!V340&">>"&Migrationsartikel!W340&">>"&Migrationsartikel!X340 -> Warengruppe>>>>>> | H342: ZHAW - Handelsware ohne Charge | I342: In/Out | J342: =Migrationsartikel!B340 -> 0 | O342: =Migrationsartikel!F340 -> 0 | P342: =Migrationsartikel!J340 -> 0 | Q342: =Migrationsartikel!N340 -> 0 | R342: =Migrationsartikel!G340 -> 0 | S342: =Migrationsartikel!K340 -> 0 | T342: =Migrationsartikel!O340 -> 0 | U342: =Migrationsartikel!H340 -> 0 | V342: =Migrationsartikel!L340 -> 0 | W342: =Migrationsartikel!P340 -> 0 | X342: =Migrationsartikel!I340 -> 0 | Y342: =Migrationsartikel!M340 -> 0 | Z342: =Migrationsartikel!Q340 -> 0 | AA342: =Migrationsartikel!R340 -> 0 | AB342: =Migrationsartikel!T340 -> 0 | AC342: =Migrationsartikel!S340 -> 0 | AD342: =Migrationsartikel!U340 -> 0 | AE342: 1 - Normalsatz | AF342: Keine | AG342: =IF(Migrationsartikel!AB340="ja","true",FALSE) -> FALSE | AH342: =IF(Migrationsartikel!AC340="ja","true",FALSE) -> FALSE | AI342: =IF(Migrationsartikel!AD340="ja","true",FALSE) -> FALSE | AJ342: =IF(Migrationsartikel!AE340="ja","true",FALSE) -> FALSE | AK342: =IF(Migrationsartikel!AF340="ja","Denner Partner","") | AL342: =IF(Migrationsartikel!AG340="ja","true","false") -> false | AM342: =IF(J342<>"","PLU","Kassentastenbelegung (ohne GTIN/PLU)") -> PLU | AN342: true | AO342: S4H
... B488: exartikel | E488: 484 - Einzelartikel | F488: ="Warengruppe>>"&Migrationsartikel!V486&">>"&Migrationsartikel!W486&">>"&Migrationsartikel!X486 -> Warengruppe>>>>>> | H488: ZHAW - Handelsware ohne Charge | I488: In/Out | J488: =Migrationsartikel!B486 -> 0 | O488: =Migrationsartikel!F486 -> 0 | P488: =Migrationsartikel!J486 -> 0 | Q488: =Migrationsartikel!N486 -> 0 | R488: =Migrationsartikel!G486 -> 0 | S488: =Migrationsartikel!K486 -> 0 | T488: =Migrationsartikel!O486 -> 0 | U488: =Migrationsartikel!H486 -> 0 | V488: =Migrationsartikel!L486 -> 0 | W488: =Migrationsartikel!P486 -> 0 | X488: =Migrationsartikel!I486 -> 0 | Y488: =Migrationsartikel!M486 -> 0 | Z488: =Migrationsartikel!Q486 -> 0 | AA488: =Migrationsartikel!R486 -> 0 | AB488: =Migrationsartikel!T486 -> 0 | AC488: =Migrationsartikel!S486 -> 0 | AD488: =Migrationsartikel!U486 -> 0 | AE488: 1 - Normalsatz | AF488: Keine | AG488: =IF(Migrationsartikel!AB486="ja","true",FALSE) -> FALSE | AH488: =IF(Migrationsartikel!AC486="ja","true",FALSE) -> FALSE | AI488: =IF(Migrationsartikel!AD486="ja","true",FALSE) -> FALSE | AJ488: =IF(Migrationsartikel!AE486="ja","true",FALSE) -> FALSE | AK488: =IF(Migrationsartikel!AF486="ja","Denner Partner","") | AL488: =IF(Migrationsartikel!AG486="ja","true","false") -> false | AM488: =IF(J488<>"","PLU","Kassentastenbelegung (ohne GTIN/PLU)") -> PLU | AN488: true | AO488: S4H
B489: exartikel | E489: 485 - Einzelartikel | F489: ="Warengruppe>>"&Migrationsartikel!V487&">>"&Migrationsartikel!W487&">>"&Migrationsartikel!X487 -> Warengruppe>>>>>> | H489: ZHAW - Handelsware ohne Charge | I489: In/Out | O489: =Migrationsartikel!F487 -> 0 | P489: =Migrationsartikel!J487 -> 0 | Q489: =Migrationsartikel!N487 -> 0 | R489: =Migrationsartikel!G487 -> 0 | S489: =Migrationsartikel!K487 -> 0 | T489: =Migrationsartikel!O487 -> 0 | U489: =Migrationsartikel!H487 -> 0 | V489: =Migrationsartikel!L487 -> 0 | W489: =Migrationsartikel!P487 -> 0 | X489: =Migrationsartikel!I487 -> 0 | Y489: =Migrationsartikel!M487 -> 0 | Z489: =Migrationsartikel!Q487 -> 0 | AA489: =Migrationsartikel!R487 -> 0 | AB489: =Migrationsartikel!T487 -> 0 | AC489: =Migrationsartikel!S487 -> 0 | AD489: =Migrationsartikel!U487 -> 0 | AE489: 1 - Normalsatz | AF489: Keine | AG489: =IF(Migrationsartikel!AB487="ja","true",FALSE) -> FALSE | AH489: =IF(Migrationsartikel!AC487="ja","true",FALSE) -> FALSE | AI489: =IF(Migrationsartikel!AD487="ja","true",FALSE) -> FALSE | AJ489: =IF(Migrationsartikel!AE487="ja","true",FALSE) -> FALSE | AK489: =IF(Migrationsartikel!AF487="ja","Denner Partner","") | AL489: =IF(Migrationsartikel!AG487="ja","true","false") -> false | AM489: =IF(J489<>"","PLU","Kassentastenbelegung (ohne GTIN/PLU)") -> Kassentastenbelegung (ohne GTIN/PLU) | AN489: true | AO489: S4H
B490: exartikel | E490: 486 - Einzelartikel | F490: ="Warengruppe>>"&Migrationsartikel!V488&">>"&Migrationsartikel!W488&">>"&Migrationsartikel!X488 -> Warengruppe>>>>>> | H490: ZHAW - Handelsware ohne Charge | I490: In/Out | O490: =Migrationsartikel!F488 -> 0 | P490: =Migrationsartikel!J488 -> 0 | Q490: =Migrationsartikel!N488 -> 0 | R490: =Migrationsartikel!G488 -> 0 | S490: =Migrationsartikel!K488 -> 0 | T490: =Migrationsartikel!O488 -> 0 | U490: =Migrationsartikel!H488 -> 0 | V490: =Migrationsartikel!L488 -> 0 | W490: =Migrationsartikel!P488 -> 0 | X490: =Migrationsartikel!I488 -> 0 | Y490: =Migrationsartikel!M488 -> 0 | Z490: =Migrationsartikel!Q488 -> 0 | AA490: =Migrationsartikel!R488 -> 0 | AB490: =Migrationsartikel!T488 -> 0 | AC490: =Migrationsartikel!S488 -> 0 | AD490: =Migrationsartikel!U488 -> 0 | AE490: 1 - Normalsatz | AF490: Keine | AG490: =IF(Migrationsartikel!AB488="ja","true",FALSE) -> FALSE | AH490: =IF(Migrationsartikel!AC488="ja","true",FALSE) -> FALSE | AI490: =IF(Migrationsartikel!AD488="ja","true",FALSE) -> FALSE | AJ490: =IF(Migrationsartikel!AE488="ja","true",FALSE) -> FALSE | AK490: =IF(Migrationsartikel!AF488="ja","Denner Partner","") | AL490: =IF(Migrationsartikel!AG488="ja","true","false") -> false | AM490: =IF(J490<>"","PLU","Kassentastenbelegung (ohne GTIN/PLU)") -> Kassentastenbelegung (ohne GTIN/PLU) | AN490: true | AO490: S4H
B491: exartikel | E491: 487 - Einzelartikel | F491: ="Warengruppe>>"&Migrationsartikel!V489&">>"&Migrationsartikel!W489&">>"&Migrationsartikel!X489 -> Warengruppe>>>>>> | H491: ZHAW - Handelsware ohne Charge | I491: In/Out | O491: =Migrationsartikel!F489 -> 0 | P491: =Migrationsartikel!J489 -> 0 | Q491: =Migrationsartikel!N489 -> 0 | R491: =Migrationsartikel!G489 -> 0 | S491: =Migrationsartikel!K489 -> 0 | T491: =Migrationsartikel!O489 -> 0 | U491: =Migrationsartikel!H489 -> 0 | V491: =Migrationsartikel!L489 -> 0 | W491: =Migrationsartikel!P489 -> 0 | X491: =Migrationsartikel!I489 -> 0 | Y491: =Migrationsartikel!M489 -> 0 | Z491: =Migrationsartikel!Q489 -> 0 | AA491: =Migrationsartikel!R489 -> 0 | AB491: =Migrationsartikel!T489 -> 0 | AC491: =Migrationsartikel!S489 -> 0 | AD491: =Migrationsartikel!U489 -> 0 | AE491: 1 - Normalsatz | AF491: Keine | AG491: =IF(Migrationsartikel!AB489="ja","true",FALSE) -> FALSE | AH491: =IF(Migrationsartikel!AC489="ja","true",FALSE) -> FALSE | AI491: =IF(Migrationsartikel!AD489="ja","true",FALSE) -> FALSE | AJ491: =IF(Migrationsartikel!AE489="ja","true",FALSE) -> FALSE | AK491: =IF(Migrationsartikel!AF489="ja","Denner Partner","") | AL491: =IF(Migrationsartikel!AG489="ja","true","false") -> false | AM491: =IF(J491<>"","PLU","Kassentastenbelegung (ohne GTIN/PLU)") -> Kassentastenbelegung (ohne GTIN/PLU) | AN491: true | AO491: S4H
B492: exartikel | E492: 488 - Einzelartikel | F492: ="Warengruppe>>"&Migrationsartikel!V490&">>"&Migrationsartikel!W490&">>"&Migrationsartikel!X490 -> Warengruppe>>>>>> | H492: ZHAW - Handelsware ohne Charge | I492: In/Out | O492: =Migrationsartikel!F490 -> 0 | P492: =Migrationsartikel!J490 -> 0 | Q492: =Migrationsartikel!N490 -> 0 | R492: =Migrationsartikel!G490 -> 0 | S492: =Migrationsartikel!K490 -> 0 | T492: =Migrationsartikel!O490 -> 0 | U492: =Migrationsartikel!H490 -> 0 | V492: =Migrationsartikel!L490 -> 0 | W492: =Migrationsartikel!P490 -> 0 | X492: =Migrationsartikel!I490 -> 0 | Y492: =Migrationsartikel!M490 -> 0 | Z492: =Migrationsartikel!Q490 -> 0 | AA492: =Migrationsartikel!R490 -> 0 | AB492: =Migrationsartikel!T490 -> 0 | AC492: =Migrationsartikel!S490 -> 0 | AD492: =Migrationsartikel!U490 -> 0 | AE492: 1 - Normalsatz | AF492: Keine | AG492: =IF(Migrationsartikel!AB490="ja","true",FALSE) -> FALSE | AH492: =IF(Migrationsartikel!AC490="ja","true",FALSE) -> FALSE | AI492: =IF(Migrationsartikel!AD490="ja","true",FALSE) -> FALSE | AJ492: =IF(Migrationsartikel!AE490="ja","true",FALSE) -> FALSE | AK492: =IF(Migrationsartikel!AF490="ja","Denner Partner","") | AL492: =IF(Migrationsartikel!AG490="ja","true","false") -> false | AM492: =IF(J492<>"","PLU","Kassentastenbelegung (ohne GTIN/PLU)") -> Kassentastenbelegung (ohne GTIN/PLU) | AN492: true | AO492: S4H
B493: exartikel | E493: 489 - Einzelartikel | F493: ="Warengruppe>>"&Migrationsartikel!V491&">>"&Migrationsartikel!W491&">>"&Migrationsartikel!X491 -> Warengruppe>>>>>> | H493: ZHAW - Handelsware ohne Charge | I493: In/Out | O493: =Migrationsartikel!F491 -> 0 | P493: =Migrationsartikel!J491 -> 0 | Q493: =Migrationsartikel!N491 -> 0 | R493: =Migrationsartikel!G491 -> 0 | S493: =Migrationsartikel!K491 -> 0 | T493: =Migrationsartikel!O491 -> 0 | U493: =Migrationsartikel!H491 -> 0 | V493: =Migrationsartikel!L491 -> 0 | W493: =Migrationsartikel!P491 -> 0 | X493: =Migrationsartikel!I491 -> 0 | Y493: =Migrationsartikel!M491 -> 0 | Z493: =Migrationsartikel!Q491 -> 0 | AA493: =Migrationsartikel!R491 -> 0 | AB493: =Migrationsartikel!T491 -> 0 | AC493: =Migrationsartikel!S491 -> 0 | AD493: =Migrationsartikel!U491 -> 0 | AE493: 1 - Normalsatz | AF493: Keine | AG493: =IF(Migrationsartikel!AB491="ja","true",FALSE) -> FALSE | AH493: =IF(Migrationsartikel!AC491="ja","true",FALSE) -> FALSE | AI493: =IF(Migrationsartikel!AD491="ja","true",FALSE) -> FALSE | AJ493: =IF(Migrationsartikel!AE491="ja","true",FALSE) -> FALSE | AK493: =IF(Migrationsartikel!AF491="ja","Denner Partner","") | AL493: =IF(Migrationsartikel!AG491="ja","true","false") -> false | AM493: =IF(J493<>"","PLU","Kassentastenbelegung (ohne GTIN/PLU)") -> Kassentastenbelegung (ohne GTIN/PLU) | AN493: true | AO493: S4H
B494: exartikel | E494: 490 - Einzelartikel | F494: ="Warengruppe>>"&Migrationsartikel!V492&">>"&Migrationsartikel!W492&">>"&Migrationsartikel!X492 -> Warengruppe>>>>>> | H494: ZHAW - Handelsware ohne Charge | I494: In/Out | O494: =Migrationsartikel!F492 -> 0 | P494: =Migrationsartikel!J492 -> 0 | Q494: =Migrationsartikel!N492 -> 0 | R494: =Migrationsartikel!G492 -> 0 | S494: =Migrationsartikel!K492 -> 0 | T494: =Migrationsartikel!O492 -> 0 | U494: =Migrationsartikel!H492 -> 0 | V494: =Migrationsartikel!L492 -> 0 | W494: =Migrationsartikel!P492 -> 0 | X494: =Migrationsartikel!I492 -> 0 | Y494: =Migrationsartikel!M492 -> 0 | Z494: =Migrationsartikel!Q492 -> 0 | AA494: =Migrationsartikel!R492 -> 0 | AB494: =Migrationsartikel!T492 -> 0 | AC494: =Migrationsartikel!S492 -> 0 | AD494: =Migrationsartikel!U492 -> 0 | AE494: 1 - Normalsatz | AF494: Keine | AG494: =IF(Migrationsartikel!AB492="ja","true",FALSE) -> FALSE | AH494: =IF(Migrationsartikel!AC492="ja","true",FALSE) -> FALSE | AI494: =IF(Migrationsartikel!AD492="ja","true",FALSE) -> FALSE | AJ494: =IF(Migrationsartikel!AE492="ja","true",FALSE) -> FALSE | AK494: =IF(Migrationsartikel!AF492="ja","Denner Partner","") | AL494: =IF(Migrationsartikel!AG492="ja","true","false") -> false | AM494: =IF(J494<>"","PLU","Kassentastenbelegung (ohne GTIN/PLU)") -> Kassentastenbelegung (ohne GTIN/PLU) | AN494: true | AO494: S4H

Sheet Migrationsartikel
A1: Lf Nr. | B1: PLU-Nr. neu | C1: Stk / kg | D1: PAZ | E1: EAN | F1: Gestellbeschriftung 1 Max. 22 Zeichen (d) | G1: Gestellbeschriftung 2 Max. 22 Zeichen (d) | H1: Gestellbeschriftung 3 Max. 4-8 Zeichen (d) | I1: Kassenbontext Max. 28 Zeichen (d) | J1: Gestellbeschriftung 1 Max. 22 Zeichen (f) | K1: Gestellbeschriftung 2 Max. 22 Zeichen (f) | L1: Gestellbeschriftung 3 Max. 4-8 Zeichen (f) | M1: Kassenbontext Max. 28 Zeichen (f) | N1: Gestellbeschriftung 1 Max. 22 Zeichen (i) | O1: Gestellbeschriftung 2 Max. 22 Zeichen (i) | P1: Gestellbeschriftung 3 Max. 4-8 Zeichen (i) | Q1: Kassenbontext Max. 28 Zeichen (i) | R1: Nettoinhalt | S1: Grundpreismenge Feld 1 | T1: Grundpreismenge Feld 2 | U1: Basismengeneinheit Waage = Kg Verkauf = Stk = Stk Relevant für Berechnungen im MDM/SAP | V1: Warengruppe 1. Feld | W1: Warengruppe 2. Feld | X1: Warengruppe 3. Feld | Y1: Steuerklassifikation | Z1: Altersbegrenzung | AA1: Depot | AB1: Rabatt zugelassen | AC1: Rückgabe zugelassen | AD1: Preisänderung zugelassen | AE1: Etiketten-druck | AF1: Shop-in-Shop | AG1: Fremdartikel | AH1: Qualitätsanforderung geprüft | AI1: Verkaufskonditionen | AJ1: Lieferant
A2: 1 | B2: 700 | C2: Stk | D2: Nein | F2: Baguette | G2: aus der Region | H2: 250g | I2: Baguette 250g | J2: Baguette | K2: de la région | L2: 250g | M2: Baguette 250g | N2: Baguette | O2: della regione | P2: 250g | Q2: Baguette 250g | R2: 0.25 | S2: 100 | T2: Gramm | U2: (PCE) Stück | V2: Backwaren & Convenience | W2: Brot und Backwaren | X2: Backwaren andere | AB2: ja | AC2: ja | AD2: ja | AE2: ja | AF2: - | AG2: - | AH2: ja | AI2: 0.05 | AJ2: -
A3: 2 | B3: 701 | C3: Stk | D3: Nein | F3: Baslerbrot | G3: aus der Region | H3: 250g | I3: Baslerbrot 250g | J3: Pain bâlois | K3: de la région | L3: 250g | M3: Pain bâlois 250g | N3: Pane di Basilea | O3: della regione | P3: 250g | Q3: Pane di Basilea 250g | R3: 0.25 | S3: 100 | T3: Gramm | U3: (PCE) Stück | V3: Backwaren & Convenience | W3: Brot und Backwaren | X3: Backwaren andere | AB3: ja | AC3: ja | AD3: ja | AE3: ja | AF3: - | AG3: - | AH3: ja | AI3: 0.05 | AJ3: -
A4: 3 | B4: 702 | C4: Stk | D4: Nein | F4: Baslerbrot | G4: aus der Region | H4: 500g | I4: Baslerbrot 500g | J4: Pain bâlois | K4: de la région | L4: 500g | M4: Pain bâlois 500g | N4: Pane di Basilea | O4: della regione | P4: 500g | Q4: Pane di Basilea 500g | R4: 0.5 | S4: 100 | T4: Gramm | U4: (PCE) Stück | V4: Backwaren & Convenience | W4: Brot und Backwaren | X4: Backwaren andere | AB4: ja | AC4: ja | AD4: ja | AE4: ja | AF4: - | AG4: - | AH4: ja | AI4: 0.05 | AJ4: -
A5: 4 | B5: 703 | C5: Stk | D5: Nein | F5: Berliner | G5: aus der Region | H5: 1Stk | I5: Berliner | J5: Boule de Berlin | K5: de la région | L5: 1pce | M5: Boule de Berlin | N5: Berliner | O5: della regione | P5: 1pz | Q5: Berliner | R5: 1 | S5: 1 | T5: Stück | U5: (PCE) Stück | V5: Backwaren & Convenience | W5: Brot und Backwaren | X5: Backwaren andere | AB5: ja | AC5: ja | AD5: ja | AE5: ja | AF5: - | AG5: - | AH5: ja | AI5: 0.05 | AJ5: -
A6: 5 | B6: 704 | C6: Stk | D6: Nein | F6: Birewegge | G6: aus der Region | H6: 1Stk | I6: Birewegge | J6: Birewegge | K6: de la région | L6: 1pce | M6: Birewegge | N6: Birewegge | O6: della regione | P6: 1pz | Q6: Birewegge | R6: 1 | S6: 1 | T6: Stück | U6: (PCE) Stück | V6: Backwaren & Convenience | W6: Brot und Backwaren | X6: Backwaren andere | AB6: ja | AC6: ja | AD6: ja | AE6: ja | AF6: - | AG6: - | AH6: ja | AI6: 0.05 | AJ6: -
A7: 6 | B7: 705 | C7: Stk | D7: Nein | F7: Bricelets | G7: aus der Region | H7: 1Stk | I7: Bricelets | J7: Bricelets | K7: de la région | L7: 1pce | M7: Bricelets | N7: Bricelets | O7: della regione | P7: 1pz | Q7: Bricelets | R7: 1 | S7: 1 | T7: Stück | U7: (PCE) Stück | V7: Backwaren & Convenience | W7: Brot und Backwaren | X7: Backwaren andere | AB7: ja | AC7: ja | AD7: ja | AE7: ja | AF7: - | AG7: - | AH7: ja | AI7: 0.05 | AJ7: -
A8: 7 | B8: 706 | C8: Stk | D8: Nein | F8: Brioche mit Füllung | G8: aus der Region | H8: 1Stk | I8: Brioche mit Füllung | J8: Brioche fourée | K8: de la région | L8: 1pce | M8: Brioche fourée | N8: Brioche ripiena | O8: della regione | P8: 1pz | Q8: Brioche ripiena | R8: 1 | S8: 1 | T8: Stück | U8: (PCE) Stück | V8: Backwaren & Convenience | W8: Brot und Backwaren | X8: Backwaren andere | AB8: ja | AC8: ja | AD8: ja | AE8: ja | AF8: - | AG8: - | AH8: ja | AI8: 0 | AJ8: -
