Workbook
Name EntitiesCol: Entities!$SRI$2
Name EntitiesRow: Entities!$A$999454
Name RelationshipsCol: [1]Relationships!$SSS$2
Name RelationshipsRow: [1]Relationships!$A$1000000
Name RSC__refxartikeltypsap: 'Reference Data'!$T$2:$T$5
Name RSC__refxbooleanalkoholhaltig: 'Reference Data'!$U$2:$U$5
Name RSC__refxboolen: 'Reference Data'!$V$2:$V$5
Name RSC__refxgtintyperegioartikel: 'Reference Data'!$AP$2:$AP$5
Name RSC__refxshopinshop: 'Reference Data'!$AO$2:$AO$5
Name RSC__refxsystemsap: 'Reference Data'!$AQ$2:$AQ$5
Name RSC_atxalkoholhaltig__de_DE: 'Reference Data'!$M$2:$M$2
Name RSC_atxalkoholhaltig__fr_FR: 'Reference Data'!$L$2:$L$2
Name RSC_atxalkoholhaltig__it_IT: 'Reference Data'!$G$2:$G$2
Name RSC_atxwarengruppesap__de_DE: 'Reference Data'!$B$2:$B$2
Name RSC_atxwarengruppesap__fr_FR: 'Reference Data'!$E$2:$E$2
Name RSC_atxwarengruppesap__it_IT: 'Reference Data'!$O$2:$O$2
Name RSC_axartikelslpmstruktur__de_DE: 'Reference Data'!$C$2:$C$2
Name RSC_axartikelslpmstruktur__fr_FR: 'Reference Data'!$H$2:$H$2
Name RSC_axartikelslpmstruktur__it_IT: 'Reference Data'!$A$2:$A$2
Name RSC_axartikeltypsap__de_DE: 'Reference Data'!$J$2:$J$2
Name RSC_axartikeltypsap__fr_FR: 'Reference Data'!$I$2:$I$2
Name RSC_axartikeltypsap__it_IT: 'Reference Data'!$P$2:$P$2
Name RSC_axmhdvorhanden__de_DE: 'Reference Data'!$N$2:$N$2
Name RSC_axmhdvorhanden__fr_FR: 'Reference Data'!$Q$2:$Q$2
Name RSC_axmhdvorhanden__it_IT: 'Reference Data'!$D$2:$D$2
Name RSC_axtaxdummyfilter__de_DE: 'Reference Data'!$K$2:$K$2
Name RSC_axtaxdummyfilter__fr_FR: 'Reference Data'!$R$2:$R$2
Name RSC_axtaxdummyfilter__it_IT: 'Reference Data'!$F$2:$F$2
Name RSC_de_DE_refxaltersbegrtyp: 'Reference Data'!$AL$2:$AL$9
Name RSC_de_DE_refxartikelartsap: 'Reference Data'!$W$2:$W$14
Name RSC_de_DE_refxmengeneinheit: 'Reference Data'!$AC$2:$AC$14
Name RSC_de_DE_refxsaisontypsap: 'Reference Data'!$Z$2:$Z$7
Name RSC_de_DE_refxtaxclass: 'Reference Data'!$AI$2:$AI$6
Name RSC_de_DE_refxvergleichspreiseinheit: 'Reference Data'!$AF$2:$AF$6
Name RSC_ENTITY_NAME: 'Reference Data'!$S$2:$S$2
Name RSC_fr_FR_refxaltersbegrtyp: 'Reference Data'!$AM$2:$AM$9
Name RSC_fr_FR_refxartikelartsap: 'Reference Data'!$X$2:$X$6
Name RSC_fr_FR_refxmengeneinheit: 'Reference Data'!$AD$2:$AD$14
Name RSC_fr_FR_refxsaisontypsap: 'Reference Data'!$AA$2:$AA$7
Name RSC_fr_FR_refxtaxclass: 'Reference Data'!$AJ$2:$AJ$6
Name RSC_fr_FR_refxvergleichspreiseinheit: 'Reference Data'!$AG$2:$AG$3
Name RSC_it_IT_refxaltersbegrtyp: 'Reference Data'!$AN$2:$AN$9
Name RSC_it_IT_refxartikelartsap: 'Reference Data'!$Y$2:$Y$6
Name RSC_it_IT_refxmengeneinheit: 'Reference Data'!$AE$2:$AE$14
Name RSC_it_IT_refxsaisontypsap: 'Reference Data'!$AB$2:$AB$7
Name RSC_it_IT_refxtaxclass: 'Reference Data'!$AK$2:$AK$6
Name RSC_it_IT_refxvergleichspreiseinheit: 'Reference Data'!$AH$2:$AH$3

Sheet Help
B3: These are all read only
A4: TEMPLATE NAME | B4: RS EXCEL
A5: TEMPLATE VERSION | B5: V1.0
A6: MULTI VALUES DELIMITER | B6: ||
A7: CONTEXT PATH DELIMITER | B7: >>
A8: LEGENDS | B8: INHERITED VALUE(S)
B9: GOVERNANCE ERROR(S)
A12: Type
A13: SYSTEM/RELATIONSHIPS | B13: COLLECTION | C13: MANDATORY | D13: MANDATORY COLLECTION
A14: GLOBAL | B14: COLLECTION | C14: MANDATORY | D14: MANDATORY COLLECTION
A15: GLOBAL ENHANCER | B15: COLLECTION | C15: MANDATORY | D15: MANDATORY COLLECTION
A16: CONTEXT | B16: COLLECTION | C16: MANDATORY | D16: MANDATORY COLLECTION
A17: CONTEXT ENHANCER | B17: COLLECTION | C17: MANDATORY | D17: MANDATORY COLLECTION

Sheet Entities
A1: System Attributes | E1: Enhancer Attribute(s) | G1: Matching Attribute(s) | H1: 01 - Rumpfinformationen | J1: 99 - intern | L1: 01 - Rumpfinformationen | O1: 03 - Texte | U1: 99 - intern | AA1: 01 - Rumpfinformationen | AH1: 05 - Kasse | AM1: 99 - intern
A2: Action | B2: Type | C2: ID | D2: Name | E2: Artikeltyp | F2: Warengruppe//de-DE | G2: MDM ID | H2: Artikelart//de-DE | I2: Saison Typ//de-DE | J2: GTIN Suche | K2: Ergänzte Regio-Artikel-GTIN | L2: Artikeltext//de-DE | M2: Artikeltext//fr-FR | N2: Artikeltext//it-IT | O2: Gestellbeschriftung 1//de-DE | P2: Gestellbeschriftung 1//fr-FR | Q2: Gestellbeschriftung 1//it-IT | R2: Gestellbeschriftung 2//de-DE | S2: Gestellbeschriftung 2//fr-FR | T2: Gestellbeschriftung 2//it-IT | U2: Gestellbeschriftung 3 Regio//de-DE | V2: Gestellbeschriftung 3 Regio//fr-FR | W2: Gestellbeschriftung 3 Regio//it-IT | X2: Cash receipt text Regio//de-DE | Y2: Cash receipt text Regio//fr-FR | Z2: Cash receipt text Regio//it-IT | AA2: Nettoinhalt | AB2: Inhaltsmengeneinheit Grundpreis//de-DE | AC2: Grundpreiseinheit//de-DE | AD2: Basismengeneinheit//de-DE | AE2: Steuerklassifikation//de-DE | AF2: Leergut | AG2: Altersbegrenzungs-Typ//de-DE | AH2: Rabatt zugelassen | AI2: Rückgabe zugelassen | AJ2: Preisänderung Kasse erlaubt | AK2: Automatischer Bondruck | AL2: Shop-In-Shop | AM2: Ist Fremdartikel | AN2: GTIN-Typ Regioapp | AO2: Ist Regioartikel | AP2: Source | AQ2: SAP System Integration | AR2: Ist Vordefiniert
B3: exartikel | E3: 00 - Einzelartikel | F3: ="Warengruppe>>"&_xlfn.TEXTJOIN(">>",TRUE,Migrationsartikel!V2:X2) -> Warengruppe>>Früchte und Gemüse>>Früchte und Gemüse>>Früchte | H3: ZHAW - Handelsware ohne Charge | J3: =_xlfn.TEXTJOIN(" ",TRUE,Migrationsartikel!B2,Migrationsartikel!E2) -> 7610029177671 | L3: =_xlfn.TEXTJOIN(" ",TRUE,Migrationsartikel!F2:H2) -> Marroni gekocht 400g | M3: =_xlfn.TEXTJOIN(" ",TRUE,Migrationsartikel!J2:L2) -> Marrons cuits 400g | N3: =_xlfn.TEXTJOIN(" ",TRUE,Migrationsartikel!N2:P2) -> Castagne cotte 400g | O3: =Migrationsartikel!F2 -> Marroni gekocht | P3: =Migrationsartikel!J2 -> Marrons cuits | Q3: =Migrationsartikel!N2 -> Castagne cotte | R3: =_xlfn.TEXTJOIN(" ",TRUE,Migrationsartikel!G2) | S3: =_xlfn.TEXTJOIN(" ",TRUE,Migrationsartikel!K2) | T3: =_xlfn.TEXTJOIN(" ",TRUE,Migrationsartikel!O2) | U3: =_xlfn.TEXTJOIN(" ",TRUE,Migrationsartikel!H2) -> 400g | V3: =_xlfn.TEXTJOIN(" ",TRUE,Migrationsartikel!L2) -> 400g | W3: =_xlfn.TEXTJOIN(" ",TRUE,Migrationsartikel!P2) -> 400g | X3: =Migrationsartikel!I2 -> Marroni gekocht | Y3: =Migrationsartikel!M2 -> Marrons cuits | Z3: =Migrationsartikel!Q2 -> Castagne cotte | AA3: =Migrationsartikel!R2 -> 1 | AB3: =Migrationsartikel!T2 -> Kilogramm | AC3: =Migrationsartikel!S2 -> 1 | AD3: =Migrationsartikel!U2 -> (PCE) Stück | AE3: =Migrationsartikel!Y2 -> 3 - Reduzierter Satz | AF3: =IF(Migrationsartikel!AA2="Kein Depotartikel","",Migrationsartikel!AA2) | AG3: =Migrationsartikel!Z2 -> Keine | AH3: =IF(Migrationsartikel!AB2="ja","true",FALSE) -> true | AI3: =IF(Migrationsartikel!AC2="ja","true",FALSE) -> true | AJ3: =IF(Migrationsartikel!AD2="ja","true",FALSE) -> true | AK3: =IF(Migrationsartikel!AE2="ja","true",FALSE) -> true | AL3: =IF(Migrationsartikel!AF2="ja","Denner Partner","") | AM3: =IF(Migrationsartikel!AG2="ja","true","false") -> false | AN3: =IF(AND(ISNUMBER(J3),J3>=100,J3<=999),"PLU",IF(AND(ISNUMBER(J3),J3>999),"GTIN","Kassentastenbelegung (ohne GTIN/PLU)")) -> Kassentastenbelegung (ohne GTIN/PLU) | AO3: true | AP3: Imp. Regio 3 - 3003 | AQ3: S4H | AR3: true
B4: exartikel | E4: 00 - Einzelartikel | F4: ="Warengruppe>>"&_xlfn.TEXTJOIN(">>",TRUE,Migrationsartikel!V3:X3) -> Warengruppe>>Früchte und Gemüse>>Früchte und Gemüse>>Früchte | H4: ZHAW - Handelsware ohne Charge | J4: =_xlfn.TEXTJOIN(" ",TRUE,Migrationsartikel!B3,Migrationsartikel!E3) | L4: =_xlfn.TEXTJOIN(" ",TRUE,Migrationsartikel!F3:H3) -> Aprikosen 1kg | M4: =_xlfn.TEXTJOIN(" ",TRUE,Migrationsartikel!J3:L3) -> Abricots 1kg | N4: =_xlfn.TEXTJOIN(" ",TRUE,Migrationsartikel!N3:P3) -> Albicocche 1kg | O4: =Migrationsartikel!F3 -> Aprikosen | P4: =Migrationsartikel!J3 -> Abricots | Q4: =Migrationsartikel!N3 -> Albicocche | R4: =_xlfn.TEXTJOIN(" ",TRUE,Migrationsartikel!G3) | S4: =_xlfn.TEXTJOIN(" ",TRUE,Migrationsartikel!K3) | T4: =_xlfn.TEXTJOIN(" ",TRUE,Migrationsartikel!O3) | U4: =_xlfn.TEXTJOIN(" ",TRUE,Migrationsartikel!H3) -> 1kg | V4: =_xlfn.TEXTJOIN(" ",TRUE,Migrationsartikel!L3) -> 1kg | W4: =_xlfn.TEXTJOIN(" ",TRUE,Migrationsartikel!P3) -> 1kg | X4: =Migrationsartikel!I3 -> Aprikosen 1kg | Y4: =Migrationsartikel!M3 -> Abricots 1g | Z4: =Migrationsartikel!Q3 -> Albicocche 1kg | AA4: =Migrationsartikel!R3 -> 1 | AB4: =Migrationsartikel!T3 -> Kilogramm | AC4: =Migrationsartikel!S3 -> 1 | AD4: =Migrationsartikel!U3 -> (PCE) Stück | AE4: =Migrationsartikel!Y3 -> 3 - Reduzierter Satz | AF4: =IF(Migrationsartikel!AA3="Kein Depotartikel","",Migrationsartikel!AA3) | AG4: =Migrationsartikel!Z3 -> Keine | AH4: =IF(Migrationsartikel!AB3="ja","true",FALSE) -> true | AI4: =IF(Migrationsartikel!AC3="ja","true",FALSE) -> true | AJ4: =IF(Migrationsartikel!AD3="ja","true",FALSE) -> true | AK4: =IF(Migrationsartikel!AE3="ja","true",FALSE) -> true | AL4: =IF(Migrationsartikel!AF3="ja","Denner Partner","") | AM4: =IF(Migrationsartikel!AG3="ja","true","false") -> false | AN4: =IF(AND(ISNUMBER(J4),J4>=100,J4<=999),"PLU",IF(AND(ISNUMBER(J4),J4>999),"GTIN","Kassentastenbelegung (ohne GTIN/PLU)")) -> Kassentastenbelegung (ohne GTIN/PLU) | AO4: true | AP4: Imp. Regio 3 - 3004 | AQ4: S4H | AR4: true
B5: exartikel | E5: 00 - Einzelartikel | F5: ="Warengruppe>>"&_xlfn.TEXTJOIN(">>",TRUE,Migrationsartikel!V4:X4) -> Warengruppe>>Früchte und Gemüse>>Früchte und Gemüse>>Früchte | H5: ZHAW - Handelsware ohne Charge | J5: =_xlfn.TEXTJOIN(" ",TRUE,Migrationsartikel!B4,Migrationsartikel!E4) -> 7613399055839 | L5: =_xlfn.TEXTJOIN(" ",TRUE,Migrationsartikel!F4:H4) -> Bio Datteln Frisch Medjoul 200g | M5: =_xlfn.TEXTJOIN(" ",TRUE,Migrationsartikel!J4:L4) -> Bio Dattes fraîches Medjoul 200g | N5: =_xlfn.TEXTJOIN(" ",TRUE,Migrationsartikel!N4:P4) -> Bio datteri freschi Medjoul 200g | O5: =Migrationsartikel!F4 -> Bio Datteln Frisch | P5: =Migrationsartikel!J4 -> Bio Dattes fraîches | Q5: =Migrationsartikel!N4 -> Bio datteri freschi | R5: =_xlfn.TEXTJOIN(" ",TRUE,Migrationsartikel!G4) -> Medjoul | S5: =_xlfn.TEXTJOIN(" ",TRUE,Migrationsartikel!K4) -> Medjoul | T5: =_xlfn.TEXTJOIN(" ",TRUE,Migrationsartikel!O4) -> Medjoul | U5: =_xlfn.TEXTJOIN(" ",TRUE,Migrationsartikel!H4) -> 200g | V5: =_xlfn.TEXTJOIN(" ",TRUE,Migrationsartikel!L4) -> 200g | W5: =_xlfn.TEXTJOIN(" ",TRUE,Migrationsartikel!P4) -> 200g | X5: =Migrationsartikel!I4 -> Bio Datteln Medjoul 200g | Y5: =Migrationsartikel!M4 -> Bio Dattes fr. Medjoul 200g | Z5: =Migrationsartikel!Q4 -> Bio datteri fre Medjoul 200g | AA5: =Migrationsartikel!R4 -> 0.2 | AB5: =Migrationsartikel!T4 -> Gramm | AC5: =Migrationsartikel!S4 -> 100 | AD5: =Migrationsartikel!U4 -> (PCE) Stück | AE5: =Migrationsartikel!Y4 -> 3 - Reduzierter Satz | AF5: =IF(Migrationsartikel!AA4="Kein Depotartikel","",Migrationsartikel!AA4) | AG5: =Migrationsartikel!Z4 -> Keine | AH5: =IF(Migrationsartikel!AB4="ja","true",FALSE) -> true | AI5: =IF(Migrationsartikel!AC4="ja","true",FALSE) -> true | AJ5: =IF(Migrationsartikel!AD4="ja","true",FALSE) -> true | AK5: =IF(Migrationsartikel!AE4="ja","true",FALSE) -> true | AL5: =IF(Migrationsartikel!AF4="ja","Denner Partner","") | AM5: =IF(Migrationsartikel!AG4="ja","true","false") -> false | AN5: =IF(AND(ISNUMBER(J5),J5>=100,J5<=999),"PLU",IF(AND(ISNUMBER(J5),J5>999),"GTIN","Kassentastenbelegung (ohne GTIN/PLU)")) -> Kassentastenbelegung (ohne GTIN/PLU) | AO5: true | AP5: Imp. Regio 3 - 3005 | AQ5: S4H | AR5: true
B6: exartikel | E6: 00 - Einzelartikel | F6: ="Warengruppe>>"&_xlfn.TEXTJOIN(">>",TRUE,Migrationsartikel!V5:X5) -> Warengruppe>>Früchte und Gemüse>>Früchte und Gemüse>>Früchte | H6: ZHAW - Handelsware ohne Charge | J6: =_xlfn.TEXTJOIN(" ",TRUE,Migrationsartikel!B5,Migrationsartikel!E5) | L6: =_xlfn.TEXTJOIN(" ",TRUE,Migrationsartikel!F5:H5) -> Feigen Pulled 400g | M6: =_xlfn.TEXTJOIN(" ",TRUE,Migrationsartikel!J5:L5) -> Figues Pulled 400g | N6: =_xlfn.TEXTJOIN(" ",TRUE,Migrationsartikel!N5:P5) -> Fichi Pulled 400g | O6: =Migrationsartikel!F5 -> Feigen Pulled | P6: =Migrationsartikel!J5 -> Figues Pulled | Q6: =Migrationsartikel!N5 -> Fichi Pulled | R6: =_xlfn.TEXTJOIN(" ",TRUE,Migrationsartikel!G5) | S6: =_xlfn.TEXTJOIN(" ",TRUE,Migrationsartikel!K5) | T6: =_xlfn.TEXTJOIN(" ",TRUE,Migrationsartikel!O5) | U6: =_xlfn.TEXTJOIN(" ",TRUE,Migrationsartikel!H5) -> 400g | V6: =_xlfn.TEXTJOIN(" ",TRUE,Migrationsartikel!L5) -> 400g | W6: =_xlfn.TEXTJOIN(" ",TRUE,Migrationsartikel!P5) -> 400g | X6: =Migrationsartikel!I5 -> Feigen Pulled 400g | Y6: =Migrationsartikel!M5 -> Figues Pulled 400g | Z6: =Migrationsartikel!Q5 -> Fichi Pulled 40g | AA6: =Migrationsartikel!R5 -> 0.4 | AB6: =Migrationsartikel!T5 -> Kilogramm | AC6: =Migrationsartikel!S5 -> 1 | AD6: =Migrationsartikel!U5 -> (PCE) Stück | AE6: =Migrationsartikel!Y5 -> 3 - Reduzierter Satz | AF6: =IF(Migrationsartikel!AA5="Kein Depotartikel","",Migrationsartikel!AA5) | AG6: =Migrationsartikel!Z5 -> Keine | AH6: =IF(Migrationsartikel!AB5="ja","true",FALSE) -> true | AI6: =IF(Migrationsartikel!AC5="ja","true",FALSE) -> true | AJ6: =IF(Migrationsartikel!AD5="ja","true",FALSE) -> true | AK6: =IF(Migrationsartikel!AE5="ja","true",FALSE) -> true | AL6: =IF(Migrationsartikel!AF5="ja","Denner Partner","") | AM6: =IF(Migrationsartikel!AG5="ja","true","false") -> false | AN6: =IF(AND(ISNUMBER(J6),J6>=100,J6<=999),"PLU",IF(AND(ISNUMBER(J6),J6>999),"GTIN","Kassentastenbelegung (ohne GTIN/PLU)")) -> Kassentastenbelegung (ohne GTIN/PLU) | AO6: true | AP6: Imp. Regio 3 - 3006 | AQ6: S4H | AR6: true
B7: exartikel | E7: 00 - Einzelartikel | F7: ="Warengruppe>>"&_xlfn.TEXTJOIN(">>",TRUE,Migrationsartikel!V6:X6) -> Warengruppe>>Früchte und Gemüse>>Früchte und Gemüse>>Früchte | H7: ZHAW - Handelsware ohne Charge | J7: =_xlfn.TEXTJOIN(" ",TRUE,Migrationsartikel!B6,Migrationsartikel!E6) -> 7613399055365 | L7: =_xlfn.TEXTJOIN(" ",TRUE,Migrationsartikel!F6:H6) -> Haselnüsse 500g | M7: =_xlfn.TEXTJOIN(" ",TRUE,Migrationsartikel!J6:L6) -> Noisettes 500g | N7: =_xlfn.TEXTJOIN(" ",TRUE,Migrationsartikel!N6:P6) -> Nocciole 500g | O7: =Migrationsartikel!F6 -> Haselnüsse | P7: =Migrationsartikel!J6 -> Noisettes | Q7: =Migrationsartikel!N6 -> Nocciole | R7: =_xlfn.TEXTJOIN(" ",TRUE,Migrationsartikel!G6) | S7: =_xlfn.TEXTJOIN(" ",TRUE,Migrationsartikel!K6) | T7: =_xlfn.TEXTJOIN(" ",TRUE,Migrationsartikel!O6) | U7: =_xlfn.TEXTJOIN(" ",TRUE,Migrationsartikel!H6) -> 500g | V7: =_xlfn.TEXTJOIN(" ",TRUE,Migrationsartikel!L6) -> 500g | W7: =_xlfn.TEXTJOIN(" ",TRUE,Migrationsartikel!P6) -> 500g | X7: =Migrationsartikel!I6 -> Haselnüsse 500g | Y7: =Migrationsartikel!M6 -> Noisettes 500g | Z7: =Migrationsartikel!Q6 -> Nocciole 500g | AA7: =Migrationsartikel!R6 -> 0.5 | AB7: =Migrationsartikel!T6 -> Kilogramm | AC7: =Migrationsartikel!S6 -> 1 | AD7: =Migrationsartikel!U6 -> (PCE) Stück | AE7: =Migrationsartikel!Y6 -> 3 - Reduzierter Satz | AF7: =IF(Migrationsartikel!AA6="Kein Depotartikel","",Migrationsartikel!AA6) | AG7: =Migrationsartikel!Z6 -> Keine | AH7: =IF(Migrationsartikel!AB6="ja","true",FALSE) -> true | AI7: =IF(Migrationsartikel!AC6="ja","true",FALSE) -> true | AJ7: =IF(Migrationsartikel!AD6="ja","true",FALSE) -> true | AK7: =IF(Migrationsartikel!AE6="ja","true",FALSE) -> true | AL7: =IF(Migrationsartikel!AF6="ja","Denner Partner","") | AM7: =IF(Migrationsartikel!AG6="ja","true","false") -> false | AN7: =IF(AND(ISNUMBER(J7),J7>=100,J7<=999),"PLU",IF(AND(ISNUMBER(J7),J7>999),"GTIN","Kassentastenbelegung (ohne GTIN/PLU)")) -> Kassentastenbelegung (ohne GTIN/PLU) | AO7: true | AP7: Imp. Regio 3 - 3007 | AQ7: S4H | AR7: true
B8: exartikel | E8: 00 - Einzelartikel | F8: ="Warengruppe>>"&_xlfn.TEXTJOIN(">>",TRUE,Migrationsartikel!V7:X7) -> Warengruppe>>Früchte und Gemüse>>Früchte und Gemüse>>Früchte | H8: ZHAW - Handelsware ohne Charge | J8: =_xlfn.TEXTJOIN(" ",TRUE,Migrationsartikel!B7,Migrationsartikel!E7) -> 143 | L8: =_xlfn.TEXTJOIN(" ",TRUE,Migrationsartikel!F7:H7) -> Birnen Büscheli Offen Kl. 1 | M8: =_xlfn.TEXTJOIN(" ",TRUE,Migrationsartikel!J7:L7) -> Poires Büscheli En vrac, cl. 1 | N8: =_xlfn.TEXTJOIN(" ",TRUE,Migrationsartikel!N7:P7) -> Pere Büscheli Cl. 1 vendita sfusa | O8: =Migrationsartikel!F7 -> Birnen Büscheli | P8: =Migrationsartikel!J7 -> Poires Büscheli | Q8: =Migrationsartikel!N7 -> Pere Büscheli | R8: =_xlfn.TEXTJOIN(" ",TRUE,Migrationsartikel!G7) -> Offen Kl. 1 | S8: =_xlfn.TEXTJOIN(" ",TRUE,Migrationsartikel!K7) -> En vrac, cl. 1 | T8: =_xlfn.TEXTJOIN(" ",TRUE,Migrationsartikel!O7) -> Cl. 1 vendita sfusa | U8: =_xlfn.TEXTJOIN(" ",TRUE,Migrationsartikel!H7) | V8: =_xlfn.TEXTJOIN(" ",TRUE,Migrationsartikel!L7) | W8: =_xlfn.TEXTJOIN(" ",TRUE,Migrationsartikel!P7) | X8: =Migrationsartikel!I7 -> Birnen Büscheli Offen Kl. 1 | Y8: =Migrationsartikel!M7 -> Poires Büscheli | Z8: =Migrationsartikel!Q7 -> Pere Büscheli Cl. 1 v.s. | AA8: =Migrationsartikel!R7 -> 1 | AB8: =Migrationsartikel!T7 -> Kilogramm | AC8: =Migrationsartikel!S7 -> 1 | AD8: =Migrationsartikel!U7 -> (KGM) KG | AE8: =Migrationsartikel!Y7 -> 3 - Reduzierter Satz | AF8: =IF(Migrationsartikel!AA7="Kein Depotartikel","",Migrationsartikel!AA7) | AG8: =Migrationsartikel!Z7 -> Keine | AH8: =IF(Migrationsartikel!AB7="ja","true",FALSE) -> true | AI8: =IF(Migrationsartikel!AC7="ja","true",FALSE) -> true | AJ8: =IF(Migrationsartikel!AD7="ja","true",FALSE) -> true | AK8: =IF(Migrationsartikel!AE7="ja","true",FALSE) -> true | AL8: =IF(Migrationsartikel!AF7="ja","Denner Partner","") | AM8: =IF(Migrationsartikel!AG7="ja","true","false") -> false | AN8: =IF(AND(ISNUMBER(J8),J8>=100,J8<=999),"PLU",IF(AND(ISNUMBER(J8),J8>999),"GTIN","Kassentastenbelegung (ohne GTIN/PLU)")) -> Kassentastenbelegung (ohne GTIN/PLU) | AO8: true | AP8: Imp. Regio 3 - 3008 | AQ8: S4H | AR8: true
B9: exartikel | E9: 00 - Einzelartikel | F9: ="Warengruppe>>"&_xlfn.TEXTJOIN(">>",TRUE,Migrationsartikel!V8:X8) -> Warengruppe>>Früchte und Gemüse>>Früchte und Gemüse>>Früchte | H9: ZHAW - Handelsware ohne Charge | J9: =_xlfn.TEXTJOIN(" ",TRUE,Migrationsartikel!B8,Migrationsartikel!E8) -> 7613399039945 | L9: =_xlfn.TEXTJOIN(" ",TRUE,Migrationsartikel!F8:H8) -> Granatapfelkerne Becher 125g | M9: =_xlfn.TEXTJOIN(" ",TRUE,Migrationsartikel!J8:L8) -> Graines de grenade Gobelet 125g | N9: =_xlfn.TEXTJOIN(" ",TRUE,Migrationsartikel!N8:P8) -> Melagrana chicchi bicchiere 125g | O9: =Migrationsartikel!F8 -> Granatapfelkerne | P9: =Migrationsartikel!J8 -> Graines de grenade | Q9: =Migrationsartikel!N8 -> Melagrana chicchi | R9: =_xlfn.TEXTJOIN(" ",TRUE,Migrationsartikel!G8) -> Becher | S9: =_xlfn.TEXTJOIN(" ",TRUE,Migrationsartikel!K8) -> Gobelet | T9: =_xlfn.TEXTJOIN(" ",TRUE,Migrationsartikel!O8) -> bicchiere | U9: =_xlfn.TEXTJOIN(" ",TRUE,Migrationsartikel!H8) -> 125g | V9: =_xlfn.TEXTJOIN(" ",TRUE,Migrationsartikel!L8) -> 125g | W9: =_xlfn.TEXTJOIN(" ",TRUE,Migrationsartikel!P8) -> 125g | X9: =Migrationsartikel!I8 -> Granatapfelkerne Becher | Y9: =Migrationsartikel!M8 -> Graines de grenade 125g | Z9: =Migrationsartikel!Q8 -> Melagrana chicchi 125g | AA9: =Migrationsartikel!R8 -> 0.125 | AB9: =Migrationsartikel!T8 -> Gramm | AC9: =Migrationsartikel!S8 -> 100 | AD9: =Migrationsartikel!U8 -> (PCE) Stück | AE9: =Migrationsartikel!Y8 -> 3 - Reduzierter Satz | AF9: =IF(Migrationsartikel!AA8="Kein Depotartikel","",Migrationsartikel!AA8) | AG9: =Migrationsartikel!Z8 -> Keine | AH9: =IF(Migrationsartikel!AB8="ja","true",FALSE) -> true | AI9: =IF(Migrationsartikel!AC8="ja","true",FALSE) -> true | AJ9: =IF(Migrationsartikel!AD8="ja","true",FALSE) -> true | AK9: =IF(Migrationsartikel!AE8="ja","true",FALSE) -> true | AL9: =IF(Migrationsartikel!AF8="ja","Denner Partner","") | AM9: =IF(Migrationsartikel!AG8="ja","true","false") -> false | AN9: =IF(AND(ISNUMBER(J9),J9>=100,J9<=999),"PLU",IF(AND(ISNUMBER(J9),J9>999),"GTIN","Kassentastenbelegung (ohne GTIN/PLU)")) -> Kassentastenbelegung (ohne GTIN/PLU) | AO9: true | AP9: Imp. Regio 3 - 3009 | AQ9: S4H | AR9: true
B10: exartikel | E10: 00 - Einzelartikel | F10: ="Warengruppe>>"&_xlfn.TEXTJOIN(">>",TRUE,Migrationsartikel!V9:X9) -> Warengruppe>>Früchte und Gemüse>>Früchte und Gemüse>>Früchte | H10: ZHAW - Handelsware ohne Charge | J10: =_xlfn.TEXTJOIN(" ",TRUE,Migrationsartikel!B9,Migrationsartikel!E9) | L10: =_xlfn.TEXTJOIN(" ",TRUE,Migrationsartikel!F9:H9) -> Ananas Baby 1Stk | M10: =_xlfn.TEXTJOIN(" ",TRUE,Migrationsartikel!J9:L9) -> Ananas Baby 1pce | N10: =_xlfn.TEXTJOIN(" ",TRUE,Migrationsartikel!N9:P9) -> Ananas Baby 1pz | O10: =Migrationsartikel!F9 -> Ananas | P10: =Migrationsartikel!J9 -> Ananas | Q10: =Migrationsartikel!N9 -> Ananas | R10: =_xlfn.TEXTJOIN(" ",TRUE,Migrationsartikel!G9) -> Baby | S10: =_xlfn.TEXTJOIN(" ",TRUE,Migrationsartikel!K9) -> Baby | T10: =_xlfn.TEXTJOIN(" ",TRUE,Migrationsartikel!O9) -> Baby | U10: =_xlfn.TEXTJOIN(" ",TRUE,Migrationsartikel!H9) -> 1Stk | V10: =_xlfn.TEXTJOIN(" ",TRUE,Migrationsartikel!L9) -> 1pce | W10: =_xlfn.TEXTJOIN(" ",TRUE,Migrationsartikel!P9) -> 1pz | X10: =Migrationsartikel!I9 -> Ananas Baby Stk | Y10: =Migrationsartikel!M9 -> Ananas Baby | Z10: =Migrationsartikel!Q9 -> Ananas Baby 1 pz | AA10: =Migrationsartikel!R9 -> 1 | AB10: =Migrationsartikel!T9 -> Stück | AC10: =Migrationsartikel!S9 -> 1 | AD10: =Migrationsartikel!U9 -> (PCE) Stück | AE10: =Migrationsartikel!Y9 -> 3 - Reduzierter Satz | AF10: =IF(Migrationsartikel!AA9="Kein Depotartikel","",Migrationsartikel!AA9) | AG10: =Migrationsartikel!Z9 -> Keine | AH10: =IF(Migrationsartikel!AB9="ja","true",FALSE) -> true | AI10: =IF(Migrationsartikel!AC9="ja","true",FALSE) -> true | AJ10: =IF(Migrationsartikel!AD9="ja","true",FALSE) -> true | AK10: =IF(Migrationsartikel!AE9="ja","true",FALSE) -> true | AL10: =IF(Migrationsartikel!AF9="ja","Denner Partner","") | AM10: =IF(Migrationsartikel!AG9="ja","true","false") -> false | AN10: =IF(AND(ISNUMBER(J10),J10>=100,J10<=999),"PLU",IF(AND(ISNUMBER(J10),J10>999),"GTIN","Kassentastenbelegung (ohne GTIN/PLU)")) -> Kassentastenbelegung (ohne GTIN/PLU) | AO10: true | AP10: Imp. Regio 3 - 3010 | AQ10: S4H | AR10: true
B11: exartikel | E11: 00 - Einzelartikel | F11: ="Warengruppe>>"&_xlfn.TEXTJOIN(">>",TRUE,Migrationsartikel!V10:X10) -> Warengruppe>>Früchte und Gemüse>>Früchte und Gemüse>>Früchte | H11: ZHAW - Handelsware ohne Charge | J11: =_xlfn.TEXTJOIN(" ",TRUE,Migrationsartikel!B10,Migrationsartikel!E10) -> 7613399001270 | L11: =_xlfn.TEXTJOIN(" ",TRUE,Migrationsartikel!F10:H10) -> Ananas Becher 200g | M11: =_xlfn.TEXTJOIN(" ",TRUE,Migrationsartikel!J10:L10) -> Ananas Gobelet 200g | N11: =_xlfn.TEXTJOIN(" ",TRUE,Migrationsartikel!N10:P10) -> Ananas bicchiere 200g | O11: =Migrationsartikel!F10 -> Ananas | P11: =Migrationsartikel!J10 -> Ananas | Q11: =Migrationsartikel!N10 -> Ananas | R11: =_xlfn.TEXTJOIN(" ",TRUE,Migrationsartikel!G10) -> Becher | S11: =_xlfn.TEXTJOIN(" ",TRUE,Migrationsartikel!K10) -> Gobelet | T11: =_xlfn.TEXTJOIN(" ",TRUE,Migrationsartikel!O10) -> bicchiere | U11: =_xlfn.TEXTJOIN(" ",TRUE,Migrationsartikel!H10) -> 200g | V11: =_xlfn.TEXTJOIN(" ",TRUE,Migrationsartikel!L10) -> 200g | W11: =_xlfn.TEXTJOIN(" ",TRUE,Migrationsartikel!P10) -> 200g | X11: =Migrationsartikel!I10 -> Ananas Becher 200g | Y11: =Migrationsartikel!M10 -> Ananas gobelet 200g | Z11: =Migrationsartikel!Q10 -> Ananas bicchiere 200g | AA11: =Migrationsartikel!R10 -> 0.2 | AB11: =Migrationsartikel!T10 -> Gramm | AC11: =Migrationsartikel!S10 -> 100 | AD11: =Migrationsartikel!U10 -> (PCE) Stück | AE11: =Migrationsartikel!Y10 -> 3 - Reduzierter Satz | AF11: =IF(Migrationsartikel!AA10="Kein Depotartikel","",Migrationsartikel!AA10) | AG11: =Migrationsartikel!Z10 -> Keine | AH11: =IF(Migrationsartikel!AB10="ja","true",FALSE) -> true | AI11: =IF(Migrationsartikel!AC10="ja","true",FALSE) -> true | AJ11: =IF(Migrationsartikel!AD10="ja","true",FALSE) -> true | AK11: =IF(Migrationsartikel!AE10="ja","true",FALSE) -> true | AL11: =IF(Migrationsartikel!AF10="ja","Denner Partner","") | AM11: =IF(Migrationsartikel!AG10="ja","true","false") -> false | AN11: =IF(AND(ISNUMBER(J11),J11>=100,J11<=999),"PLU",IF(AND(ISNUMBER(J11),J11>999),"GTIN","Kassentastenbelegung (ohne GTIN/PLU)")) -> Kassentastenbelegung (ohne GTIN/PLU) | AO11: true | AP11: Imp. Regio 3 - 3011 | AQ11: S4H | AR11: true
B12: exartikel | E12: 00 - Einzelartikel | F12: ="Warengruppe>>"&_xlfn.TEXTJOIN(">>",TRUE,Migrationsartikel!V11:X11) -> Warengruppe>>Früchte und Gemüse>>Früchte und Gemüse>>Früchte | H12: ZHAW - Handelsware ohne Charge | J12: =_xlfn.TEXTJOIN(" ",TRUE,Migrationsartikel!B11,Migrationsartikel!E11) -> 104 | L12: =_xlfn.TEXTJOIN(" ",TRUE,Migrationsartikel!F11:H11) -> Äpfel Diwa Offen Kl. 1 | M12: =_xlfn.TEXTJOIN(" ",TRUE,Migrationsartikel!J11:L11) -> Pommes Diwa En vrac, cl. 1 | N12: =_xlfn.TEXTJOIN(" ",TRUE,Migrationsartikel!N11:P11) -> Mele Diwa Cl. 1 vendita sfusa | O12: =Migrationsartikel!F11 -> Äpfel Diwa | P12: =Migrationsartikel!J11 -> Pommes Diwa | Q12: =Migrationsartikel!N11 -> Mele Diwa | R12: =_xlfn.TEXTJOIN(" ",TRUE,Migrationsartikel!G11) -> Offen Kl. 1 | S12: =_xlfn.TEXTJOIN(" ",TRUE,Migrationsartikel!K11) -> En vrac, cl. 1 | T12: =_xlfn.TEXTJOIN(" ",TRUE,Migrationsartikel!O11) -> Cl. 1 vendita sfusa | U12: =_xlfn.TEXTJOIN(" ",TRUE,Migrationsartikel!H11) | V12: =_xlfn.TEXTJOIN(" ",TRUE,Migrationsartikel!L11) | W12: =_xlfn.TEXTJOIN(" ",TRUE,Migrationsartikel!P11) | X12: =Migrationsartikel!I11 -> Äpfel Diwa Offen Kl. 1 | Y12: =Migrationsartikel!M11 -> Pommes Diwa en vrac cl. 1 | Z12: =Migrationsartikel!Q11 -> Mele Diwa cl. 1 vend. sfusa | AA12: =Migrationsartikel!R11 -> 1 | AB12: =Migrationsartikel!T11 -> Kilogramm | AC12: =Migrationsartikel!S11 -> 1 | AD12: =Migrationsartikel!U11 -> (KGM) KG | AE12: =Migrationsartikel!Y11 -> 3 - Reduzierter Satz | AF12: =IF(Migrationsartikel!AA11="Kein Depotartikel","",Migrationsartikel!AA11) | AG12: =Migrationsartikel!Z11 -> Keine | AH12: =IF(Migrationsartikel!AB11="ja","true",FALSE) -> true | AI12: =IF(Migrationsartikel!AC11="ja","true",FALSE) -> true | AJ12: =IF(Migrationsartikel!AD11="ja","true",FALSE) -> true | AK12: =IF(Migrationsartikel!AE11="ja","true",FALSE) -> true | AL12: =IF(Migrationsartikel!AF11="ja","Denner Partner","") | AM12: =IF(Migrationsartikel!AG11="ja","true","false") -> false | AN12: =IF(AND(ISNUMBER(J12),J12>=100,J12<=999),"PLU",IF(AND(ISNUMBER(J12),J12>999),"GTIN","Kassentastenbelegung (ohne GTIN/PLU)")) -> Kassentastenbelegung (ohne GTIN/PLU) | AO12: true | AP12: Imp. Regio 3 - 3012 | AQ12: S4H | AR12: true
B13: exartikel | E13: 00 - Einzelartikel | F13: ="Warengruppe>>"&_xlfn.TEXTJOIN(">>",TRUE,Migrationsartikel!V12:X12) -> Warengruppe>>Früchte und Gemüse>>Früchte und Gemüse>>Früchte | H13: ZHAW - Handelsware ohne Charge | J13: =_xlfn.TEXTJOIN(" ",TRUE,Migrationsartikel!B12,Migrationsartikel!E12) -> 134 | L13: =_xlfn.TEXTJOIN(" ",TRUE,Migrationsartikel!F12:H12) -> IP-Suisse Äpfel Gala Kl. 1 | M13: =_xlfn.TEXTJOIN(" ",TRUE,Migrationsartikel!J12:L12) -> IP-Suisse Pommes Gala Cl. 1 | N13: =_xlfn.TEXTJOIN(" ",TRUE,Migrationsartikel!N12:P12) -> IP-Suisse Mele Gala Cl. 1 | O13: =Migrationsartikel!F12 -> IP-Suisse Äpfel Gala | P13: =Migrationsartikel!J12 -> IP-Suisse Pommes Gala | Q13: =Migrationsartikel!N12 -> IP-Suisse Mele Gala | R13: =_xlfn.TEXTJOIN(" ",TRUE,Migrationsartikel!G12) -> Kl. 1 | S13: =_xlfn.TEXTJOIN(" ",TRUE,Migrationsartikel!K12) -> Cl. 1 | T13: =_xlfn.TEXTJOIN(" ",TRUE,Migrationsartikel!O12) -> Cl. 1 | U13: =_xlfn.TEXTJOIN(" ",TRUE,Migrationsartikel!H12) | V13: =_xlfn.TEXTJOIN(" ",TRUE,Migrationsartikel!L12) | W13: =_xlfn.TEXTJOIN(" ",TRUE,Migrationsartikel!P12) | X13: =Migrationsartikel!I12 -> IP-Suisse Äpfel Gala Kl. 1 | Y13: =Migrationsartikel!M12 -> IP-Suisse Pommes Gala cl. 1 | Z13: =Migrationsartikel!Q12 -> IP-Suisse Mele Gala cl. 1 | AA13: =Migrationsartikel!R12 -> 1 | AB13: =Migrationsartikel!T12 -> Kilogramm | AC13: =Migrationsartikel!S12 -> 1 | AD13: =Migrationsartikel!U12 -> (KGM) KG | AE13: =Migrationsartikel!Y12 -> 3 - Reduzierter Satz | AF13: =IF(Migrationsartikel!AA12="Kein Depotartikel","",Migrationsartikel!AA12) | AG13: =Migrationsartikel!Z12 -> Keine | AH13: =IF(Migrationsartikel!AB12="ja","true",FALSE) -> true | AI13: =IF(Migrationsartikel!AC12="ja","true",FALSE) -> true | AJ13: =IF(Migrationsartikel!AD12="ja","true",FALSE) -> true | AK13: =IF(Migrationsartikel!AE12="ja","true",FALSE) -> true | AL13: =IF(Migrationsartikel!AF12="ja","Denner Partner","") | AM13: =IF(Migrationsartikel!AG12="ja","true","false") -> false | AN13: =IF(AND(ISNUMBER(J13),J13>=100,J13<=999),"PLU",IF(AND(ISNUMBER(J13),J13>999),"GTIN","Kassentastenbelegung (ohne GTIN/PLU)")) -> Kassentastenbelegung (ohne GTIN/PLU) | AO13: true | AP13: Imp. Regio 3 - 3013 | AQ13: S4H | AR13: true
B14: exartikel | E14: 00 - Einzelartikel | F14: ="Warengruppe>>"&_xlfn.TEXTJOIN(">>",TRUE,Migrationsartikel!V13:X13) -> Warengruppe>>Früchte und Gemüse>>Früchte und Gemüse>>Früchte | H14: ZHAW - Handelsware ohne Charge | J14: =_xlfn.TEXTJOIN(" ",TRUE,Migrationsartikel!B13,Migrationsartikel!E13) -> 112 | L14: =_xlfn.TEXTJOIN(" ",TRUE,Migrationsartikel!F13:H13) -> Äpfel Gala Offen Kl. 2 | M14: =_xlfn.TEXTJOIN(" ",TRUE,Migrationsartikel!J13:L13) -> Pommes Gala En vrac, cl. 2 | N14: =_xlfn.TEXTJOIN(" ",TRUE,Migrationsartikel!N13:P13) -> Mele Gala Cl. 2 vendita sfusa | O14: =Migrationsartikel!F13 -> Äpfel Gala | P14: =Migrationsartikel!J13 -> Pommes Gala | Q14: =Migrationsartikel!N13 -> Mele Gala | R14: =_xlfn.TEXTJOIN(" ",TRUE,Migrationsartikel!G13) -> Offen Kl. 2 | S14: =_xlfn.TEXTJOIN(" ",TRUE,Migrationsartikel!K13) -> En vrac, cl. 2 | T14: =_xlfn.TEXTJOIN(" ",TRUE,Migrationsartikel!O13) -> Cl. 2 vendita sfusa | U14: =_xlfn.TEXTJOIN(" ",TRUE,Migrationsartikel!H13) | V14: =_xlfn.TEXTJOIN(" ",TRUE,Migrationsartikel!L13) | W14: =_xlfn.TEXTJOIN(" ",TRUE,Migrationsartikel!P13) | X14: =Migrationsartikel!I13 -> Äpfel Gala Offen Kl. 2 | Y14: =Migrationsartikel!M13 -> Pommes Gala en vrac cl. 2 | Z14: =Migrationsartikel!Q13 -> Mele Gala cl. 2 vend. afusa | AA14: =Migrationsartikel!R13 -> 1 | AB14: =Migrationsartikel!T13 -> Kilogramm | AC14: =Migrationsartikel!S13 -> 1 | AD14: =Migrationsartikel!U13 -> (KGM) KG | AE14: =Migrationsartikel!Y13 -> 3 - Reduzierter Satz | AF14: =IF(Migrationsartikel!AA13="Kein Depotartikel","",Migrationsartikel!AA13) | AG14: =Migrationsartikel!Z13 -> Keine | AH14: =IF(Migrationsartikel!AB13="ja","true",FALSE) -> true | AI14: =IF(Migrationsartikel!AC13="ja","true",FALSE) -> true | AJ14: =IF(Migrationsartikel!AD13="ja","true",FALSE) -> true | AK14: =IF(Migrationsartikel!AE13="ja","true",FALSE) -> true | AL14: =IF(Migrationsartikel!AF13="ja","Denner Partner","") | AM14: =IF(Migrationsartikel!AG13="ja","true","false") -> false | AN14: =IF(AND(ISNUMBER(J14),J14>=100,J14<=999),"PLU",IF(AND(ISNUMBER(J14),J14>999),"GTIN","Kassentastenbelegung (ohne GTIN/PLU)")) -> Kassentastenbelegung (ohne GTIN/PLU) | AO14: true | AP14: Imp. Regio 3 - 3014 | AQ14: S4H | AR14: true
... B375: exartikel | E375: 00 - Einzelartikel | F375: ="Warengruppe>>"&_xlfn.TEXTJOIN(">>",TRUE,Migrationsartikel!V374:X374) -> Warengruppe>>Food>>Öl/Essig/Salatsaucen>>Öl/Essig/Salatsaucen | H375: ZHAW - Handelsware ohne Charge | J375: =_xlfn.TEXTJOIN(" ",TRUE,Migrationsartikel!B374,Migrationsartikel!E374) | L375: =_xlfn.TEXTJOIN(" ",TRUE,Migrationsartikel!F374:H374) -> Salatsauce Mama's 500ml | M375: =_xlfn.TEXTJOIN(" ",TRUE,Migrationsartikel!J374:L374) -> Sauce à salade Mama’s 500ml | N375: =_xlfn.TEXTJOIN(" ",TRUE,Migrationsartikel!N374:P374) -> Mama's Condimento insalata 500ml | O375: =Migrationsartikel!F374 -> Salatsauce Mama's | P375: =Migrationsartikel!J374 -> Sauce à salade Mama’s | Q375: =Migrationsartikel!N374 -> Mama's Condimento | R375: =_xlfn.TEXTJOIN(" ",TRUE,Migrationsartikel!G374) | S375: =_xlfn.TEXTJOIN(" ",TRUE,Migrationsartikel!K374) | T375: =_xlfn.TEXTJOIN(" ",TRUE,Migrationsartikel!O374) -> insalata | U375: =_xlfn.TEXTJOIN(" ",TRUE,Migrationsartikel!H374) -> 500ml | V375: =_xlfn.TEXTJOIN(" ",TRUE,Migrationsartikel!L374) -> 500ml | W375: =_xlfn.TEXTJOIN(" ",TRUE,Migrationsartikel!P374) -> 500ml | X375: =Migrationsartikel!I374 -> Salatsauce Mama's | Y375: =Migrationsartikel!M374 -> Sauce à salade Mama's 500ml | Z375: =Migrationsartikel!Q374 -> Mama's Cond. insal. 500ml | AA375: =Migrationsartikel!R374 -> 0.5 | AB375: =Migrationsartikel!T374 -> Liter | AC375: =Migrationsartikel!S374 -> 1 | AD375: =Migrationsartikel!U374 -> (LTR) Liter | AE375: =Migrationsartikel!Y374 -> 3 - Reduzierter Satz | AF375: =IF(Migrationsartikel!AA374="Kein Depotartikel","",Migrationsartikel!AA374) | AG375: =Migrationsartikel!Z374 -> Keine | AH375: =IF(Migrationsartikel!AB374="ja","true",FALSE) -> true | AI375: =IF(Migrationsartikel!AC374="ja","true",FALSE) -> true | AJ375: =IF(Migrationsartikel!AD374="ja","true",FALSE) -> true | AK375: =IF(Migrationsartikel!AE374="ja","true",FALSE) -> true | AL375: =IF(Migrationsartikel!AF374="ja","Denner Partner","") | AM375: =IF(Migrationsartikel!AG374="ja","true","false") -> false | AN375: =IF(AND(ISNUMBER(J375),J375>=100,J375<=999),"PLU",IF(AND(ISNUMBER(J375),J375>999),"GTIN","Kassentastenbelegung (ohne GTIN/PLU)")) -> Kassentastenbelegung (ohne GTIN/PLU) | AO375: true | AP375: Imp. Regio 3 - 3375 | AQ375: S4H | AR375: true

Sheet Migrationsartikel
A1: Lf Nr. | B1: PLU-Nr. neu | C1: Stk / kg | D1: PAZ | E1: EAN | F1: Gestellbeschriftung 1 Max. 22 Zeichen (d) | G1: Gestellbeschriftung 2 Max. 22 Zeichen (d) | H1: Gestellbeschriftung 3 Max. 4-8 Zeichen (d) | I1: Kassenbontext Max. 28 Zeichen (d) | J1: Gestellbeschriftung 1 Max. 22 Zeichen (f) | K1: Gestellbeschriftung 2 Max. 22 Zeichen (f) | L1: Gestellbeschriftung 3 Max. 4-8 Zeichen (f) | M1: Kassenbontext Max. 28 Zeichen (f) | N1: Gestellbeschriftung 1 Max. 22 Zeichen (i) | O1: Gestellbeschriftung 2 Max. 22 Zeichen (i) | P1: Gestellbeschriftung 3 Max. 4-8 Zeichen (i) | Q1: Kassenbontext Max. 28 Zeichen (i) | R1: Nettoinhalt | S1: Grundpreismenge Feld 1 | T1: Grundpreismenge Feld 2 | U1: Basismengeneinheit Waage = Kg Verkauf = Stk = Stk Relevant für Berechnungen im MDM/SAP | V1: Warengruppe 1. Feld | W1: Warengruppe 2. Feld | X1: Warengruppe 3. Feld | Y1: Steuerklassifikation | Z1: Altersbegrenzung | AA1: Depot | AB1: Rabatt zugelassen | AC1: Rückgabe zugelassen | AD1: Preisänderung zugelassen | AE1: Etiketten-druck | AF1: Shop-in-Shop | AG1: Fremdartikel | AH1: Qualitätsanforderung geprüft | AI1: Verkaufskonditionen | AJ1: Lieferant
A2: 162 | C2: Stk | D2: Nein | E2: 7610029177671 | F2: Marroni gekocht | H2: 400g | I2: Marroni gekocht | J2: Marrons cuits | L2: 400g | M2: Marrons cuits | N2: Castagne cotte | P2: 400g | Q2: Castagne cotte | R2: 1 | S2: 1 | T2: Kilogramm | U2: (PCE) Stück | V2: Früchte und Gemüse | W2: Früchte und Gemüse | X2: Früchte | Y2: 3 - Reduzierter Satz | Z2: Keine | AA2: Kein Depotartikel | AB2: ja | AC2: ja | AD2: ja | AE2: ja | AF2: - | AG2: - | AH2: ja | AI2: 0.05 | AJ2: -
A3: 163 | C3: Stk | F3: Aprikosen | H3: 1kg | I3: Aprikosen 1kg | J3: Abricots | L3: 1kg | M3: Abricots 1g | N3: Albicocche | P3: 1kg | Q3: Albicocche 1kg | R3: 1 | S3: 1 | T3: Kilogramm | U3: (PCE) Stück | V3: Früchte und Gemüse | W3: Früchte und Gemüse | X3: Früchte | Y3: 3 - Reduzierter Satz | Z3: Keine | AA3: Kein Depotartikel | AB3: ja | AC3: ja | AD3: ja | AE3: ja | AF3: - | AG3: - | AH3: ja | AI3: 0.05 | AJ3: -
A4: 169 | C4: Stk | D4: Nein | E4: 7613399055839 | F4: Bio Datteln Frisch | G4: Medjoul | H4: 200g | I4: Bio Datteln Medjoul 200g | J4: Bio Dattes fraîches | K4: Medjoul | L4: 200g | M4: Bio Dattes fr. Medjoul 200g | N4: Bio datteri freschi | O4: Medjoul | P4: 200g | Q4: Bio datteri fre Medjoul 200g | R4: 0.2 | S4: 100 | T4: Gramm | U4: (PCE) Stück | V4: Früchte und Gemüse | W4: Früchte und Gemüse | X4: Früchte | Y4: 3 - Reduzierter Satz | Z4: Keine | AA4: Kein Depotartikel | AB4: ja | AC4: ja | AD4: ja | AE4: ja | AF4: - | AG4: - | AH4: ja | AI4: 0.05 | AJ4: -
A5: 170 | C5: Stk | F5: Feigen Pulled | H5: 400g | I5: Feigen Pulled 400g | J5: Figues Pulled | L5: 400g | M5: Figues Pulled 400g | N5: Fichi Pulled | P5: 400g | Q5: Fichi Pulled 40g | R5: 0.4 | S5: 1 | T5: Kilogramm | U5: (PCE) Stück | V5: Früchte und Gemüse | W5: Früchte und Gemüse | X5: Früchte | Y5: 3 - Reduzierter Satz | Z5: Keine | AA5: Kein Depotartikel | AB5: ja | AC5: ja | AD5: ja | AE5: ja | AF5: - | AG5: - | AH5: ja | AI5: 0.05 | AJ5: -
A6: 195 | C6: Stk | D6: Nein | E6: 7613399055365 | F6: Haselnüsse | H6: 500g | I6: Haselnüsse 500g | J6: Noisettes | L6: 500g | M6: Noisettes 500g | N6: Nocciole | P6: 500g | Q6: Nocciole 500g | R6: 0.5 | S6: 1 | T6: Kilogramm | U6: (PCE) Stück | V6: Früchte und Gemüse | W6: Früchte und Gemüse | X6: Früchte | Y6: 3 - Reduzierter Satz | Z6: Keine | AA6: Kein Depotartikel | AB6: ja | AC6: ja | AD6: ja | AE6: ja | AF6: - | AG6: - | AH6: ja | AI6: 0.05 | AJ6: -
A7: 200 | B7: 143 | C7: kg | D7: Nein | F7: Birnen Büscheli | G7: Offen Kl. 1 | I7: Birnen Büscheli Offen Kl. 1 | J7: Poires Büscheli | K7: En vrac, cl. 1 | M7: Poires Büscheli | N7: Pere Büscheli | O7: Cl. 1 vendita sfusa | Q7: Pere Büscheli Cl. 1 v.s. | R7: 1 | S7: 1 | T7: Kilogramm | U7: (KGM) KG | V7: Früchte und Gemüse | W7: Früchte und Gemüse | X7: Früchte | Y7: 3 - Reduzierter Satz | Z7: Keine | AA7: Kein Depotartikel | AB7: ja | AC7: ja | AD7: ja | AE7: ja | AF7: - | AG7: - | AH7: ja | AI7: 0.05 | AJ7: -
A8: 204 | C8: Stk | D8: Nein | E8: 7613399039945 | F8: Granatapfelkerne | G8: Becher | H8: 125g | I8: Granatapfelkerne Becher | J8: Graines de grenade | K8: Gobelet | L8: 125g | M8: Graines de grenade 125g | N8: Melagrana chicchi | O8: bicchiere | P8: 125g | Q8: Melagrana chicchi 125g | R8: 0.125 | S8: 100 | T8: Gramm | U8: (PCE) Stück | V8: Früchte und Gemüse | W8: Früchte und Gemüse | X8: Früchte | Y8: 3 - Reduzierter Satz | Z8: Keine | AA8: Kein Depotartikel | AB8: ja | AC8: ja | AD8: ja | AE8: ja | AF8: - | AG8: - | AH8: ja | AI8: 0.05 | AJ8: -
A9: 214 | C9: Stk | D9: Nein | F9: Ananas | G9: Baby | H9: 1Stk | I9: Ananas Baby Stk | J9: Ananas | K9: Baby | L9: 1pce | M9: Ananas Baby | N9: Ananas | O9: Baby | P9: 1pz | Q9: Ananas Baby 1 pz | R9: 1 | S9: 1 | T9: Stück | U9: (PCE) Stück | V9: Früchte und Gemüse | W9: Früchte und Gemüse | X9: Früchte | Y9: 3 - Reduzierter Satz | Z9: Keine | AA9: Kein Depotartikel | AB9: ja | AC9: ja | AD9: ja | AE9: ja | AF9: - | AG9: - | AH9: ja | AI9: 0.05 | AJ9: -
A10: 215 | C10: Stk | D10: Nein | E10: 7613399001270 | F10: Ananas | G10: Becher | H10: 200g | I10: Ananas Becher 200g | J10: Ananas | K10: Gobelet | L10: 200g | M10: Ananas gobelet 200g | N10: Ananas | O10: bicchiere | P10: 200g | Q10: Ananas bicchiere 200g | R10: 0.2 | S10: 100 | T10: Gramm | U10: (PCE) Stück | V10: Früchte und Gemüse | W10: Früchte und Gemüse | X10: Früchte | Y10: 3 - Reduzierter Satz | Z10: Keine | AA10: Kein Depotartikel | AB10: ja | AC10: ja | AD10: ja | AE10: ja | AF10: - | AG10: - | AH10: ja | AI10: 0.05 | AJ10: -
A11: 230 | B11: 104 | C11: kg | F11: Äpfel Diwa | G11: Offen Kl. 1 | I11: Äpfel Diwa Offen Kl. 1 | J11: Pommes Diwa | K11: En vrac, cl. 1 | M11: Pommes Diwa en vrac cl. 1 | N11: Mele Diwa | O11: Cl. 1 vendita sfusa | Q11: Mele Diwa cl. 1 vend. sfusa | R11: 1 | S11: 1 | T11: Kilogramm | U11: (KGM) KG | V11: Früchte und Gemüse | W11: Früchte und Gemüse | X11: Früchte | Y11: 3 - Reduzierter Satz | Z11: Keine | AA11: Kein Depotartikel | AB11: ja | AC11: ja | AD11: ja | AE11: ja | AF11: - | AG11: - | AH11: ja | AI11: 0.05 | AJ11: -
A12: 243 | B12: 134 | C12: kg | F12: IP-Suisse Äpfel Gala | G12: Kl. 1 | I12: IP-Suisse Äpfel Gala Kl. 1 | J12: IP-Suisse Pommes Gala | K12: Cl. 1 | M12: IP-Suisse Pommes Gala cl. 1 | N12: IP-Suisse Mele Gala | O12: Cl. 1 | Q12: IP-Suisse Mele Gala cl. 1 | R12: 1 | S12: 1 | T12: Kilogramm | U12: (KGM) KG | V12: Früchte und Gemüse | W12: Früchte und Gemüse | X12: Früchte | Y12: 3 - Reduzierter Satz | Z12: Keine | AA12: Kein Depotartikel | AB12: ja | AC12: ja | AD12: ja | AE12: ja | AF12: - | AG12: - | AH12: ja | AI12: 0.05 | AJ12: -
A13: 245 | B13: 112 | C13: kg | F13: Äpfel Gala | G13: Offen Kl. 2 | I13: Äpfel Gala Offen Kl. 2 | J13: Pommes Gala | K13: En vrac, cl. 2 | M13: Pommes Gala en vrac cl. 2 | N13: Mele Gala | O13: Cl. 2 vendita sfusa | Q13: Mele Gala cl. 2 vend. afusa | R13: 1 | S13: 1 | T13: Kilogramm | U13: (KGM) KG | V13: Früchte und Gemüse | W13: Früchte und Gemüse | X13: Früchte | Y13: 3 - Reduzierter Satz | Z13: Keine | AA13: Kein Depotartikel | AB13: ja | AC13: ja | AD13: ja | AE13: ja | AF13: - | AG13: - | AH13: ja | AI13: 0.05 | AJ13: -
A14: 254 | B14: 125 | C14: kg | F14: Äpfel Pink Lady | G14: Offen Kl. 1 | I14: Äpfel Pink Lady Offen Kl. 1 | J14: Pommes Pink Lady | K14: En vrac, cl. 1 | M14: Pomm Pink Lady en vrac cl.1 | N14: Mele Pink Lady | O14: Cl. 1 vendita sfusa | Q14: Mele Pink Lady cl. 1 vend. s | R14: 1 | S14: 1 | T14: Kilogramm | U14: (KGM) KG | V14: Früchte und Gemüse | W14: Früchte und Gemüse | X14: Früchte | Y14: 3 - Reduzierter Satz | Z14: Keine | AA14: Kein Depotartikel | AB14: ja | AC14: ja | AD14: ja | AE14: ja | AF14: - | AG14: - | AH14: ja | AI14: 0.05 | AJ14: -
A15: 265 | C15: Stk | F15: Aprikosen | H15: 500g | I15: Aprikosen 500g | J15: Abricots | L15: 500g | M15: Abricos 500g | N15: Albicocche | P15: 500g | Q15: Albicocche 500g | R15: 0.5 | S15: 1 | T15: Kilogramm | U15: (PCE) Stück | V15: Früchte und Gemüse | W15: Früchte und Gemüse | X15: Früchte | Y15: 3 - Reduzierter Satz | Z15: Keine | AA15: Kein Depotartikel | AB15: ja | AC15: ja | AD15: ja | AE15: ja | AF15: - | AG15: - | AH15: ja | AI15: 0.05 | AJ15: -
A16: 269 | C16: Stk | D16: Nein | E16: 7613399021476 | F16: Aprikosen | H16: 2kg | I16: Aprikosen 2kg | J16: Abricots | L16: 2kg | M16: Abricots 2kg | N16: Albicocche | P16: 2kg | Q16: Albicocche 2kg | R16: 2 | S16: 1 | T16: Kilogramm | U16: (PCE) Stück | V16: Früchte und Gemüse | W16: Früchte und Gemüse | X16: Früchte | Y16: 3 - Reduzierter Satz | Z16: Keine | AA16: Kein Depotartikel | AB16: ja | AC16: ja | AD16: ja | AE16: ja | AF16: - | AG16: - | AH16: ja | AI16: 0.05 | AJ16: -
A17: 276 | B17: 135 | C17: kg | D17: Nein | F17: Aprikosen | G17: Offen AAA | I17: Aprikosen Offen AAA | J17: Abricots | K17: En vrac AAA | M17: Abricosts en vrac AAA | N17: Albicocche | O17: vendita sfusa AAA | Q17: Albicocche vend. sfus. AAA | R17: 1 | S17: 1 | T17: Kilogramm | U17: (KGM) KG | V17: Früchte und Gemüse | W17: Früchte und Gemüse | X17: Früchte | Y17: 3 - Reduzierter Satz | Z17: Keine | AA17: Kein Depotartikel | AB17: ja | AC17: ja | AD17: ja | AE17: ja | AF17: - | AG17: - | AH17: ja | AI17: 0.05 | AJ17: -
A18: 298 | C18: Stk | D18: Ja | E18: 2202158000000 | F18: Aprikosen | H18: ca. 800g | I18: Aprikosen ca. 800g | J18: Abricots | L18: env. 800g | M18: Abricots env. 800g | N18: Albicocche | P18: ca. 800g | Q18: Albicocche ca. 800g | R18: 0.8 | S18: 1 | T18: Kilogramm | U18: (PCE) Stück | V18: Früchte und Gemüse | W18: Früchte und Gemüse | X18: Früchte | Y18: 3 - Reduzierter Satz | Z18: Keine | AA18: Kein Depotartikel | AB18: ja | AC18: ja | AD18: ja | AE18: ja | AF18: - | AG18: - | AH18: ja | AI18: 0.05 | AJ18: -
A19: 317 | C19: Stk | D19: Ja | E19: 2205672000000 | F19: Aprikosen | G19: Schale | H19: 650g | I19: Aprikosen Schale 650g | J19: Abricots | K19: Barquette | L19: 650g | M19: Abricots barquette 650g | N19: Albicocche | O19: vaschetta | P19: 650g | Q19: Albicocche vasch. 650g | R19: 0.65 | S19: 1 | T19: Kilogramm | U19: (PCE) Stück | V19: Früchte und Gemüse | W19: Früchte und Gemüse | X19: Früchte | Y19: 3 - Reduzierter Satz | Z19: Keine | AA19: Kein Depotartikel | AB19: ja | AC19: ja | AD19: ja | AE19: ja | AF19: - | AG19: - | AH19: ja | AI19: 0.05 | AJ19: -
A20: 318 | C20: Stk | D20: Nein | E20: 7613399047834 | F20: Aprikosen getrocknet | H20: 200g | I20: Aprikosen getrocknet 200g | J20: Abricots secs | L20: 200g | M20: Abricots secs 200g | N20: Albicocche secche | P20: 200g | Q20: Albicocche secche 200g | R20: 0.2 | S20: 100 | T20: Gramm | U20: (PCE) Stück | V20: Früchte und Gemüse | W20: Früchte und Gemüse | X20: Früchte | Y20: 3 - Reduzierter Satz | Z20: Keine | AA20: Kein Depotartikel | AB20: ja | AC20: ja | AD20: ja | AE20: ja | AF20: - | AG20: - | AH20: ja | AI20: 0.05 | AJ20: -
A21: 327 | B21: 138 | C21: kg | D21: Nein | F21: Bananen Fyffes | G21: Offen | I21: Bananen Fyffes Offen | J21: Bananes Fyffes | K21: En vrac | M21: Bananes Fyffes en vrac | N21: Banane Fyffes | O21: vendita sfusa | Q21: Banane Fyffes vend. sfusa | R21: 1 | S21: 1 | T21: Kilogramm | U21: (KGM) KG | V21: Früchte und Gemüse | W21: Früchte und Gemüse | X21: Früchte | Y21: 3 - Reduzierter Satz | Z21: Keine | AA21: Kein Depotartikel | AB21: ja | AC21: ja | AD21: ja | AE21: ja | AF21: - | AG21: - | AH21: ja | AI21: 0.05 | AJ21: -
A22: 328 | C22: Stk | D22: Ja | E22: 2201581000000 | F22: Bananen | G22: gepackt | I22: Bananen gepackt | J22: Bananes | K22: Emballé | M22: Bananes emballé | N22: Banane | O22: confezionato | Q22: Banane confezionato | R22: 1 | S22: 1 | T22: Kilogramm | U22: (PCE) Stück | V22: Früchte und Gemüse | W22: Früchte und Gemüse | X22: Früchte | Y22: 3 - Reduzierter Satz | Z22: Keine | AA22: Kein Depotartikel | AB22: ja | AC22: ja | AD22: ja | AE22: ja | AF22: - | AG22: - | AH22: ja | AI22: 0.05 | AJ22: -
A23: 346 | C23: Stk | D23: Nein | E23: 7610632050514 | F23: Beerenmischung | G23: Schale | H23: 250g | I23: Beerenmischung Schale 250g | J23: Mélange de baies | K23: Barquette | L23: 250g | M23: Melange de baies 250g | N23: Bacche miste | O23: vaschetta | P23: 250g | Q23: Bacche miste 250g | R23: 0.25 | S23: 100 | T23: Gramm | U23: (PCE) Stück | V23: Früchte und Gemüse | W23: Früchte und Gemüse | X23: Früchte | Y23: 3 - Reduzierter Satz | Z23: Keine | AA23: Kein Depotartikel | AB23: ja | AC23: ja | AD23: ja | AE23: ja | AF23: - | AG23: - | AH23: ja | AI23: 0.05 | AJ23: -
A24: 369 | B24: 145 | C24: kg | F24: Birnen Ercolini | G24: Offen Kl. 1 | I24: Birnen Ercolini Offen Kl. 1 | J24: Poires Ercolini | K24: En vrac, cl. 1 | M24: Poire Ercolini en vrac cl. 1 | N24: Pere Ercolini | O24: Cl. 1 vendita sfusa | Q24: Pere Ercolini cl.1 vend. Sf. | R24: 1 | S24: 1 | T24: Kilogramm | U24: (KGM) KG | V24: Früchte und Gemüse | W24: Früchte und Gemüse | X24: Früchte | Y24: 3 - Reduzierter Satz | Z24: Keine | AA24: Kein Depotartikel | AB24: ja | AC24: ja | AD24: ja | AE24: ja | AF24: - | AG24: - | AH24: ja | AI24: 0.05 | AJ24: -
A25: 371 | B25: 151 | C25: kg | F25: Birnen Kaiser | G25: Offen Kl. 1 | I25: Birnen Kaiser Offen Kl.1 | J25: Poires Beurré Bosc | K25: En vrac, cl. 1 | M25: Poire Beurré Bosc en v. cl1 | N25: Pere Kaiser | O25: Cl. 1 vendita sfusa | Q25: Pere Kaiser cl. 1 vendta sf. | R25: 1 | S25: 1 | T25: Kilogramm | U25: (KGM) KG | V25: Früchte und Gemüse | W25: Früchte und Gemüse | X25: Früchte | Y25: 3 - Reduzierter Satz | Z25: Keine | AA25: Kein Depotartikel | AB25: ja | AC25: ja | AD25: ja | AE25: ja | AF25: - | AG25: - | AH25: ja | AI25: 0.05 | AJ25: -
A26: 375 | C26: Stk | D26: Ja | E26: 2203071000000 | F26: Birnen Abate | G26: Kl. 1 gepackt | I26: Birnen Abate Kl. 1 gepackt | J26: Poires Abate | K26: Cl. 1 emballé | M26: Poires Abate cl. 1 emballé | N26: Pere Abate | O26: Cl. 1 confezionato | Q26: Pere Abate cl.1 confezionato | R26: 1 | S26: 1 | T26: Kilogramm | U26: (PCE) Stück | V26: Früchte und Gemüse | W26: Früchte und Gemüse | X26: Früchte | Y26: 3 - Reduzierter Satz | Z26: Keine | AA26: Kein Depotartikel | AB26: ja | AC26: ja | AD26: ja | AE26: ja | AF26: - | AG26: - | AH26: ja | AI26: 0.05 | AJ26: -
A27: 376 | C27: Stk | D27: Ja | E27: 2205627000000 | F27: Bio Birnen Abate | G27: Kl. 1 gepackt | I27: Bio Birnen Abate Kl. 1 gep. | J27: Bio Poires Abate | K27: Cl. 1 emballé | M27: Bio Poires Abate cl1 emballé | N27: Bio Pere Abate | O27: Cl. 1 confezionato | Q27: Bio Pere Abate cl. 1 confez. | R27: 1 | S27: 1 | T27: Kilogramm | U27: (PCE) Stück | V27: Früchte und Gemüse | W27: Früchte und Gemüse | X27: Früchte | Y27: 3 - Reduzierter Satz | Z27: Keine | AA27: Kein Depotartikel | AB27: ja | AC27: ja | AD27: ja | AE27: ja | AF27: - | AG27: - | AH27: ja | AI27: 0.05 | AJ27: -
A28: 378 | B28: 142 | C28: kg | D28: Nein | F28: Birnen Boscop | G28: Offen Kl. 1 | I28: Birnen Boscop Offen Kl. 1 | J28: Poires Boscop | K28: En vrac, cl. 1 | M28: Poires Boscop en vrac cl. 1 | N28: Pere Boscop | O28: Cl. 1 vendita sfusa | Q28: Pere Boscop cl.1 vend. sfusa | R28: 1 | S28: 1 | T28: Kilogramm | U28: (KGM) KG | V28: Früchte und Gemüse | W28: Früchte und Gemüse | X28: Früchte | Y28: 3 - Reduzierter Satz | Z28: Keine | AA28: Kein Depotartikel | AB28: ja | AC28: ja | AD28: ja | AE28: ja | AF28: - | AG28: - | AH28: ja | AI28: 0.05 | AJ28: -
A29: 381 | C29: Stk | D29: Ja | E29: 2260561000002 | F29: Birnen Boscop | G29: Kl. 1 gepackt | I29: Birnen Boscop Kl. 1 gepackt | J29: Poires Boscop | K29: Cl. 1 emballé | M29: Poires Boscop cl. 1 emballé | N29: Pere Boscop | O29: Cl. 1 confezionato | Q29: Pere Boscop cl. 1 confez. | R29: 1 | S29: 1 | T29: Kilogramm | U29: (PCE) Stück | V29: Früchte und Gemüse | W29: Früchte und Gemüse | X29: Früchte | Y29: 3 - Reduzierter Satz | Z29: Keine | AA29: Kein Depotartikel | AB29: ja | AC29: ja | AD29: ja | AE29: ja | AF29: - | AG29: - | AH29: ja | AI29: 0.05 | AJ29: -
A30: 383 | C30: Stk | D30: Ja | E30: 2287572000000 | F30: Birnen Carmen | G30: Kl. 1 gepackt | I30: Birnen Carmen Kl. 1 gepackt | J30: Poires Carmen | K30: Cl. 1 emballé | M30: Poires Carmen cl. 1 emballé | N30: Pere Carmen | O30: Cl. 1 confezionato | Q30: Pere Carmen cl. 1 confez. | R30: 1 | S30: 1 | T30: Kilogramm | U30: (PCE) Stück | V30: Früchte und Gemüse | W30: Früchte und Gemüse | X30: Früchte | Y30: 3 - Reduzierter Satz | Z30: Keine | AA30: Kein Depotartikel | AB30: ja | AC30: ja | AD30: ja | AE30: ja | AF30: - | AG30: - | AH30: ja | AI30: 0.05 | AJ30: -
A31: 386 | B31: 144 | C31: kg | D31: Nein | F31: Birnen Conférence | G31: Offen Kl. 1 | I31: Birnen Conférence Offen Kl.1 | J31: Poires Conférence | K31: En vrac, cl. 1 | M31: Poires Conférence cl.1 en vr | N31: Pere Conférence | O31: Cl. 1 vendita sfusa | Q31: Pere Conférence cl. 1 ve. Sf | R31: 1 | S31: 1 | T31: Kilogramm | U31: (KGM) KG | V31: Früchte und Gemüse | W31: Früchte und Gemüse | X31: Früchte | Y31: 3 - Reduzierter Satz | Z31: Keine | AA31: Kein Depotartikel | AB31: ja | AC31: ja | AD31: ja | AE31: ja | AF31: - | AG31: - | AH31: ja | AI31: 0.05 | AJ31: -
A32: 387 | C32: Stk | D32: Ja | E32: 2216831000005 | F32: Birnen Conférence | G32: Kl. 1 gepackt | I32: Birnen Conférence Kl. 1 gep. | J32: Poires Conférence | K32: Cl. 1 emballé | M32: Poires Conférence cl. 1 emb. | N32: Pere Conférence | O32: Cl. 1 confezionato | Q32: Pere Conférence cl. 1 conf | R32: 1 | S32: 1 | T32: Kilogramm | U32: (PCE) Stück | V32: Früchte und Gemüse | W32: Früchte und Gemüse | X32: Früchte | Y32: 3 - Reduzierter Satz | Z32: Keine | AA32: Kein Depotartikel | AB32: ja | AC32: ja | AD32: ja | AE32: ja | AF32: - | AG32: - | AH32: ja | AI32: 0.05 | AJ32: -
A33: 388 | C33: Stk | D33: Ja | E33: 2216799000000 | F33: Bio Birnen Conférence | G33: Kl. 1 gepackt | I33: Bio Birnen Conf. Kl.1 gep. | J33: Bio Poires Conférence | K33: Cl. 1 emballé | M33: Bio Poires Confér. cl.1 emb. | N33: Bio Pere Conférence | O33: Cl. 1 confezionato | Q33: Bio Pere Conf. cl. 1 conf. | R33: 1 | S33: 1 | T33: Kilogramm | U33: (PCE) Stück | V33: Früchte und Gemüse | W33: Früchte und Gemüse | X33: Früchte | Y33: 3 - Reduzierter Satz | Z33: Keine | AA33: Kein Depotartikel | AB33: ja | AC33: ja | AD33: ja | AE33: ja | AF33: - | AG33: - | AH33: ja | AI33: 0.05 | AJ33: -
A34: 389 | B34: 146 | C34: kg | D34: Nein | F34: Birnen Forellen | G34: Offen Kl. 1 | I34: Birnen Forellen Offen Kl. 1 | J34: Poires Forelle | K34: En vrac, cl. 1 | M34: Poires Forelle cl. 1 en vrac | N34: Pere Forelle | O34: Cl. 1 vendita sfusa | Q34: Pere Forelle cl. 1 vend. Sf. | R34: 1 | S34: 1 | T34: Kilogramm | U34: (KGM) KG | V34: Früchte und Gemüse | W34: Früchte und Gemüse | X34: Früchte | Y34: 3 - Reduzierter Satz | Z34: Keine | AA34: Kein Depotartikel | AB34: ja | AC34: ja | AD34: ja | AE34: ja | AF34: - | AG34: - | AH34: ja | AI34: 0.05 | AJ34: -
A35: 391 | C35: Stk | D35: Ja | E35: 2201108000000 | F35: Birnen Forellen | G35: Kl. 1 gepackt | I35: Birnen Forellen Kl.1 gepackt | J35: Poires Forelle | K35: Cl. 1 emballé | M35: Poires Forelle cl. 1 emballé | N35: Pere Forelle | O35: Cl. 1 confezionato | Q35: Pere Forelle cl. 1 confez. | R35: 1 | S35: 1 | T35: Kilogramm | U35: (PCE) Stück | V35: Früchte und Gemüse | W35: Früchte und Gemüse | X35: Früchte | Y35: 3 - Reduzierter Satz | Z35: Keine | AA35: Kein Depotartikel | AB35: ja | AC35: ja | AD35: ja | AE35: ja | AF35: - | AG35: - | AH35: ja | AI35: 0.05 | AJ35: -
A36: 394 | B36: 147 | C36: kg | D36: Nein | F36: Birnen Fred | G36: Offen Kl. 1 | I36: Birnen Fred Offen Kl. 1 | J36: Poires Fred | K36: En vrac, cl. 1 | M36: Poires Fred cl. 1 en vrac | N36: Pere Fred | O36: Cl. 1 vendita sfusa | Q36: Pere Fred cl. 1 vend sfusa | R36: 1 | S36: 1 | T36: Kilogramm | U36: (KGM) KG | V36: Früchte und Gemüse | W36: Früchte und Gemüse | X36: Früchte | Y36: 3 - Reduzierter Satz | Z36: Keine | AA36: Kein Depotartikel | AB36: ja | AC36: ja | AD36: ja | AE36: ja | AF36: - | AG36: - | AH36: ja | AI36: 0.05 | AJ36: -
A37: 395 | C37: Stk | D37: Ja | E37: 2205556000000 | F37: Birnen Fred | G37: Kl. 1 gepackt | I37: Birnen Fred Kl. 1 gepackt | J37: Poires Fred | K37: Cl. 1 emballé | M37: Poires Fred cl. 1 emballé | N37: Pere Fred | O37: Cl. 1 confezionato | Q37: Pere Fred cl. 1 confez. | R37: 1 | S37: 1 | T37: Kilogramm | U37: (PCE) Stück | V37: Früchte und Gemüse | W37: Früchte und Gemüse | X37: Früchte | Y37: 3 - Reduzierter Satz | Z37: Keine | AA37: Kein Depotartikel | AB37: ja | AC37: ja | AD37: ja | AE37: ja | AF37: - | AG37: - | AH37: ja | AI37: 0.05 | AJ37: -
A38: 398 | B38: 148 | C38: kg | D38: Nein | F38: Birnen Gute Louise | G38: Offen Kl. 1 | I38: Birnen Gute Louise Off. Kl.1 | J38: Poires Bonne Louise | K38: En vrac, cl. 1 | M38: Poires Bonn. Lou. cl.1 en v. | N38: Pere Gute Luise | O38: Cl. 1 vendita sfusa | Q38: Pere Gute Luise cl. 1 v. sf. | R38: 1 | S38: 1 | T38: Kilogramm | U38: (KGM) KG | V38: Früchte und Gemüse | W38: Früchte und Gemüse | X38: Früchte | Y38: 3 - Reduzierter Satz | Z38: Keine | AA38: Kein Depotartikel | AB38: ja | AC38: ja | AD38: ja | AE38: ja | AF38: - | AG38: - | AH38: ja | AI38: 0.05 | AJ38: -
A39: 400 | C39: Stk | D39: Ja | E39: 2216791000008 | F39: Birnen Gute Louise | G39: Kl. 1 gepackt | I39: Birnen Gute Louise Kl.1 gep. | J39: Poires Bonne Louise | K39: Cl. 1 emballé | M39: Poires Bonn. Lou. cl.1 emb. | N39: Pere Gute Luise | O39: Cl. 1 confezionato | Q39: Pere Gute Luise cl. 1 confez | R39: 1 | S39: 1 | T39: Kilogramm | U39: (PCE) Stück | V39: Früchte und Gemüse | W39: Früchte und Gemüse | X39: Früchte | Y39: 3 - Reduzierter Satz | Z39: Keine | AA39: Kein Depotartikel | AB39: ja | AC39: ja | AD39: ja | AE39: ja | AF39: - | AG39: - | AH39: ja | AI39: 0.05 | AJ39: -
A40: 403 | B40: 150 | C40: kg | D40: Nein | F40: Birnen Guyot | G40: Offen Kl. 1 | I40: Birnen Guyot Offen Kl. 1 | J40: Poires Guyot | K40: En vrac, cl. 1 | M40: Poires Guyot cl. 1 en vrac | N40: Pere Guyot | O40: Cl. 1 vendita sfusa | Q40: Pere Guyot cl. 1 vend. sfusa | R40: 1 | S40: 1 | T40: Kilogramm | U40: (KGM) KG | V40: Früchte und Gemüse | W40: Früchte und Gemüse | X40: Früchte | Y40: 3 - Reduzierter Satz | Z40: Keine | AA40: Kein Depotartikel | AB40: ja | AC40: ja | AD40: ja | AE40: ja | AF40: - | AG40: - | AH40: ja | AI40: 0.05 | AJ40: -
...

Sheet Leergutliste
A1: System Attributes | E1: Matching Attribute(s) | F1: Reference Data Attributes
A2: Action | B2: Type | C2: ID | D2: Name | E2: Artikelnummer | F2: Artikeltext//de-DE | G2: Artikeltext//fr-FR | H2: Artikeltext//it-IT | I2: Konditionsbetrag | J2: GTIN
B3: refxdepotartikel | C3: 24a46c0f-a771-41e2-93ed-cb0c3fab73bd | D3: 1031091 - Flasche Depot Fr. 0.30 1Stk | E3: 1031091 | F3: 1031091 - Flasche Depot Fr. 0.30 1Stk | G3: 1031091 - Bouteille Dépôt Fr. 0.30 1pce | H3: 1031091 - Bottiglia deposito CHF 0.30 1pz | I3: 0.3 | J3: 2009990300013 | L3: PROD
B4: refxdepotartikel | C4: cb0f8f2a-b148-4463-8ea6-f724fe195806 | D4: 1031091 - Flasche Depot Fr. 0.30 1Stk | E4: 1031091 | F4: 1031091 - Flasche Depot Fr. 0.30 1Stk | G4: 1031091 - Bouteille Dépôt Fr. 0.30 1pc | H4: 1031091 - Bottiglia 0.30 Deposito Fr. 1pz | I4: 0.3 | J4: 2009990300013 | L4: FS
B5: refxdepotartikel | C5: ab6d040c-8203-4e0b-b175-1994c4972eae | D5: 1031092 - Zylinder Soda Pfand Lieferung 1Stk CHF 10.00 | E5: 1031092 | F5: 1031092 - Zylinder Soda Pfand Lieferung 1Stk CHF 10.00 | G5: 1031092 - Cylindre Soda consigne 1pc CHF 10.00 | H5: 1031092 - Zylinder Soda cilindro consegna 1pz CHF 10.00 | I5: 10 | J5: 2009990400010 | L5: PROD
B6: refxdepotartikel | C6: fbc0f523-d3b6-47ba-81d4-f929ccdf1d54 | D6: 1031092 - Zylinder Soda Pfand Lieferung 1Stk | E6: 1031092 | F6: 1031092 - Zylinder Soda Pfand Lieferung 1Stk | G6: 1031092 - Cylindre Soda consigne 1pc | H6: 1031092 - Zylinder Soda cilindro consegna 1pz | I6: 10 | J6: 2009990400010 | L6: FS
B7: refxdepotartikel | C7: eff3978d-7324-4585-9715-cc4ffba09c37 | D7: 1031093 - Soda Lieferkarton 1Stk CHF 0.01 | E7: 1031093 | F7: 1031093 - Soda Lieferkarton 1Stk CHF 0.01 | G7: 1031093 - Carton de livraison Soda 1pc CHF 0.01 | H7: 1031093 - Soda Cartone consegna 1pz CHF 0.01 | I7: 0.01 | J7: 2009990410019 | L7: PROD
B8: refxdepotartikel | C8: bbd5d45f-1d71-4630-8c19-a80359c65efc | D8: 1031095 - Bierharass Depot 20er Fr. 5.00 1Stk | E8: 1031095 | F8: 1031095 - Bierharass Depot 20er Fr. 5.00 1Stk | G8: 1031095 - Caisse de bière dépôt 20 bt Fr. 5.00 1pc | H8: 1031095 - Cassa di birra da 20 deposi Fr. 5.00 1pz | I8: 5 | J8: 2009995530019 | L8: PROD
B9: refxdepotartikel | C9: efc07f6e-9d05-4740-8c39-a909a84956a5 | D9: 1031095 - Bierharass Depot 20er Fr. 5.00 1Stk | E9: 1031095 | F9: 1031095 - Bierharass Depot 20er Fr. 5.00 1Stk | G9: 1031095 - Caisse de bière Depot 20 Fr. 5.00 1pc | H9: 1031095 - Cassa di birra da 20 Depot Fr. 5.00 1pz | I9: 5 | J9: 2009995530019 | L9: FS
B10: refxdepotartikel | C10: 4ef93831-6d2b-4ecf-b453-90d4c225e3c6 | D10: 1035856 - Depot Harasse mit 20 Fl. CHF 11.00 | E10: 1035856 | F10: 1035856 - Depot Harasse mit 20 Fl. CHF 11.00 | G10: 1035856 - Depot Caisse avec 20 btlles CHF 11.00 | H10: 1035856 - Depot Cassa 20 bottiglie CHF 11.00 | I10: 11 | J10: 2009992010019 | L10: PROD
B11: refxdepotartikel | C11: aefcdd96-edf3-4763-8537-23b468197a31 | D11: 1035857 - Soda Zylinder Gebinde Rückgabe 1Stk CHF 10.00 | E11: 1035857 | F11: 1035857 - Soda Zylinder Gebinde Rückgabe 1Stk CHF 10.00 | G11: 1035857 - Soda Cylindre vide reprise 1 pce CHF 10.00 | H11: 1035857 - Soda Cilindri Contenitore resi 1pz CHF 10.00 | I11: 10 | J11: 2009995950015 | L11: PROD
B12: refxdepotartikel | C12: 39869ad3-bb9d-4f50-b44d-875afa9af2d4 | D12: 1035857 - Soda Zylinder Gebinde Rückgabe 1Stk | E12: 1035857 | F12: 1035857 - Soda Zylinder Gebinde Rückgabe 1Stk | G12: 1035857 - Soda Cylindre vide reprise 1 pce | H12: 1035857 - Soda Cilindri Contenitore resi 1pz | I12: 10 | J12: 2009995950015 | L12: FS
B13: refxdepotartikel | C13: 3cacbdbc-b134-402c-adba-636c19439a49 | D13: 1035858 - Gebinderücknahme DSD | E13: 1035858 | F13: 1035858 - Gebinderücknahme DSD | G13: 1035858 - restitution consigne DSD | H13: 1035858 - Restituzione contenitori, DSD | I13: 0.01 | J13: 2009995990011 | L13: FS
B14: refxdepotartikel | C14: f43d1af9-c103-4073-8a92-0c7379dd1446 | D14: 1102242 - Depot CHF 0.10 | E14: 1102242 | F14: 1102242 - Depot CHF 0.10 | G14: 1102242 - Depot CHF 0.10 | H14: 1102242 - Depot CHF 0.10 | I14: 0.1 | J14: 2011022420019 | L14: PROD
... B32: refxdepotartikel | C32: ers2vCq6ZaKBFib | D32: 1601772 - Depot Gasflasche Composite CHF 65.00 | E32: 1601772 | F32: 1601772 - Depot Gasflasche Composite CHF 65.00 | G32: 1102318 - Dépot Bouteille gaz Composite Vito 65.00 | H32: 1102318 - Bombole di gas deposito Vito CHF 65.00 | I32: 65 | J32: 2016017720013 | L32: FS

Sheet Model
A1: Sheet Name | B1: Data | D1: Attribute Name | E1: isCollection
A2: Entities | B2: Data | D2: GTIN-Typ Regioapp | E2: true

Sheet Reference Data
